5:return {{["x"] = 2, ["y"] = 0, ["param1"] = 81, ["z"] = 3, ["name"] = "wool:blue"}, {["x"] = 2, ["y"] = 0, ["param1"] = 81, ["z"] = 4, ["name"] = "wool:blue"}, {["x"] = 2, ["y"] = 0, ["param1"] = 81, ["z"] = 11, ["name"] = "wool:blue"}, {["x"] = 2, ["y"] = 0, ["param1"] = 81, ["z"] = 12, ["name"] = "wool:blue"}, {["x"] = 2, ["y"] = 1, ["param1"] = 81, ["z"] = 3, ["name"] = "wool:blue"}, {["x"] = 2, ["y"] = 1, ["param1"] = 81, ["z"] = 4, ["name"] = "wool:blue"}, {["x"] = 2, ["y"] = 1, ["param1"] = 81, ["z"] = 11, ["name"] = "wool:blue"}, {["x"] = 2, ["y"] = 1, ["param1"] = 81, ["z"] = 12, ["name"] = "wool:blue"}, {["x"] = 2, ["y"] = 2, ["param1"] = 81, ["z"] = 3, ["name"] = "wool:blue"}, {["x"] = 2, ["y"] = 2, ["param1"] = 81, ["z"] = 4, ["name"] = "wool:blue"}, {["x"] = 2, ["y"] = 2, ["param1"] = 81, ["z"] = 11, ["name"] = "wool:blue"}, {["x"] = 2, ["y"] = 2, ["param1"] = 81, ["z"] = 12, ["name"] = "wool:blue"}, {["x"] = 2, ["y"] = 5, ["param1"] = 86, ["z"] = 3, ["name"] = "wool:brown"}, {["x"] = 2, ["y"] = 5, ["param1"] = 86, ["z"] = 4, ["name"] = "wool:brown"}, {["x"] = 2, ["y"] = 5, ["param1"] = 86, ["z"] = 5, ["name"] = "wool:brown"}, {["x"] = 2, ["y"] = 5, ["param1"] = 86, ["z"] = 6, ["name"] = "wool:brown"}, {["x"] = 2, ["y"] = 5, ["param1"] = 86, ["z"] = 7, ["name"] = "wool:brown"}, {["x"] = 2, ["y"] = 5, ["param1"] = 86, ["z"] = 8, ["name"] = "wool:brown"}, {["x"] = 2, ["y"] = 5, ["param1"] = 86, ["z"] = 9, ["name"] = "wool:brown"}, {["x"] = 2, ["y"] = 5, ["param1"] = 86, ["z"] = 10, ["name"] = "wool:brown"}, {["x"] = 2, ["y"] = 5, ["param1"] = 86, ["z"] = 11, ["name"] = "wool:brown"}, {["x"] = 2, ["y"] = 5, ["param1"] = 86, ["z"] = 12, ["name"] = "wool:brown"}, {["x"] = 3, ["y"] = 0, ["param1"] = 81, ["z"] = 3, ["name"] = "wool:blue"}, {["x"] = 3, ["y"] = 0, ["param1"] = 81, ["z"] = 4, ["name"] = "wool:blue"}, {["x"] = 3, ["y"] = 0, ["param1"] = 81, ["z"] = 11, ["name"] = "wool:blue"}, {["x"] = 3, ["y"] = 0, ["param1"] = 81, ["z"] = 12, ["name"] = "wool:blue"}, {["x"] = 3, ["y"] = 3, ["param1"] = 81, ["z"] = 3, ["name"] = "wool:blue"}, {["x"] = 3, ["y"] = 3, ["param1"] = 81, ["z"] = 4, ["name"] = "wool:blue"}, {["x"] = 3, ["y"] = 3, ["param1"] = 81, ["z"] = 11, ["name"] = "wool:blue"}, {["x"] = 3, ["y"] = 3, ["param1"] = 81, ["z"] = 12, ["name"] = "wool:blue"}, {["x"] = 3, ["y"] = 4, ["param1"] = 86, ["z"] = 2, ["name"] = "wool:brown"}, {["x"] = 3, ["y"] = 4, ["param1"] = 86, ["z"] = 3, ["name"] = "wool:brown"}, {["x"] = 3, ["y"] = 4, ["param1"] = 86, ["z"] = 4, ["name"] = "wool:brown"}, {["x"] = 3, ["y"] = 4, ["param1"] = 86, ["z"] = 5, ["name"] = "wool:brown"}, {["x"] = 3, ["y"] = 4, ["param1"] = 86, ["z"] = 6, ["name"] = "wool:brown"}, {["x"] = 3, ["y"] = 4, ["param1"] = 86, ["z"] = 7, ["name"] = "wool:brown"}, {["x"] = 3, ["y"] = 4, ["param1"] = 86, ["z"] = 8, ["name"] = "wool:brown"}, {["x"] = 3, ["y"] = 4, ["param1"] = 86, ["z"] = 9, ["name"] = "wool:brown"}, {["x"] = 3, ["y"] = 4, ["param1"] = 86, ["z"] = 10, ["name"] = "wool:brown"}, {["x"] = 3, ["y"] = 4, ["param1"] = 86, ["z"] = 11, ["name"] = "wool:brown"}, {["x"] = 3, ["y"] = 4, ["param1"] = 86, ["z"] = 12, ["name"] = "wool:brown"}, {["x"] = 3, ["y"] = 4, ["param1"] = 86, ["z"] = 13, ["name"] = "wool:brown"}, {["x"] = 3, ["y"] = 5, ["param1"] = 86, ["z"] = 2, ["name"] = "wool:brown"}, {["x"] = 3, ["y"] = 5, ["param1"] = 86, ["z"] = 13, ["name"] = "wool:brown"}, {["x"] = 3, ["y"] = 6, ["param1"] = 86, ["z"] = 2, ["name"] = "wool:brown"}, {["x"] = 3, ["y"] = 6, ["param1"] = 86, ["z"] = 3, ["name"] = "wool:brown"}, {["x"] = 3, ["y"] = 6, ["param1"] = 86, ["z"] = 4, ["name"] = "wool:brown"}, {["x"] = 3, ["y"] = 6, ["param1"] = 86, ["z"] = 5, ["name"] = "wool:brown"}, {["x"] = 3, ["y"] = 6, ["param1"] = 86, ["z"] = 6, ["name"] = "wool:brown"}, {["x"] = 3, ["y"] = 6, ["param1"] = 86, ["z"] = 7, ["name"] = "wool:brown"}, {["x"] = 3, ["y"] = 6, ["param1"] = 86, ["z"] = 8, ["name"] = "wool:brown"}, {["x"] = 3, ["y"] = 6, ["param1"] = 86, ["z"] = 9, ["name"] = "wool:brown"}, {["x"] = 3, ["y"] = 6, ["param1"] = 86, ["z"] = 10, ["name"] = "wool:brown"}, {["x"] = 3, ["y"] = 6, ["param1"] = 86, ["z"] = 11, ["name"] = "wool:brown"}, {["x"] = 3, ["y"] = 6, ["param1"] = 86, ["z"] = 12, ["name"] = "wool:brown"}, {["x"] = 3, ["y"] = 6, ["param1"] = 86, ["z"] = 13, ["name"] = "wool:brown"}, {["x"] = 3, ["y"] = 7, ["param1"] = 88, ["z"] = 5, ["name"] = "wool:red"}, {["x"] = 3, ["y"] = 7, ["param1"] = 88, ["z"] = 10, ["name"] = "wool:red"}, {["x"] = 3, ["y"] = 8, ["param1"] = 88, ["z"] = 5, ["name"] = "wool:red"}, {["x"] = 3, ["y"] = 8, ["param1"] = 88, ["z"] = 10, ["name"] = "wool:red"}, {["x"] = 3, ["y"] = 9, ["param1"] = 88, ["z"] = 5, ["name"] = "wool:red"}, {["x"] = 3, ["y"] = 9, ["param1"] = 88, ["z"] = 10, ["name"] = "wool:red"}, {["x"] = 3, ["y"] = 10, ["param1"] = 76, ["z"] = 5, ["name"] = "wool:white"}, {["x"] = 3, ["y"] = 10, ["param1"] = 76, ["z"] = 6, ["name"] = "wool:white"}, {["x"] = 3, ["y"] = 10, ["param1"] = 76, ["z"] = 7, ["name"] = "wool:white"}, {["x"] = 3, ["y"] = 10, ["param1"] = 76, ["z"] = 8, ["name"] = "wool:white"}, {["x"] = 3, ["y"] = 10, ["param1"] = 76, ["z"] = 9, ["name"] = "wool:white"}, {["x"] = 3, ["y"] = 10, ["param1"] = 76, ["z"] = 10, ["name"] = "wool:white"}, {["x"] = 3, ["y"] = 11, ["param1"] = 76, ["z"] = 6, ["name"] = "wool:white"}, {["x"] = 3, ["y"] = 11, ["param1"] = 76, ["z"] = 7, ["name"] = "wool:white"}, {["x"] = 3, ["y"] = 11, ["param1"] = 76, ["z"] = 8, ["name"] = "wool:white"}, {["x"] = 3, ["y"] = 11, ["param1"] = 76, ["z"] = 9, ["name"] = "wool:white"}, {["x"] = 3, ["y"] = 12, ["param1"] = 76, ["z"] = 6, ["name"] = "wool:white"}, {["x"] = 3, ["y"] = 12, ["param1"] = 76, ["z"] = 7, ["name"] = "wool:white"}, {["x"] = 3, ["y"] = 12, ["param1"] = 76, ["z"] = 8, ["name"] = "wool:white"}, {["x"] = 3, ["y"] = 12, ["param1"] = 76, ["z"] = 9, ["name"] = "wool:white"}, {["x"] = 3, ["y"] = 13, ["param1"] = 76, ["z"] = 6, ["name"] = "wool:white"}, {["x"] = 3, ["y"] = 13, ["param1"] = 76, ["z"] = 7, ["name"] = "wool:white"}, {["x"] = 3, ["y"] = 13, ["param1"] = 76, ["z"] = 8, ["name"] = "wool:white"}, {["x"] = 3, ["y"] = 13, ["param1"] = 76, ["z"] = 9, ["name"] = "wool:white"}, {["x"] = 3, ["y"] = 14, ["param1"] = 76, ["z"] = 6, ["name"] = "wool:white"}, {["x"] = 3, ["y"] = 14, ["param1"] = 76, ["z"] = 7, ["name"] = "wool:white"}, {["x"] = 3, ["y"] = 14, ["param1"] = 76, ["z"] = 8, ["name"] = "wool:white"}, {["x"] = 3, ["y"] = 14, ["param1"] = 76, ["z"] = 9, ["name"] = "wool:white"}, {["x"] = 4, ["y"] = 0, ["param1"] = 81, ["z"] = 3, ["name"] = "wool:blue"}, {["x"] = 4, ["y"] = 0, ["param1"] = 81, ["z"] = 4, ["name"] = "wool:blue"}, {["x"] = 4, ["y"] = 0, ["param1"] = 81, ["z"] = 11, ["name"] = "wool:blue"}, {["x"] = 4, ["y"] = 0, ["param1"] = 81, ["z"] = 12, ["name"] = "wool:blue"}, {["x"] = 4, ["y"] = 3, ["param1"] = 86, ["z"] = 2, ["name"] = "wool:brown"}, {["x"] = 4, ["y"] = 3, ["param1"] = 86, ["z"] = 3, ["name"] = "wool:brown"}, {["x"] = 4, ["y"] = 3, ["param1"] = 86, ["z"] = 4, ["name"] = "wool:brown"}, {["x"] = 4, ["y"] = 3, ["param1"] = 86, ["z"] = 5, ["name"] = "wool:brown"}, {["x"] = 4, ["y"] = 3, ["param1"] = 86, ["z"] = 6, ["name"] = "wool:brown"}, {["x"] = 4, ["y"] = 3, ["param1"] = 86, ["z"] = 7, ["name"] = "wool:brown"}, {["x"] = 4, ["y"] = 3, ["param1"] = 86, ["z"] = 8, ["name"] = "wool:brown"}, {["x"] = 4, ["y"] = 3, ["param1"] = 86, ["z"] = 9, ["name"] = "wool:brown"}, {["x"] = 4, ["y"] = 3, ["param1"] = 86, ["z"] = 10, ["name"] = "wool:brown"}, {["x"] = 4, ["y"] = 3, ["param1"] = 86, ["z"] = 11, ["name"] = "wool:brown"}, {["x"] = 4, ["y"] = 3, ["param1"] = 86, ["z"] = 12, ["name"] = "wool:brown"}, {["x"] = 4, ["y"] = 3, ["param1"] = 86, ["z"] = 13, ["name"] = "wool:brown"}, {["x"] = 4, ["y"] = 4, ["param1"] = 86, ["z"] = 1, ["name"] = "wool:brown"}, {["x"] = 4, ["y"] = 4, ["param1"] = 86, ["z"] = 14, ["name"] = "wool:brown"}, {["x"] = 4, ["y"] = 5, ["param1"] = 86, ["z"] = 1, ["name"] = "wool:brown"}, {["x"] = 4, ["y"] = 5, ["param1"] = 86, ["z"] = 14, ["name"] = "wool:brown"}, {["x"] = 4, ["y"] = 6, ["param1"] = 86, ["z"] = 1, ["name"] = "wool:brown"}, {["x"] = 4, ["y"] = 6, ["param1"] = 86, ["z"] = 14, ["name"] = "wool:brown"}, {["x"] = 4, ["y"] = 7, ["param1"] = 86, ["z"] = 2, ["name"] = "wool:brown"}, {["x"] = 4, ["y"] = 7, ["param1"] = 86, ["z"] = 3, ["name"] = "wool:brown"}, {["x"] = 4, ["y"] = 7, ["param1"] = 86, ["z"] = 4, ["name"] = "wool:brown"}, {["x"] = 4, ["y"] = 7, ["param1"] = 86, ["z"] = 5, ["name"] = "wool:brown"}, {["x"] = 4, ["y"] = 7, ["param1"] = 86, ["z"] = 6, ["name"] = "wool:brown"}, {["x"] = 4, ["y"] = 7, ["param1"] = 86, ["z"] = 7, ["name"] = "wool:brown"}, {["x"] = 4, ["y"] = 7, ["param1"] = 86, ["z"] = 8, ["name"] = "wool:brown"}, {["x"] = 4, ["y"] = 7, ["param1"] = 86, ["z"] = 9, ["name"] = "wool:brown"}, {["x"] = 4, ["y"] = 7, ["param1"] = 86, ["z"] = 10, ["name"] = "wool:brown"}, {["x"] = 4, ["y"] = 7, ["param1"] = 86, ["z"] = 11, ["name"] = "wool:brown"}, {["x"] = 4, ["y"] = 7, ["param1"] = 86, ["z"] = 12, ["name"] = "wool:brown"}, {["x"] = 4, ["y"] = 7, ["param1"] = 86, ["z"] = 13, ["name"] = "wool:brown"}, {["x"] = 4, ["y"] = 8, ["param1"] = 85, ["z"] = 8, ["name"] = "wool:yellow"}, {["x"] = 4, ["y"] = 8, ["param1"] = 13, ["z"] = 11, ["name"] = "default:stone"}, {["x"] = 4, ["y"] = 8, ["param1"] = 13, ["z"] = 12, ["name"] = "default:stone"}, {["x"] = 4, ["y"] = 9, ["param1"] = 85, ["z"] = 8, ["name"] = "wool:yellow"}, {["x"] = 4, ["y"] = 9, ["param1"] = 13, ["z"] = 12, ["name"] = "default:stone"}, {["x"] = 4, ["y"] = 9, ["param1"] = 13, ["z"] = 13, ["name"] = "default:stone"}, {["x"] = 4, ["y"] = 10, ["param1"] = 76, ["z"] = 5, ["name"] = "wool:white"}, {["x"] = 4, ["y"] = 10, ["param1"] = 76, ["z"] = 6, ["name"] = "wool:white"}, {["x"] = 4, ["y"] = 10, ["param1"] = 76, ["z"] = 7, ["name"] = "wool:white"}, {["x"] = 4, ["y"] = 10, ["param1"] = 76, ["z"] = 8, ["name"] = "wool:white"}, {["x"] = 4, ["y"] = 10, ["param1"] = 76, ["z"] = 9, ["name"] = "wool:white"}, {["x"] = 4, ["y"] = 10, ["param1"] = 76, ["z"] = 10, ["name"] = "wool:white"}, {["x"] = 4, ["y"] = 11, ["param1"] = 76, ["z"] = 6, ["name"] = "wool:white"}, {["x"] = 4, ["y"] = 11, ["param1"] = 76, ["z"] = 9, ["name"] = "wool:white"}, {["x"] = 4, ["y"] = 12, ["param1"] = 56, ["z"] = 6, ["name"] = "default:wood"}, {["x"] = 4, ["y"] = 12, ["param1"] = 56, ["z"] = 7, ["name"] = "default:wood"}, {["x"] = 4, ["y"] = 12, ["param1"] = 56, ["z"] = 8, ["name"] = "default:wood"}, {["x"] = 4, ["y"] = 12, ["param1"] = 56, ["z"] = 9, ["name"] = "default:wood"}, {["x"] = 4, ["y"] = 13, ["param1"] = 56, ["z"] = 6, ["name"] = "default:wood"}, {["x"] = 4, ["y"] = 13, ["param1"] = 56, ["z"] = 7, ["name"] = "default:wood"}, {["x"] = 4, ["y"] = 13, ["param1"] = 56, ["z"] = 8, ["name"] = "default:wood"}, {["x"] = 4, ["y"] = 13, ["param1"] = 56, ["z"] = 9, ["name"] = "default:wood"}, {["x"] = 4, ["y"] = 14, ["param1"] = 56, ["z"] = 6, ["name"] = "default:wood"}, {["x"] = 4, ["y"] = 14, ["param1"] = 56, ["z"] = 7, ["name"] = "default:wood"}, {["x"] = 4, ["y"] = 14, ["param1"] = 56, ["z"] = 8, ["name"] = "default:wood"}, {["x"] = 4, ["y"] = 14, ["param1"] = 56, ["z"] = 9, ["name"] = "default:wood"}, {["x"] = 4, ["y"] = 15, ["param1"] = 76, ["z"] = 6, ["name"] = "wool:white"}, {["x"] = 4, ["y"] = 15, ["param1"] = 76, ["z"] = 7, ["name"] = "wool:white"}, {["x"] = 4, ["y"] = 15, ["param1"] = 76, ["z"] = 8, ["name"] = "wool:white"}, {["x"] = 4, ["y"] = 15, ["param1"] = 76, ["z"] = 9, ["name"] = "wool:white"}, {["x"] = 5, ["y"] = 0, ["param1"] = 81, ["z"] = 3, ["name"] = "wool:blue"}, {["x"] = 5, ["y"] = 0, ["param1"] = 81, ["z"] = 4, ["name"] = "wool:blue"}, {["x"] = 5, ["y"] = 0, ["param1"] = 81, ["z"] = 11, ["name"] = "wool:blue"}, {["x"] = 5, ["y"] = 0, ["param1"] = 81, ["z"] = 12, ["name"] = "wool:blue"}, {["x"] = 5, ["y"] = 1, ["z"] = 8, ["name"] = "wool:yellow"}, {["x"] = 5, ["y"] = 1, ["z"] = 9, ["name"] = "wool:yellow"}, {["x"] = 5, ["y"] = 1, ["z"] = 10, ["name"] = "wool:yellow"}, {["x"] = 5, ["y"] = 1, ["z"] = 11, ["name"] = "wool:yellow"}, {["x"] = 5, ["y"] = 1, ["z"] = 12, ["name"] = "wool:yellow"}, {["x"] = 5, ["y"] = 1, ["z"] = 13, ["name"] = "wool:yellow"}, {["x"] = 5, ["y"] = 1, ["z"] = 14, ["name"] = "wool:yellow"}, {["x"] = 5, ["y"] = 2, ["param1"] = 86, ["z"] = 3, ["name"] = "wool:brown"}, {["x"] = 5, ["y"] = 2, ["param1"] = 86, ["z"] = 4, ["name"] = "wool:brown"}, {["x"] = 5, ["y"] = 2, ["param1"] = 86, ["z"] = 5, ["name"] = "wool:brown"}, {["x"] = 5, ["y"] = 2, ["param1"] = 86, ["z"] = 6, ["name"] = "wool:brown"}, {["x"] = 5, ["y"] = 2, ["param1"] = 86, ["z"] = 7, ["name"] = "wool:brown"}, {["x"] = 5, ["y"] = 2, ["param1"] = 86, ["z"] = 8, ["name"] = "wool:brown"}, {["x"] = 5, ["y"] = 2, ["param1"] = 86, ["z"] = 9, ["name"] = "wool:brown"}, {["x"] = 5, ["y"] = 2, ["param1"] = 86, ["z"] = 10, ["name"] = "wool:brown"}, {["x"] = 5, ["y"] = 2, ["param1"] = 86, ["z"] = 11, ["name"] = "wool:brown"}, {["x"] = 5, ["y"] = 2, ["param1"] = 86, ["z"] = 12, ["name"] = "wool:brown"}, {["x"] = 5, ["y"] = 3, ["param1"] = 86, ["z"] = 2, ["name"] = "wool:brown"}, {["x"] = 5, ["y"] = 3, ["param1"] = 86, ["z"] = 13, ["name"] = "wool:brown"}, {["x"] = 5, ["y"] = 4, ["param1"] = 86, ["z"] = 1, ["name"] = "wool:brown"}, {["x"] = 5, ["y"] = 4, ["param1"] = 86, ["z"] = 14, ["name"] = "wool:brown"}, {["x"] = 5, ["y"] = 5, ["param1"] = 86, ["z"] = 0, ["name"] = "wool:brown"}, {["x"] = 5, ["y"] = 5, ["param1"] = 86, ["z"] = 15, ["name"] = "wool:brown"}, {["x"] = 5, ["y"] = 6, ["param1"] = 86, ["z"] = 1, ["name"] = "wool:brown"}, {["x"] = 5, ["y"] = 6, ["param1"] = 86, ["z"] = 14, ["name"] = "wool:brown"}, {["x"] = 5, ["y"] = 7, ["param1"] = 86, ["z"] = 2, ["name"] = "wool:brown"}, {["x"] = 5, ["y"] = 7, ["param1"] = 86, ["z"] = 13, ["name"] = "wool:brown"}, {["x"] = 5, ["y"] = 8, ["param1"] = 86, ["z"] = 3, ["name"] = "wool:brown"}, {["x"] = 5, ["y"] = 8, ["param1"] = 86, ["z"] = 4, ["name"] = "wool:brown"}, {["x"] = 5, ["y"] = 8, ["param1"] = 86, ["z"] = 5, ["name"] = "wool:brown"}, {["x"] = 5, ["y"] = 8, ["param1"] = 86, ["z"] = 6, ["name"] = "wool:brown"}, {["x"] = 5, ["y"] = 8, ["param1"] = 86, ["z"] = 7, ["name"] = "wool:brown"}, {["x"] = 5, ["y"] = 8, ["param1"] = 86, ["z"] = 8, ["name"] = "wool:brown"}, {["x"] = 5, ["y"] = 8, ["param1"] = 86, ["z"] = 9, ["name"] = "wool:brown"}, {["x"] = 5, ["y"] = 8, ["param1"] = 86, ["z"] = 10, ["name"] = "wool:brown"}, {["x"] = 5, ["y"] = 8, ["param1"] = 86, ["z"] = 11, ["name"] = "wool:brown"}, {["x"] = 5, ["y"] = 8, ["param1"] = 13, ["z"] = 13, ["name"] = "default:stone"}, {["x"] = 5, ["y"] = 9, ["param1"] = 13, ["z"] = 11, ["name"] = "default:stone"}, {["x"] = 5, ["y"] = 9, ["param1"] = 62, ["z"] = 13, ["name"] = "default:junglewood"}, {["x"] = 5, ["y"] = 10, ["param1"] = 76, ["z"] = 5, ["name"] = "wool:white"}, {["x"] = 5, ["y"] = 10, ["param1"] = 76, ["z"] = 6, ["name"] = "wool:white"}, {["x"] = 5, ["y"] = 10, ["param1"] = 76, ["z"] = 7, ["name"] = "wool:white"}, {["x"] = 5, ["y"] = 10, ["param1"] = 76, ["z"] = 8, ["name"] = "wool:white"}, {["x"] = 5, ["y"] = 10, ["param1"] = 76, ["z"] = 9, ["name"] = "wool:white"}, {["x"] = 5, ["y"] = 10, ["param1"] = 76, ["z"] = 10, ["name"] = "wool:white"}, {["x"] = 5, ["y"] = 10, ["param1"] = 13, ["z"] = 12, ["name"] = "default:stone"}, {["x"] = 5, ["y"] = 10, ["param1"] = 13, ["z"] = 13, ["name"] = "default:stone"}, {["x"] = 5, ["y"] = 11, ["param1"] = 76, ["z"] = 6, ["name"] = "wool:white"}, {["x"] = 5, ["y"] = 11, ["param1"] = 76, ["z"] = 9, ["name"] = "wool:white"}, {["x"] = 5, ["y"] = 12, ["param1"] = 56, ["z"] = 6, ["name"] = "default:wood"}, {["x"] = 5, ["y"] = 12, ["param1"] = 56, ["z"] = 7, ["name"] = "default:wood"}, {["x"] = 5, ["y"] = 12, ["param1"] = 56, ["z"] = 8, ["name"] = "default:wood"}, {["x"] = 5, ["y"] = 12, ["param1"] = 56, ["z"] = 9, ["name"] = "default:wood"}, {["x"] = 5, ["y"] = 13, ["param1"] = 79, ["z"] = 6, ["name"] = "wool:black"}, {["x"] = 5, ["y"] = 13, ["param1"] = 79, ["z"] = 7, ["name"] = "wool:black"}, {["x"] = 5, ["y"] = 13, ["param1"] = 79, ["z"] = 8, ["name"] = "wool:black"}, {["x"] = 5, ["y"] = 13, ["param1"] = 79, ["z"] = 9, ["name"] = "wool:black"}, {["x"] = 5, ["y"] = 14, ["param1"] = 56, ["z"] = 6, ["name"] = "default:wood"}, {["x"] = 5, ["y"] = 14, ["param1"] = 56, ["z"] = 7, ["name"] = "default:wood"}, {["x"] = 5, ["y"] = 14, ["param1"] = 56, ["z"] = 8, ["name"] = "default:wood"}, {["x"] = 5, ["y"] = 14, ["param1"] = 56, ["z"] = 9, ["name"] = "default:wood"}, {["x"] = 5, ["y"] = 15, ["param1"] = 76, ["z"] = 6, ["name"] = "wool:white"}, {["x"] = 5, ["y"] = 15, ["param1"] = 76, ["z"] = 7, ["name"] = "wool:white"}, {["x"] = 5, ["y"] = 15, ["param1"] = 76, ["z"] = 8, ["name"] = "wool:white"}, {["x"] = 5, ["y"] = 15, ["param1"] = 76, ["z"] = 9, ["name"] = "wool:white"}, {["x"] = 6, ["y"] = 0, ["param1"] = 81, ["z"] = 3, ["name"] = "wool:blue"}, {["x"] = 6, ["y"] = 0, ["param1"] = 81, ["z"] = 4, ["name"] = "wool:blue"}, {["x"] = 6, ["y"] = 0, ["param1"] = 81, ["z"] = 11, ["name"] = "wool:blue"}, {["x"] = 6, ["y"] = 0, ["param1"] = 81, ["z"] = 12, ["name"] = "wool:blue"}, {["x"] = 6, ["y"] = 1, ["z"] = 14, ["name"] = "wool:yellow"}, {["x"] = 6, ["y"] = 2, ["z"] = 14, ["name"] = "wool:yellow"}, {["x"] = 6, ["y"] = 3, ["param1"] = 86, ["z"] = 2, ["name"] = "wool:brown"}, {["x"] = 6, ["y"] = 3, ["param1"] = 86, ["z"] = 3, ["name"] = "wool:brown"}, {["x"] = 6, ["y"] = 3, ["param1"] = 86, ["z"] = 4, ["name"] = "wool:brown"}, {["x"] = 6, ["y"] = 3, ["param1"] = 86, ["z"] = 5, ["name"] = "wool:brown"}, {["x"] = 6, ["y"] = 3, ["param1"] = 86, ["z"] = 6, ["name"] = "wool:brown"}, {["x"] = 6, ["y"] = 3, ["param1"] = 86, ["z"] = 7, ["name"] = "wool:brown"}, {["x"] = 6, ["y"] = 3, ["param1"] = 86, ["z"] = 8, ["name"] = "wool:brown"}, {["x"] = 6, ["y"] = 3, ["param1"] = 86, ["z"] = 9, ["name"] = "wool:brown"}, {["x"] = 6, ["y"] = 3, ["param1"] = 86, ["z"] = 10, ["name"] = "wool:brown"}, {["x"] = 6, ["y"] = 3, ["param1"] = 86, ["z"] = 11, ["name"] = "wool:brown"}, {["x"] = 6, ["y"] = 3, ["param1"] = 86, ["z"] = 12, ["name"] = "wool:brown"}, {["x"] = 6, ["y"] = 3, ["param1"] = 86, ["z"] = 13, ["name"] = "wool:brown"}, {["x"] = 6, ["y"] = 3, ["z"] = 14, ["name"] = "wool:yellow"}, {["x"] = 6, ["y"] = 3, ["z"] = 15, ["name"] = "wool:yellow"}, {["x"] = 6, ["y"] = 4, ["param1"] = 86, ["z"] = 1, ["name"] = "wool:brown"}, {["x"] = 6, ["y"] = 4, ["param1"] = 86, ["z"] = 14, ["name"] = "wool:brown"}, {["x"] = 6, ["y"] = 4, ["z"] = 15, ["name"] = "wool:yellow"}, {["x"] = 6, ["y"] = 5, ["param1"] = 86, ["z"] = 1, ["name"] = "wool:brown"}, {["x"] = 6, ["y"] = 5, ["param1"] = 86, ["z"] = 14, ["name"] = "wool:brown"}, {["x"] = 6, ["y"] = 5, ["z"] = 15, ["name"] = "wool:yellow"}, {["x"] = 6, ["y"] = 6, ["param1"] = 86, ["z"] = 1, ["name"] = "wool:brown"}, {["x"] = 6, ["y"] = 6, ["param1"] = 86, ["z"] = 14, ["name"] = "wool:brown"}, {["x"] = 6, ["y"] = 6, ["z"] = 15, ["name"] = "wool:yellow"}, {["x"] = 6, ["y"] = 7, ["param1"] = 86, ["z"] = 2, ["name"] = "wool:brown"}, {["x"] = 6, ["y"] = 7, ["param1"] = 86, ["z"] = 3, ["name"] = "wool:brown"}, {["x"] = 6, ["y"] = 7, ["param1"] = 86, ["z"] = 4, ["name"] = "wool:brown"}, {["x"] = 6, ["y"] = 7, ["param1"] = 86, ["z"] = 5, ["name"] = "wool:brown"}, {["x"] = 6, ["y"] = 7, ["param1"] = 86, ["z"] = 6, ["name"] = "wool:brown"}, {["x"] = 6, ["y"] = 7, ["param1"] = 86, ["z"] = 7, ["name"] = "wool:brown"}, {["x"] = 6, ["y"] = 7, ["param1"] = 86, ["z"] = 8, ["name"] = "wool:brown"}, {["x"] = 6, ["y"] = 7, ["param1"] = 86, ["z"] = 9, ["name"] = "wool:brown"}, {["x"] = 6, ["y"] = 7, ["param1"] = 86, ["z"] = 10, ["name"] = "wool:brown"}, {["x"] = 6, ["y"] = 7, ["param1"] = 86, ["z"] = 11, ["name"] = "wool:brown"}, {["x"] = 6, ["y"] = 7, ["param1"] = 86, ["z"] = 12, ["name"] = "wool:brown"}, {["x"] = 6, ["y"] = 7, ["param1"] = 86, ["z"] = 13, ["name"] = "wool:brown"}, {["x"] = 6, ["y"] = 7, ["z"] = 15, ["name"] = "wool:yellow"}, {["x"] = 6, ["y"] = 8, ["param1"] = 85, ["z"] = 7, ["name"] = "wool:yellow"}, {["x"] = 6, ["y"] = 8, ["param1"] = 13, ["z"] = 11, ["name"] = "default:stone"}, {["x"] = 6, ["y"] = 8, ["param1"] = 13, ["z"] = 12, ["name"] = "default:stone"}, {["x"] = 6, ["y"] = 9, ["param1"] = 85, ["z"] = 7, ["name"] = "wool:yellow"}, {["x"] = 6, ["y"] = 9, ["param1"] = 13, ["z"] = 12, ["name"] = "default:stone"}, {["x"] = 6, ["y"] = 9, ["param1"] = 13, ["z"] = 13, ["name"] = "default:stone"}, {["x"] = 6, ["y"] = 10, ["param1"] = 76, ["z"] = 5, ["name"] = "wool:white"}, {["x"] = 6, ["y"] = 10, ["param1"] = 76, ["z"] = 6, ["name"] = "wool:white"}, {["x"] = 6, ["y"] = 10, ["param1"] = 76, ["z"] = 7, ["name"] = "wool:white"}, {["x"] = 6, ["y"] = 10, ["param1"] = 76, ["z"] = 8, ["name"] = "wool:white"}, {["x"] = 6, ["y"] = 10, ["param1"] = 76, ["z"] = 9, ["name"] = "wool:white"}, {["x"] = 6, ["y"] = 10, ["param1"] = 76, ["z"] = 10, ["name"] = "wool:white"}, {["x"] = 6, ["y"] = 11, ["param1"] = 76, ["z"] = 6, ["name"] = "wool:white"}, {["x"] = 6, ["y"] = 11, ["param1"] = 76, ["z"] = 9, ["name"] = "wool:white"}, {["x"] = 6, ["y"] = 12, ["param1"] = 56, ["z"] = 6, ["name"] = "default:wood"}, {["x"] = 6, ["y"] = 12, ["param1"] = 56, ["z"] = 7, ["name"] = "default:wood"}, {["x"] = 6, ["y"] = 12, ["param1"] = 56, ["z"] = 8, ["name"] = "default:wood"}, {["x"] = 6, ["y"] = 12, ["param1"] = 56, ["z"] = 9, ["name"] = "default:wood"}, {["x"] = 6, ["y"] = 13, ["param1"] = 56, ["z"] = 6, ["name"] = "default:wood"}, {["x"] = 6, ["y"] = 13, ["param1"] = 56, ["z"] = 7, ["name"] = "default:wood"}, {["x"] = 6, ["y"] = 13, ["param1"] = 56, ["z"] = 8, ["name"] = "default:wood"}, {["x"] = 6, ["y"] = 13, ["param1"] = 56, ["z"] = 9, ["name"] = "default:wood"}, {["x"] = 6, ["y"] = 14, ["param1"] = 56, ["z"] = 6, ["name"] = "default:wood"}, {["x"] = 6, ["y"] = 14, ["param1"] = 56, ["z"] = 7, ["name"] = "default:wood"}, {["x"] = 6, ["y"] = 14, ["param1"] = 56, ["z"] = 8, ["name"] = "default:wood"}, {["x"] = 6, ["y"] = 14, ["param1"] = 56, ["z"] = 9, ["name"] = "default:wood"}, {["x"] = 6, ["y"] = 15, ["param1"] = 76, ["z"] = 6, ["name"] = "wool:white"}, {["x"] = 6, ["y"] = 15, ["param1"] = 76, ["z"] = 7, ["name"] = "wool:white"}, {["x"] = 6, ["y"] = 15, ["param1"] = 76, ["z"] = 8, ["name"] = "wool:white"}, {["x"] = 6, ["y"] = 15, ["param1"] = 76, ["z"] = 9, ["name"] = "wool:white"}, {["x"] = 7, ["y"] = 0, ["param1"] = 81, ["z"] = 3, ["name"] = "wool:blue"}, {["x"] = 7, ["y"] = 0, ["param1"] = 81, ["z"] = 4, ["name"] = "wool:blue"}, {["x"] = 7, ["y"] = 0, ["param1"] = 81, ["z"] = 11, ["name"] = "wool:blue"}, {["x"] = 7, ["y"] = 0, ["param1"] = 81, ["z"] = 12, ["name"] = "wool:blue"}, {["x"] = 7, ["y"] = 0, ["z"] = 13, ["name"] = "wool:blue"}, {["x"] = 7, ["y"] = 0, ["z"] = 14, ["name"] = "wool:blue"}, {["x"] = 7, ["y"] = 1, ["z"] = 14, ["name"] = "wool:blue"}, {["x"] = 7, ["y"] = 2, ["z"] = 14, ["name"] = "wool:blue"}, {["x"] = 7, ["y"] = 3, ["param1"] = 81, ["z"] = 3, ["name"] = "wool:blue"}, {["x"] = 7, ["y"] = 3, ["param1"] = 81, ["z"] = 4, ["name"] = "wool:blue"}, {["x"] = 7, ["y"] = 3, ["param1"] = 81, ["z"] = 11, ["name"] = "wool:blue"}, {["x"] = 7, ["y"] = 3, ["param1"] = 81, ["z"] = 12, ["name"] = "wool:blue"}, {["x"] = 7, ["y"] = 3, ["z"] = 14, ["name"] = "wool:blue"}, {["x"] = 7, ["y"] = 4, ["param1"] = 86, ["z"] = 2, ["name"] = "wool:brown"}, {["x"] = 7, ["y"] = 4, ["param1"] = 86, ["z"] = 3, ["name"] = "wool:brown"}, {["x"] = 7, ["y"] = 4, ["param1"] = 86, ["z"] = 4, ["name"] = "wool:brown"}, {["x"] = 7, ["y"] = 4, ["param1"] = 86, ["z"] = 5, ["name"] = "wool:brown"}, {["x"] = 7, ["y"] = 4, ["param1"] = 86, ["z"] = 6, ["name"] = "wool:brown"}, {["x"] = 7, ["y"] = 4, ["param1"] = 86, ["z"] = 7, ["name"] = "wool:brown"}, {["x"] = 7, ["y"] = 4, ["param1"] = 86, ["z"] = 8, ["name"] = "wool:brown"}, {["x"] = 7, ["y"] = 4, ["param1"] = 86, ["z"] = 9, ["name"] = "wool:brown"}, {["x"] = 7, ["y"] = 4, ["param1"] = 86, ["z"] = 10, ["name"] = "wool:brown"}, {["x"] = 7, ["y"] = 4, ["param1"] = 86, ["z"] = 11, ["name"] = "wool:brown"}, {["x"] = 7, ["y"] = 4, ["param1"] = 86, ["z"] = 12, ["name"] = "wool:brown"}, {["x"] = 7, ["y"] = 4, ["param1"] = 86, ["z"] = 13, ["name"] = "wool:brown"}, {["x"] = 7, ["y"] = 4, ["z"] = 14, ["name"] = "wool:blue"}, {["x"] = 7, ["y"] = 5, ["param1"] = 86, ["z"] = 2, ["name"] = "wool:brown"}, {["x"] = 7, ["y"] = 5, ["param1"] = 86, ["z"] = 13, ["name"] = "wool:brown"}, {["x"] = 7, ["y"] = 5, ["z"] = 14, ["name"] = "wool:blue"}, {["x"] = 7, ["y"] = 6, ["param1"] = 86, ["z"] = 2, ["name"] = "wool:brown"}, {["x"] = 7, ["y"] = 6, ["param1"] = 86, ["z"] = 3, ["name"] = "wool:brown"}, {["x"] = 7, ["y"] = 6, ["param1"] = 86, ["z"] = 4, ["name"] = "wool:brown"}, {["x"] = 7, ["y"] = 6, ["param1"] = 86, ["z"] = 5, ["name"] = "wool:brown"}, {["x"] = 7, ["y"] = 6, ["param1"] = 86, ["z"] = 6, ["name"] = "wool:brown"}, {["x"] = 7, ["y"] = 6, ["param1"] = 86, ["z"] = 7, ["name"] = "wool:brown"}, {["x"] = 7, ["y"] = 6, ["param1"] = 86, ["z"] = 8, ["name"] = "wool:brown"}, {["x"] = 7, ["y"] = 6, ["param1"] = 86, ["z"] = 9, ["name"] = "wool:brown"}, {["x"] = 7, ["y"] = 6, ["param1"] = 86, ["z"] = 10, ["name"] = "wool:brown"}, {["x"] = 7, ["y"] = 6, ["param1"] = 86, ["z"] = 11, ["name"] = "wool:brown"}, {["x"] = 7, ["y"] = 6, ["param1"] = 86, ["z"] = 12, ["name"] = "wool:brown"}, {["x"] = 7, ["y"] = 6, ["param1"] = 86, ["z"] = 13, ["name"] = "wool:brown"}, {["x"] = 7, ["y"] = 6, ["z"] = 14, ["name"] = "wool:blue"}, {["x"] = 7, ["y"] = 7, ["param1"] = 88, ["z"] = 5, ["name"] = "wool:red"}, {["x"] = 7, ["y"] = 7, ["param1"] = 88, ["z"] = 10, ["name"] = "wool:red"}, {["x"] = 7, ["y"] = 7, ["z"] = 14, ["name"] = "wool:blue"}, {["x"] = 7, ["y"] = 7, ["z"] = 15, ["name"] = "wool:yellow"}, {["x"] = 7, ["y"] = 8, ["param1"] = 88, ["z"] = 5, ["name"] = "wool:red"}, {["x"] = 7, ["y"] = 8, ["param1"] = 88, ["z"] = 10, ["name"] = "wool:red"}, {["x"] = 7, ["y"] = 8, ["z"] = 14, ["name"] = "wool:blue"}, {["x"] = 7, ["y"] = 8, ["z"] = 15, ["name"] = "wool:yellow"}, {["x"] = 7, ["y"] = 9, ["param1"] = 88, ["z"] = 5, ["name"] = "wool:red"}, {["x"] = 7, ["y"] = 9, ["param1"] = 88, ["z"] = 10, ["name"] = "wool:red"}, {["x"] = 7, ["y"] = 10, ["param1"] = 76, ["z"] = 5, ["name"] = "wool:white"}, {["x"] = 7, ["y"] = 10, ["param1"] = 76, ["z"] = 6, ["name"] = "wool:white"}, {["x"] = 7, ["y"] = 10, ["param1"] = 85, ["z"] = 7, ["name"] = "wool:yellow"}, {["x"] = 7, ["y"] = 10, ["param1"] = 76, ["z"] = 8, ["name"] = "wool:white"}, {["x"] = 7, ["y"] = 10, ["param1"] = 76, ["z"] = 9, ["name"] = "wool:white"}, {["x"] = 7, ["y"] = 10, ["param1"] = 76, ["z"] = 10, ["name"] = "wool:white"}, {["x"] = 7, ["y"] = 11, ["param1"] = 76, ["z"] = 6, ["name"] = "wool:white"}, {["x"] = 7, ["y"] = 11, ["param1"] = 85, ["z"] = 7, ["name"] = "wool:yellow"}, {["x"] = 7, ["y"] = 11, ["param1"] = 76, ["z"] = 8, ["name"] = "wool:white"}, {["x"] = 7, ["y"] = 11, ["param1"] = 76, ["z"] = 9, ["name"] = "wool:white"}, {["x"] = 7, ["y"] = 12, ["param1"] = 76, ["z"] = 6, ["name"] = "wool:white"}, {["x"] = 7, ["y"] = 12, ["param1"] = 76, ["z"] = 7, ["name"] = "wool:white"}, {["x"] = 7, ["y"] = 12, ["param1"] = 76, ["z"] = 8, ["name"] = "wool:white"}, {["x"] = 7, ["y"] = 12, ["param1"] = 76, ["z"] = 9, ["name"] = "wool:white"}, {["x"] = 7, ["y"] = 13, ["param1"] = 76, ["z"] = 6, ["name"] = "wool:white"}, {["x"] = 7, ["y"] = 13, ["param1"] = 76, ["z"] = 7, ["name"] = "wool:white"}, {["x"] = 7, ["y"] = 13, ["param1"] = 76, ["z"] = 8, ["name"] = "wool:white"}, {["x"] = 7, ["y"] = 13, ["param1"] = 76, ["z"] = 9, ["name"] = "wool:white"}, {["x"] = 7, ["y"] = 14, ["param1"] = 76, ["z"] = 6, ["name"] = "wool:white"}, {["x"] = 7, ["y"] = 14, ["param1"] = 76, ["z"] = 7, ["name"] = "wool:white"}, {["x"] = 7, ["y"] = 14, ["param1"] = 76, ["z"] = 8, ["name"] = "wool:white"}, {["x"] = 7, ["y"] = 14, ["param1"] = 76, ["z"] = 9, ["name"] = "wool:white"}, {["x"] = 8, ["y"] = 0, ["param1"] = 81, ["z"] = 3, ["name"] = "wool:blue"}, {["x"] = 8, ["y"] = 0, ["param1"] = 81, ["z"] = 4, ["name"] = "wool:blue"}, {["x"] = 8, ["y"] = 0, ["param1"] = 81, ["z"] = 11, ["name"] = "wool:blue"}, {["x"] = 8, ["y"] = 0, ["param1"] = 81, ["z"] = 12, ["name"] = "wool:blue"}, {["x"] = 8, ["y"] = 0, ["z"] = 13, ["name"] = "wool:blue"}, {["x"] = 8, ["y"] = 0, ["z"] = 14, ["name"] = "wool:blue"}, {["x"] = 8, ["y"] = 1, ["param1"] = 81, ["z"] = 3, ["name"] = "wool:blue"}, {["x"] = 8, ["y"] = 1, ["param1"] = 81, ["z"] = 4, ["name"] = "wool:blue"}, {["x"] = 8, ["y"] = 1, ["param1"] = 81, ["z"] = 11, ["name"] = "wool:blue"}, {["x"] = 8, ["y"] = 1, ["param1"] = 81, ["z"] = 12, ["name"] = "wool:blue"}, {["x"] = 8, ["y"] = 1, ["z"] = 14, ["name"] = "wool:blue"}, {["x"] = 8, ["y"] = 2, ["param1"] = 81, ["z"] = 3, ["name"] = "wool:blue"}, {["x"] = 8, ["y"] = 2, ["param1"] = 81, ["z"] = 4, ["name"] = "wool:blue"}, {["x"] = 8, ["y"] = 2, ["param1"] = 81, ["z"] = 11, ["name"] = "wool:blue"}, {["x"] = 8, ["y"] = 2, ["param1"] = 81, ["z"] = 12, ["name"] = "wool:blue"}, {["x"] = 8, ["y"] = 2, ["z"] = 14, ["name"] = "wool:blue"}, {["x"] = 8, ["y"] = 3, ["z"] = 14, ["name"] = "wool:blue"}, {["x"] = 8, ["y"] = 4, ["z"] = 14, ["name"] = "wool:blue"}, {["x"] = 8, ["y"] = 5, ["param1"] = 86, ["z"] = 3, ["name"] = "wool:brown"}, {["x"] = 8, ["y"] = 5, ["param1"] = 86, ["z"] = 4, ["name"] = "wool:brown"}, {["x"] = 8, ["y"] = 5, ["param1"] = 86, ["z"] = 5, ["name"] = "wool:brown"}, {["x"] = 8, ["y"] = 5, ["param1"] = 86, ["z"] = 6, ["name"] = "wool:brown"}, {["x"] = 8, ["y"] = 5, ["param1"] = 86, ["z"] = 7, ["name"] = "wool:brown"}, {["x"] = 8, ["y"] = 5, ["param1"] = 86, ["z"] = 8, ["name"] = "wool:brown"}, {["x"] = 8, ["y"] = 5, ["param1"] = 86, ["z"] = 9, ["name"] = "wool:brown"}, {["x"] = 8, ["y"] = 5, ["param1"] = 86, ["z"] = 10, ["name"] = "wool:brown"}, {["x"] = 8, ["y"] = 5, ["param1"] = 86, ["z"] = 11, ["name"] = "wool:brown"}, {["x"] = 8, ["y"] = 5, ["param1"] = 86, ["z"] = 12, ["name"] = "wool:brown"}, {["x"] = 8, ["y"] = 5, ["z"] = 14, ["name"] = "wool:blue"}, {["x"] = 8, ["y"] = 6, ["z"] = 14, ["name"] = "wool:blue"}, {["x"] = 8, ["y"] = 7, ["z"] = 14, ["name"] = "wool:blue"}, {["x"] = 8, ["y"] = 7, ["z"] = 15, ["name"] = "wool:yellow"}, {["x"] = 8, ["y"] = 8, ["z"] = 14, ["name"] = "wool:blue"}, {["x"] = 8, ["y"] = 8, ["z"] = 15, ["name"] = "wool:yellow"}, {["x"] = 8, ["y"] = 12, ["param1"] = 85, ["z"] = 7, ["name"] = "wool:yellow"}, {["x"] = 9, ["y"] = 12, ["param1"] = 85, ["z"] = 7, ["name"] = "wool:yellow"}, {["x"] = 10, ["meta"] = {["fields"] = {}, ["inventory"] = {}}, ["y"] = 0, ["param1"] = 84, ["z"] = 5, ["name"] = "wool:green"}, {["x"] = 10, ["meta"] = {["fields"] = {}, ["inventory"] = {}}, ["y"] = 0, ["param1"] = 84, ["z"] = 6, ["name"] = "wool:green"}, {["x"] = 10, ["meta"] = {["fields"] = {}, ["inventory"] = {}}, ["y"] = 0, ["param1"] = 84, ["z"] = 7, ["name"] = "wool:green"}, {["x"] = 10, ["meta"] = {["fields"] = {}, ["inventory"] = {}}, ["y"] = 0, ["param1"] = 84, ["z"] = 8, ["name"] = "wool:green"}, {["x"] = 10, ["meta"] = {["fields"] = {}, ["inventory"] = {}}, ["y"] = 0, ["param1"] = 84, ["z"] = 9, ["name"] = "wool:green"}, {["x"] = 10, ["meta"] = {["fields"] = {}, ["inventory"] = {}}, ["y"] = 0, ["param1"] = 84, ["z"] = 10, ["name"] = "wool:green"}, {["x"] = 10, ["meta"] = {["fields"] = {}, ["inventory"] = {}}, ["y"] = 3, ["param1"] = 81, ["z"] = 6, ["name"] = "default:steelblock"}, {["x"] = 10, ["meta"] = {["fields"] = {}, ["inventory"] = {}}, ["y"] = 3, ["param1"] = 81, ["z"] = 7, ["name"] = "default:steelblock"}, {["x"] = 10, ["meta"] = {["fields"] = {}, ["inventory"] = {}}, ["y"] = 3, ["param1"] = 81, ["z"] = 8, ["name"] = "default:steelblock"}, {["x"] = 10, ["meta"] = {["fields"] = {}, ["inventory"] = {}}, ["y"] = 3, ["param1"] = 81, ["z"] = 9, ["name"] = "default:steelblock"}, {["x"] = 10, ["meta"] = {["fields"] = {}, ["inventory"] = {}}, ["y"] = 4, ["param1"] = 81, ["z"] = 6, ["name"] = "default:steelblock"}, {["x"] = 10, ["meta"] = {["fields"] = {}, ["inventory"] = {}}, ["y"] = 4, ["param1"] = 81, ["z"] = 7, ["name"] = "default:steelblock"}, {["x"] = 10, ["meta"] = {["fields"] = {}, ["inventory"] = {}}, ["y"] = 4, ["param1"] = 81, ["z"] = 8, ["name"] = "default:steelblock"}, {["x"] = 10, ["meta"] = {["fields"] = {}, ["inventory"] = {}}, ["y"] = 4, ["param1"] = 81, ["z"] = 9, ["name"] = "default:steelblock"}, {["x"] = 10, ["meta"] = {["fields"] = {}, ["inventory"] = {}}, ["y"] = 5, ["param1"] = 81, ["z"] = 6, ["name"] = "default:steelblock"}, {["x"] = 10, ["meta"] = {["fields"] = {}, ["inventory"] = {}}, ["y"] = 5, ["param1"] = 81, ["z"] = 7, ["name"] = "default:steelblock"}, {["x"] = 10, ["meta"] = {["fields"] = {}, ["inventory"] = {}}, ["y"] = 5, ["param1"] = 81, ["z"] = 8, ["name"] = "default:steelblock"}, {["x"] = 10, ["meta"] = {["fields"] = {}, ["inventory"] = {}}, ["y"] = 5, ["param1"] = 81, ["z"] = 9, ["name"] = "default:steelblock"}, {["x"] = 10, ["meta"] = {["fields"] = {}, ["inventory"] = {}}, ["y"] = 6, ["param1"] = 81, ["z"] = 6, ["name"] = "default:steelblock"}, {["x"] = 10, ["meta"] = {["fields"] = {}, ["inventory"] = {}}, ["y"] = 6, ["param1"] = 81, ["z"] = 7, ["name"] = "default:steelblock"}, {["x"] = 10, ["meta"] = {["fields"] = {}, ["inventory"] = {}}, ["y"] = 6, ["param1"] = 81, ["z"] = 8, ["name"] = "default:steelblock"}, {["x"] = 10, ["meta"] = {["fields"] = {}, ["inventory"] = {}}, ["y"] = 6, ["param1"] = 81, ["z"] = 9, ["name"] = "default:steelblock"}, {["x"] = 10, ["meta"] = {["fields"] = {}, ["inventory"] = {}}, ["y"] = 7, ["param1"] = 81, ["z"] = 6, ["name"] = "default:steelblock"}, {["x"] = 10, ["meta"] = {["fields"] = {}, ["inventory"] = {}}, ["y"] = 7, ["param1"] = 81, ["z"] = 7, ["name"] = "default:steelblock"}, {["x"] = 10, ["meta"] = {["fields"] = {}, ["inventory"] = {}}, ["y"] = 7, ["param1"] = 81, ["z"] = 8, ["name"] = "default:steelblock"}, {["x"] = 10, ["meta"] = {["fields"] = {}, ["inventory"] = {}}, ["y"] = 7, ["param1"] = 81, ["z"] = 9, ["name"] = "default:steelblock"}, {["x"] = 10, ["meta"] = {["fields"] = {}, ["inventory"] = {}}, ["y"] = 8, ["param1"] = 81, ["z"] = 6, ["name"] = "default:steelblock"}, {["x"] = 10, ["meta"] = {["fields"] = {}, ["inventory"] = {}}, ["y"] = 8, ["param1"] = 81, ["z"] = 7, ["name"] = "default:steelblock"}, {["x"] = 10, ["meta"] = {["fields"] = {}, ["inventory"] = {}}, ["y"] = 8, ["param1"] = 81, ["z"] = 8, ["name"] = "default:steelblock"}, {["x"] = 10, ["meta"] = {["fields"] = {}, ["inventory"] = {}}, ["y"] = 8, ["param1"] = 81, ["z"] = 9, ["name"] = "default:steelblock"}, {["x"] = 10, ["meta"] = {["fields"] = {}, ["inventory"] = {}}, ["y"] = 9, ["param1"] = 81, ["z"] = 6, ["name"] = "default:steelblock"}, {["x"] = 10, ["meta"] = {["fields"] = {}, ["inventory"] = {}}, ["y"] = 9, ["param1"] = 81, ["z"] = 7, ["name"] = "default:steelblock"}, {["x"] = 10, ["meta"] = {["fields"] = {}, ["inventory"] = {}}, ["y"] = 9, ["param1"] = 81, ["z"] = 8, ["name"] = "default:steelblock"}, {["x"] = 10, ["meta"] = {["fields"] = {}, ["inventory"] = {}}, ["y"] = 9, ["param1"] = 81, ["z"] = 9, ["name"] = "default:steelblock"}, {["x"] = 10, ["meta"] = {["fields"] = {}, ["inventory"] = {}}, ["y"] = 10, ["param1"] = 81, ["z"] = 6, ["name"] = "default:steelblock"}, {["x"] = 10, ["meta"] = {["fields"] = {}, ["inventory"] = {}}, ["y"] = 10, ["param1"] = 81, ["z"] = 7, ["name"] = "default:steelblock"}, {["x"] = 10, ["meta"] = {["fields"] = {}, ["inventory"] = {}}, ["y"] = 10, ["param1"] = 81, ["z"] = 8, ["name"] = "default:steelblock"}, {["x"] = 10, ["meta"] = {["fields"] = {}, ["inventory"] = {}}, ["y"] = 10, ["param1"] = 81, ["z"] = 9, ["name"] = "default:steelblock"}, {["x"] = 10, ["meta"] = {["fields"] = {}, ["inventory"] = {}}, ["y"] = 11, ["param1"] = 81, ["z"] = 6, ["name"] = "default:steelblock"}, {["x"] = 10, ["meta"] = {["fields"] = {}, ["inventory"] = {}}, ["y"] = 11, ["param1"] = 81, ["z"] = 7, ["name"] = "default:steelblock"}, {["x"] = 10, ["meta"] = {["fields"] = {}, ["inventory"] = {}}, ["y"] = 11, ["param1"] = 81, ["z"] = 8, ["name"] = "default:steelblock"}, {["x"] = 10, ["meta"] = {["fields"] = {}, ["inventory"] = {}}, ["y"] = 11, ["param1"] = 81, ["z"] = 9, ["name"] = "default:steelblock"}, {["x"] = 10, ["meta"] = {["fields"] = {}, ["inventory"] = {}}, ["y"] = 13, ["param1"] = 85, ["z"] = 7, ["name"] = "wool:yellow"}, {["x"] = 11, ["meta"] = {["fields"] = {}, ["inventory"] = {}}, ["y"] = 0, ["param1"] = 84, ["z"] = 5, ["name"] = "wool:green"}, {["x"] = 11, ["meta"] = {["fields"] = {}, ["inventory"] = {}}, ["y"] = 0, ["param1"] = 84, ["z"] = 6, ["name"] = "wool:green"}, {["x"] = 11, ["meta"] = {["fields"] = {}, ["inventory"] = {}}, ["y"] = 0, ["param1"] = 84, ["z"] = 7, ["name"] = "wool:green"}, {["x"] = 11, ["meta"] = {["fields"] = {}, ["inventory"] = {}}, ["y"] = 0, ["param1"] = 84, ["z"] = 8, ["name"] = "wool:green"}, {["x"] = 11, ["meta"] = {["fields"] = {}, ["inventory"] = {}}, ["y"] = 0, ["param1"] = 84, ["z"] = 9, ["name"] = "wool:green"}, {["x"] = 11, ["meta"] = {["fields"] = {}, ["inventory"] = {}}, ["y"] = 0, ["param1"] = 84, ["z"] = 10, ["name"] = "wool:green"}, {["x"] = 11, ["meta"] = {["fields"] = {}, ["inventory"] = {}}, ["y"] = 1, ["param1"] = 81, ["z"] = 6, ["name"] = "default:steelblock"}, {["x"] = 11, ["meta"] = {["fields"] = {}, ["inventory"] = {}}, ["y"] = 1, ["param1"] = 81, ["z"] = 7, ["name"] = "default:steelblock"}, {["x"] = 11, ["meta"] = {["fields"] = {}, ["inventory"] = {}}, ["y"] = 1, ["param1"] = 81, ["z"] = 8, ["name"] = "default:steelblock"}, {["x"] = 11, ["meta"] = {["fields"] = {}, ["inventory"] = {}}, ["y"] = 1, ["param1"] = 81, ["z"] = 9, ["name"] = "default:steelblock"}, {["x"] = 11, ["meta"] = {["fields"] = {}, ["inventory"] = {}}, ["y"] = 2, ["param1"] = 81, ["z"] = 6, ["name"] = "default:steelblock"}, {["x"] = 11, ["meta"] = {["fields"] = {}, ["inventory"] = {}}, ["y"] = 2, ["param1"] = 81, ["z"] = 7, ["name"] = "default:steelblock"}, {["x"] = 11, ["meta"] = {["fields"] = {}, ["inventory"] = {}}, ["y"] = 2, ["param1"] = 81, ["z"] = 8, ["name"] = "default:steelblock"}, {["x"] = 11, ["meta"] = {["fields"] = {}, ["inventory"] = {}}, ["y"] = 2, ["param1"] = 81, ["z"] = 9, ["name"] = "default:steelblock"}, {["x"] = 11, ["meta"] = {["fields"] = {}, ["inventory"] = {}}, ["y"] = 3, ["param1"] = 81, ["z"] = 5, ["name"] = "default:steelblock"}, {["x"] = 11, ["meta"] = {["fields"] = {}, ["inventory"] = {}}, ["y"] = 3, ["param1"] = 81, ["z"] = 6, ["name"] = "default:steelblock"}, {["x"] = 11, ["meta"] = {["fields"] = {}, ["inventory"] = {}}, ["y"] = 3, ["param1"] = 81, ["z"] = 7, ["name"] = "default:steelblock"}, {["x"] = 11, ["meta"] = {["fields"] = {}, ["inventory"] = {}}, ["y"] = 3, ["param1"] = 81, ["z"] = 8, ["name"] = "default:steelblock"}, {["x"] = 11, ["meta"] = {["fields"] = {}, ["inventory"] = {}}, ["y"] = 3, ["param1"] = 81, ["z"] = 9, ["name"] = "default:steelblock"}, {["x"] = 11, ["meta"] = {["fields"] = {}, ["inventory"] = {}}, ["y"] = 3, ["param1"] = 81, ["z"] = 10, ["name"] = "default:steelblock"}, {["x"] = 11, ["meta"] = {["fields"] = {}, ["inventory"] = {}}, ["y"] = 4, ["param1"] = 81, ["z"] = 5, ["name"] = "default:steelblock"}, {["x"] = 11, ["meta"] = {["fields"] = {}, ["inventory"] = {}}, ["y"] = 4, ["param1"] = 81, ["z"] = 10, ["name"] = "default:steelblock"}, {["x"] = 11, ["meta"] = {["fields"] = {}, ["inventory"] = {}}, ["y"] = 5, ["param1"] = 81, ["z"] = 5, ["name"] = "default:steelblock"}, {["x"] = 11, ["meta"] = {["fields"] = {}, ["inventory"] = {}}, ["y"] = 5, ["param1"] = 81, ["z"] = 10, ["name"] = "default:steelblock"}, {["x"] = 11, ["meta"] = {["fields"] = {}, ["inventory"] = {}}, ["y"] = 6, ["param1"] = 81, ["z"] = 5, ["name"] = "default:steelblock"}, {["x"] = 11, ["meta"] = {["fields"] = {}, ["inventory"] = {}}, ["y"] = 6, ["param1"] = 81, ["z"] = 10, ["name"] = "default:steelblock"}, {["x"] = 11, ["meta"] = {["fields"] = {}, ["inventory"] = {}}, ["y"] = 7, ["param1"] = 81, ["z"] = 5, ["name"] = "default:steelblock"}, {["x"] = 11, ["meta"] = {["fields"] = {}, ["inventory"] = {}}, ["y"] = 7, ["param1"] = 81, ["z"] = 10, ["name"] = "default:steelblock"}, {["x"] = 11, ["meta"] = {["fields"] = {}, ["inventory"] = {}}, ["y"] = 8, ["param1"] = 81, ["z"] = 5, ["name"] = "default:steelblock"}, {["x"] = 11, ["meta"] = {["fields"] = {}, ["inventory"] = {}}, ["y"] = 8, ["param1"] = 81, ["z"] = 10, ["name"] = "default:steelblock"}, {["x"] = 11, ["meta"] = {["fields"] = {}, ["inventory"] = {}}, ["y"] = 9, ["param1"] = 81, ["z"] = 5, ["name"] = "default:steelblock"}, {["x"] = 11, ["meta"] = {["fields"] = {}, ["inventory"] = {}}, ["y"] = 9, ["param1"] = 81, ["z"] = 10, ["name"] = "default:steelblock"}, {["x"] = 11, ["meta"] = {["fields"] = {}, ["inventory"] = {}}, ["y"] = 10, ["param1"] = 81, ["z"] = 5, ["name"] = "default:steelblock"}, {["x"] = 11, ["meta"] = {["fields"] = {}, ["inventory"] = {}}, ["y"] = 10, ["param1"] = 81, ["z"] = 10, ["name"] = "default:steelblock"}, {["x"] = 11, ["meta"] = {["fields"] = {}, ["inventory"] = {}}, ["y"] = 11, ["param1"] = 81, ["z"] = 5, ["name"] = "default:steelblock"}, {["x"] = 11, ["meta"] = {["fields"] = {}, ["inventory"] = {}}, ["y"] = 11, ["param1"] = 81, ["z"] = 10, ["name"] = "default:steelblock"}, {["x"] = 11, ["meta"] = {["fields"] = {}, ["inventory"] = {}}, ["y"] = 12, ["param1"] = 81, ["z"] = 6, ["name"] = "default:steelblock"}, {["x"] = 11, ["meta"] = {["fields"] = {}, ["inventory"] = {}}, ["y"] = 12, ["param1"] = 81, ["z"] = 7, ["name"] = "default:steelblock"}, {["x"] = 11, ["meta"] = {["fields"] = {}, ["inventory"] = {}}, ["y"] = 12, ["param1"] = 81, ["z"] = 8, ["name"] = "default:steelblock"}, {["x"] = 11, ["meta"] = {["fields"] = {}, ["inventory"] = {}}, ["y"] = 12, ["param1"] = 81, ["z"] = 9, ["name"] = "default:steelblock"}, {["x"] = 11, ["meta"] = {["fields"] = {}, ["inventory"] = {}}, ["y"] = 13, ["param1"] = 81, ["z"] = 6, ["name"] = "default:steelblock"}, {["x"] = 11, ["meta"] = {["fields"] = {}, ["inventory"] = {}}, ["y"] = 13, ["param1"] = 85, ["z"] = 7, ["name"] = "wool:yellow"}, {["x"] = 11, ["meta"] = {["fields"] = {}, ["inventory"] = {}}, ["y"] = 13, ["param1"] = 81, ["z"] = 9, ["name"] = "default:steelblock"}, {["x"] = 11, ["meta"] = {["fields"] = {}, ["inventory"] = {}}, ["y"] = 14, ["param1"] = 81, ["z"] = 6, ["name"] = "default:steelblock"}, {["x"] = 11, ["meta"] = {["fields"] = {}, ["inventory"] = {}}, ["y"] = 14, ["param1"] = 81, ["z"] = 9, ["name"] = "default:steelblock"}, {["x"] = 11, ["meta"] = {["fields"] = {}, ["inventory"] = {}}, ["y"] = 15, ["param1"] = 81, ["z"] = 6, ["name"] = "default:steelblock"}, {["x"] = 11, ["meta"] = {["fields"] = {}, ["inventory"] = {}}, ["y"] = 15, ["param1"] = 81, ["z"] = 7, ["name"] = "default:steelblock"}, {["x"] = 11, ["meta"] = {["fields"] = {}, ["inventory"] = {}}, ["y"] = 15, ["param1"] = 81, ["z"] = 8, ["name"] = "default:steelblock"}, {["x"] = 11, ["meta"] = {["fields"] = {}, ["inventory"] = {}}, ["y"] = 15, ["param1"] = 81, ["z"] = 9, ["name"] = "default:steelblock"}, {["x"] = 12, ["meta"] = {["fields"] = {}, ["inventory"] = {}}, ["y"] = 0, ["param1"] = 84, ["z"] = 5, ["name"] = "wool:green"}, {["x"] = 12, ["meta"] = {["fields"] = {}, ["inventory"] = {}}, ["y"] = 0, ["param1"] = 84, ["z"] = 6, ["name"] = "wool:green"}, {["x"] = 12, ["meta"] = {["fields"] = {}, ["inventory"] = {}}, ["y"] = 0, ["param1"] = 84, ["z"] = 7, ["name"] = "wool:green"}, {["x"] = 12, ["meta"] = {["fields"] = {}, ["inventory"] = {}}, ["y"] = 0, ["param1"] = 84, ["z"] = 8, ["name"] = "wool:green"}, {["x"] = 12, ["meta"] = {["fields"] = {}, ["inventory"] = {}}, ["y"] = 0, ["param1"] = 84, ["z"] = 9, ["name"] = "wool:green"}, {["x"] = 12, ["meta"] = {["fields"] = {}, ["inventory"] = {}}, ["y"] = 0, ["param1"] = 84, ["z"] = 10, ["name"] = "wool:green"}, {["x"] = 12, ["meta"] = {["fields"] = {}, ["inventory"] = {}}, ["y"] = 1, ["param1"] = 81, ["z"] = 6, ["name"] = "default:steelblock"}, {["x"] = 12, ["meta"] = {["fields"] = {}, ["inventory"] = {}}, ["y"] = 1, ["param1"] = 81, ["z"] = 9, ["name"] = "default:steelblock"}, {["x"] = 12, ["meta"] = {["fields"] = {}, ["inventory"] = {}}, ["y"] = 2, ["param1"] = 81, ["z"] = 6, ["name"] = "default:steelblock"}, {["x"] = 12, ["meta"] = {["fields"] = {}, ["inventory"] = {}}, ["y"] = 2, ["param1"] = 81, ["z"] = 9, ["name"] = "default:steelblock"}, {["x"] = 12, ["meta"] = {["fields"] = {}, ["inventory"] = {}}, ["y"] = 3, ["param1"] = 81, ["z"] = 5, ["name"] = "default:steelblock"}, {["x"] = 12, ["meta"] = {["fields"] = {}, ["inventory"] = {}}, ["y"] = 3, ["param1"] = 81, ["z"] = 6, ["name"] = "default:steelblock"}, {["x"] = 12, ["meta"] = {["fields"] = {}, ["inventory"] = {}}, ["y"] = 3, ["param1"] = 81, ["z"] = 7, ["name"] = "default:steelblock"}, {["x"] = 12, ["meta"] = {["fields"] = {}, ["inventory"] = {}}, ["y"] = 3, ["param1"] = 81, ["z"] = 8, ["name"] = "default:steelblock"}, {["x"] = 12, ["meta"] = {["fields"] = {}, ["inventory"] = {}}, ["y"] = 3, ["param1"] = 81, ["z"] = 9, ["name"] = "default:steelblock"}, {["x"] = 12, ["meta"] = {["fields"] = {}, ["inventory"] = {}}, ["y"] = 3, ["param1"] = 81, ["z"] = 10, ["name"] = "default:steelblock"}, {["x"] = 12, ["meta"] = {["fields"] = {}, ["inventory"] = {}}, ["y"] = 4, ["param1"] = 81, ["z"] = 5, ["name"] = "default:steelblock"}, {["x"] = 12, ["meta"] = {["fields"] = {}, ["inventory"] = {}}, ["y"] = 4, ["param1"] = 81, ["z"] = 10, ["name"] = "default:steelblock"}, {["x"] = 12, ["meta"] = {["fields"] = {}, ["inventory"] = {}}, ["y"] = 5, ["param1"] = 81, ["z"] = 5, ["name"] = "default:steelblock"}, {["x"] = 12, ["meta"] = {["fields"] = {}, ["inventory"] = {}}, ["y"] = 5, ["param1"] = 81, ["z"] = 10, ["name"] = "default:steelblock"}, {["x"] = 12, ["meta"] = {["fields"] = {}, ["inventory"] = {}}, ["y"] = 6, ["param1"] = 81, ["z"] = 5, ["name"] = "default:steelblock"}, {["x"] = 12, ["meta"] = {["fields"] = {}, ["inventory"] = {}}, ["y"] = 6, ["param1"] = 81, ["z"] = 10, ["name"] = "default:steelblock"}, {["x"] = 12, ["meta"] = {["fields"] = {}, ["inventory"] = {}}, ["y"] = 7, ["param1"] = 81, ["z"] = 5, ["name"] = "default:steelblock"}, {["x"] = 12, ["meta"] = {["fields"] = {}, ["inventory"] = {}}, ["y"] = 7, ["param1"] = 81, ["z"] = 10, ["name"] = "default:steelblock"}, {["x"] = 12, ["meta"] = {["fields"] = {}, ["inventory"] = {}}, ["y"] = 8, ["param1"] = 81, ["z"] = 5, ["name"] = "default:steelblock"}, {["x"] = 12, ["meta"] = {["fields"] = {}, ["inventory"] = {}}, ["y"] = 8, ["param1"] = 81, ["z"] = 10, ["name"] = "default:steelblock"}, {["x"] = 12, ["meta"] = {["fields"] = {}, ["inventory"] = {}}, ["y"] = 9, ["param1"] = 81, ["z"] = 5, ["name"] = "default:steelblock"}, {["x"] = 12, ["meta"] = {["fields"] = {}, ["inventory"] = {}}, ["y"] = 9, ["param1"] = 81, ["z"] = 10, ["name"] = "default:steelblock"}, {["x"] = 12, ["meta"] = {["fields"] = {}, ["inventory"] = {}}, ["y"] = 10, ["param1"] = 81, ["z"] = 5, ["name"] = "default:steelblock"}, {["x"] = 12, ["meta"] = {["fields"] = {}, ["inventory"] = {}}, ["y"] = 10, ["param1"] = 81, ["z"] = 10, ["name"] = "default:steelblock"}, {["x"] = 12, ["meta"] = {["fields"] = {}, ["inventory"] = {}}, ["y"] = 11, ["param1"] = 81, ["z"] = 5, ["name"] = "default:steelblock"}, {["x"] = 12, ["meta"] = {["fields"] = {}, ["inventory"] = {}}, ["y"] = 11, ["param1"] = 81, ["z"] = 10, ["name"] = "default:steelblock"}, {["x"] = 12, ["meta"] = {["fields"] = {}, ["inventory"] = {}}, ["y"] = 12, ["param1"] = 81, ["z"] = 6, ["name"] = "default:steelblock"}, {["x"] = 12, ["meta"] = {["fields"] = {}, ["inventory"] = {}}, ["y"] = 12, ["param1"] = 81, ["z"] = 7, ["name"] = "default:steelblock"}, {["x"] = 12, ["meta"] = {["fields"] = {}, ["inventory"] = {}}, ["y"] = 12, ["param1"] = 81, ["z"] = 8, ["name"] = "default:steelblock"}, {["x"] = 12, ["meta"] = {["fields"] = {}, ["inventory"] = {}}, ["y"] = 12, ["param1"] = 81, ["z"] = 9, ["name"] = "default:steelblock"}, {["x"] = 12, ["meta"] = {["fields"] = {}, ["inventory"] = {}}, ["y"] = 13, ["param1"] = 85, ["z"] = 7, ["name"] = "wool:yellow"}, {["x"] = 12, ["meta"] = {["fields"] = {}, ["inventory"] = {}}, ["y"] = 15, ["param1"] = 81, ["z"] = 6, ["name"] = "default:steelblock"}, {["x"] = 12, ["meta"] = {["fields"] = {}, ["inventory"] = {}}, ["y"] = 15, ["param1"] = 81, ["z"] = 9, ["name"] = "default:steelblock"}, {["x"] = 13, ["meta"] = {["fields"] = {}, ["inventory"] = {}}, ["y"] = 0, ["param1"] = 84, ["z"] = 5, ["name"] = "wool:green"}, {["x"] = 13, ["meta"] = {["fields"] = {}, ["inventory"] = {}}, ["y"] = 0, ["param1"] = 84, ["z"] = 6, ["name"] = "wool:green"}, {["x"] = 13, ["meta"] = {["fields"] = {}, ["inventory"] = {}}, ["y"] = 0, ["param1"] = 84, ["z"] = 7, ["name"] = "wool:green"}, {["x"] = 13, ["meta"] = {["fields"] = {}, ["inventory"] = {}}, ["y"] = 0, ["param1"] = 84, ["z"] = 8, ["name"] = "wool:green"}, {["x"] = 13, ["meta"] = {["fields"] = {}, ["inventory"] = {}}, ["y"] = 0, ["param1"] = 84, ["z"] = 9, ["name"] = "wool:green"}, {["x"] = 13, ["meta"] = {["fields"] = {}, ["inventory"] = {}}, ["y"] = 0, ["param1"] = 84, ["z"] = 10, ["name"] = "wool:green"}, {["x"] = 13, ["meta"] = {["fields"] = {}, ["inventory"] = {}}, ["y"] = 1, ["param1"] = 81, ["z"] = 6, ["name"] = "default:steelblock"}, {["x"] = 13, ["meta"] = {["fields"] = {}, ["inventory"] = {}}, ["y"] = 1, ["param1"] = 81, ["z"] = 9, ["name"] = "default:steelblock"}, {["x"] = 13, ["meta"] = {["fields"] = {}, ["inventory"] = {}}, ["y"] = 2, ["param1"] = 81, ["z"] = 6, ["name"] = "default:steelblock"}, {["x"] = 13, ["meta"] = {["fields"] = {}, ["inventory"] = {}}, ["y"] = 2, ["param1"] = 81, ["z"] = 9, ["name"] = "default:steelblock"}, {["x"] = 13, ["meta"] = {["fields"] = {}, ["inventory"] = {}}, ["y"] = 3, ["param1"] = 81, ["z"] = 5, ["name"] = "default:steelblock"}, {["x"] = 13, ["meta"] = {["fields"] = {}, ["inventory"] = {}}, ["y"] = 3, ["param1"] = 81, ["z"] = 6, ["name"] = "default:steelblock"}, {["x"] = 13, ["meta"] = {["fields"] = {}, ["inventory"] = {}}, ["y"] = 3, ["param1"] = 81, ["z"] = 7, ["name"] = "default:steelblock"}, {["x"] = 13, ["meta"] = {["fields"] = {}, ["inventory"] = {}}, ["y"] = 3, ["param1"] = 81, ["z"] = 8, ["name"] = "default:steelblock"}, {["x"] = 13, ["meta"] = {["fields"] = {}, ["inventory"] = {}}, ["y"] = 3, ["param1"] = 81, ["z"] = 9, ["name"] = "default:steelblock"}, {["x"] = 13, ["meta"] = {["fields"] = {}, ["inventory"] = {}}, ["y"] = 3, ["param1"] = 81, ["z"] = 10, ["name"] = "default:steelblock"}, {["x"] = 13, ["meta"] = {["fields"] = {}, ["inventory"] = {}}, ["y"] = 4, ["param1"] = 81, ["z"] = 5, ["name"] = "default:steelblock"}, {["x"] = 13, ["meta"] = {["fields"] = {}, ["inventory"] = {}}, ["y"] = 4, ["param1"] = 81, ["z"] = 10, ["name"] = "default:steelblock"}, {["x"] = 13, ["meta"] = {["fields"] = {}, ["inventory"] = {}}, ["y"] = 5, ["param1"] = 81, ["z"] = 5, ["name"] = "default:steelblock"}, {["x"] = 13, ["meta"] = {["fields"] = {}, ["inventory"] = {}}, ["y"] = 5, ["param1"] = 81, ["z"] = 10, ["name"] = "default:steelblock"}, {["x"] = 13, ["meta"] = {["fields"] = {}, ["inventory"] = {}}, ["y"] = 6, ["param1"] = 81, ["z"] = 5, ["name"] = "default:steelblock"}, {["x"] = 13, ["meta"] = {["fields"] = {}, ["inventory"] = {}}, ["y"] = 6, ["param1"] = 81, ["z"] = 10, ["name"] = "default:steelblock"}, {["x"] = 13, ["meta"] = {["fields"] = {}, ["inventory"] = {}}, ["y"] = 7, ["param1"] = 81, ["z"] = 5, ["name"] = "default:steelblock"}, {["x"] = 13, ["meta"] = {["fields"] = {}, ["inventory"] = {}}, ["y"] = 7, ["param1"] = 81, ["z"] = 10, ["name"] = "default:steelblock"}, {["x"] = 13, ["meta"] = {["fields"] = {}, ["inventory"] = {}}, ["y"] = 8, ["param1"] = 81, ["z"] = 5, ["name"] = "default:steelblock"}, {["x"] = 13, ["meta"] = {["fields"] = {}, ["inventory"] = {}}, ["y"] = 8, ["param1"] = 81, ["z"] = 10, ["name"] = "default:steelblock"}, {["x"] = 13, ["meta"] = {["fields"] = {}, ["inventory"] = {}}, ["y"] = 9, ["param1"] = 81, ["z"] = 5, ["name"] = "default:steelblock"}, {["x"] = 13, ["meta"] = {["fields"] = {}, ["inventory"] = {}}, ["y"] = 9, ["param1"] = 81, ["z"] = 10, ["name"] = "default:steelblock"}, {["x"] = 13, ["meta"] = {["fields"] = {}, ["inventory"] = {}}, ["y"] = 10, ["param1"] = 81, ["z"] = 5, ["name"] = "default:steelblock"}, {["x"] = 13, ["meta"] = {["fields"] = {}, ["inventory"] = {}}, ["y"] = 10, ["param1"] = 81, ["z"] = 10, ["name"] = "default:steelblock"}, {["x"] = 13, ["meta"] = {["fields"] = {}, ["inventory"] = {}}, ["y"] = 11, ["param1"] = 81, ["z"] = 5, ["name"] = "default:steelblock"}, {["x"] = 13, ["meta"] = {["fields"] = {}, ["inventory"] = {}}, ["y"] = 11, ["param1"] = 81, ["z"] = 10, ["name"] = "default:steelblock"}, {["x"] = 13, ["meta"] = {["fields"] = {}, ["inventory"] = {}}, ["y"] = 12, ["param1"] = 81, ["z"] = 6, ["name"] = "default:steelblock"}, {["x"] = 13, ["meta"] = {["fields"] = {}, ["inventory"] = {}}, ["y"] = 12, ["param1"] = 81, ["z"] = 7, ["name"] = "default:steelblock"}, {["x"] = 13, ["meta"] = {["fields"] = {}, ["inventory"] = {}}, ["y"] = 12, ["param1"] = 81, ["z"] = 8, ["name"] = "default:steelblock"}, {["x"] = 13, ["meta"] = {["fields"] = {}, ["inventory"] = {}}, ["y"] = 12, ["param1"] = 81, ["z"] = 9, ["name"] = "default:steelblock"}, {["x"] = 13, ["meta"] = {["fields"] = {}, ["inventory"] = {}}, ["y"] = 15, ["param1"] = 81, ["z"] = 6, ["name"] = "default:steelblock"}, {["x"] = 13, ["meta"] = {["fields"] = {}, ["inventory"] = {}}, ["y"] = 15, ["param1"] = 81, ["z"] = 9, ["name"] = "default:steelblock"}, {["x"] = 14, ["meta"] = {["fields"] = {}, ["inventory"] = {}}, ["y"] = 0, ["param1"] = 84, ["z"] = 5, ["name"] = "wool:green"}, {["x"] = 14, ["meta"] = {["fields"] = {}, ["inventory"] = {}}, ["y"] = 0, ["param1"] = 84, ["z"] = 6, ["name"] = "wool:green"}, {["x"] = 14, ["meta"] = {["fields"] = {}, ["inventory"] = {}}, ["y"] = 0, ["param1"] = 84, ["z"] = 7, ["name"] = "wool:green"}, {["x"] = 14, ["meta"] = {["fields"] = {}, ["inventory"] = {}}, ["y"] = 0, ["param1"] = 84, ["z"] = 8, ["name"] = "wool:green"}, {["x"] = 14, ["meta"] = {["fields"] = {}, ["inventory"] = {}}, ["y"] = 0, ["param1"] = 84, ["z"] = 9, ["name"] = "wool:green"}, {["x"] = 14, ["meta"] = {["fields"] = {}, ["inventory"] = {}}, ["y"] = 0, ["param1"] = 84, ["z"] = 10, ["name"] = "wool:green"}, {["x"] = 14, ["meta"] = {["fields"] = {}, ["inventory"] = {}}, ["y"] = 1, ["param1"] = 81, ["z"] = 6, ["name"] = "default:steelblock"}, {["x"] = 14, ["meta"] = {["fields"] = {}, ["inventory"] = {}}, ["y"] = 1, ["param1"] = 81, ["z"] = 7, ["name"] = "default:steelblock"}, {["x"] = 14, ["meta"] = {["fields"] = {}, ["inventory"] = {}}, ["y"] = 1, ["param1"] = 81, ["z"] = 8, ["name"] = "default:steelblock"}, {["x"] = 14, ["meta"] = {["fields"] = {}, ["inventory"] = {}}, ["y"] = 1, ["param1"] = 81, ["z"] = 9, ["name"] = "default:steelblock"}, {["x"] = 14, ["meta"] = {["fields"] = {}, ["inventory"] = {}}, ["y"] = 2, ["param1"] = 81, ["z"] = 6, ["name"] = "default:steelblock"}, {["x"] = 14, ["meta"] = {["fields"] = {}, ["inventory"] = {}}, ["y"] = 2, ["param1"] = 81, ["z"] = 7, ["name"] = "default:steelblock"}, {["x"] = 14, ["meta"] = {["fields"] = {}, ["inventory"] = {}}, ["y"] = 2, ["param1"] = 81, ["z"] = 8, ["name"] = "default:steelblock"}, {["x"] = 14, ["meta"] = {["fields"] = {}, ["inventory"] = {}}, ["y"] = 2, ["param1"] = 81, ["z"] = 9, ["name"] = "default:steelblock"}, {["x"] = 14, ["meta"] = {["fields"] = {}, ["inventory"] = {}}, ["y"] = 3, ["param1"] = 81, ["z"] = 5, ["name"] = "default:steelblock"}, {["x"] = 14, ["meta"] = {["fields"] = {}, ["inventory"] = {}}, ["y"] = 3, ["param1"] = 81, ["z"] = 6, ["name"] = "default:steelblock"}, {["x"] = 14, ["meta"] = {["fields"] = {}, ["inventory"] = {}}, ["y"] = 3, ["param1"] = 81, ["z"] = 7, ["name"] = "default:steelblock"}, {["x"] = 14, ["meta"] = {["fields"] = {}, ["inventory"] = {}}, ["y"] = 3, ["param1"] = 81, ["z"] = 8, ["name"] = "default:steelblock"}, {["x"] = 14, ["meta"] = {["fields"] = {}, ["inventory"] = {}}, ["y"] = 3, ["param1"] = 81, ["z"] = 9, ["name"] = "default:steelblock"}, {["x"] = 14, ["meta"] = {["fields"] = {}, ["inventory"] = {}}, ["y"] = 3, ["param1"] = 81, ["z"] = 10, ["name"] = "default:steelblock"}, {["x"] = 14, ["meta"] = {["fields"] = {}, ["inventory"] = {}}, ["y"] = 4, ["param1"] = 81, ["z"] = 5, ["name"] = "default:steelblock"}, {["x"] = 14, ["meta"] = {["fields"] = {}, ["inventory"] = {}}, ["y"] = 4, ["param1"] = 81, ["z"] = 10, ["name"] = "default:steelblock"}, {["x"] = 14, ["meta"] = {["fields"] = {}, ["inventory"] = {}}, ["y"] = 5, ["param1"] = 81, ["z"] = 5, ["name"] = "default:steelblock"}, {["x"] = 14, ["meta"] = {["fields"] = {}, ["inventory"] = {}}, ["y"] = 5, ["param1"] = 81, ["z"] = 10, ["name"] = "default:steelblock"}, {["x"] = 14, ["meta"] = {["fields"] = {}, ["inventory"] = {}}, ["y"] = 6, ["param1"] = 81, ["z"] = 5, ["name"] = "default:steelblock"}, {["x"] = 14, ["meta"] = {["fields"] = {}, ["inventory"] = {}}, ["y"] = 6, ["param1"] = 81, ["z"] = 10, ["name"] = "default:steelblock"}, {["x"] = 14, ["meta"] = {["fields"] = {}, ["inventory"] = {}}, ["y"] = 7, ["param1"] = 81, ["z"] = 5, ["name"] = "default:steelblock"}, {["x"] = 14, ["meta"] = {["fields"] = {}, ["inventory"] = {}}, ["y"] = 7, ["param1"] = 81, ["z"] = 10, ["name"] = "default:steelblock"}, {["x"] = 14, ["meta"] = {["fields"] = {}, ["inventory"] = {}}, ["y"] = 8, ["param1"] = 81, ["z"] = 5, ["name"] = "default:steelblock"}, {["x"] = 14, ["meta"] = {["fields"] = {}, ["inventory"] = {}}, ["y"] = 8, ["param1"] = 81, ["z"] = 10, ["name"] = "default:steelblock"}, {["x"] = 14, ["meta"] = {["fields"] = {}, ["inventory"] = {}}, ["y"] = 9, ["param1"] = 81, ["z"] = 5, ["name"] = "default:steelblock"}, {["x"] = 14, ["meta"] = {["fields"] = {}, ["inventory"] = {}}, ["y"] = 9, ["param1"] = 81, ["z"] = 10, ["name"] = "default:steelblock"}, {["x"] = 14, ["meta"] = {["fields"] = {}, ["inventory"] = {}}, ["y"] = 10, ["param1"] = 81, ["z"] = 5, ["name"] = "default:steelblock"}, {["x"] = 14, ["meta"] = {["fields"] = {}, ["inventory"] = {}}, ["y"] = 10, ["param1"] = 81, ["z"] = 10, ["name"] = "default:steelblock"}, {["x"] = 14, ["meta"] = {["fields"] = {}, ["inventory"] = {}}, ["y"] = 11, ["param1"] = 81, ["z"] = 5, ["name"] = "default:steelblock"}, {["x"] = 14, ["meta"] = {["fields"] = {}, ["inventory"] = {}}, ["y"] = 11, ["param1"] = 81, ["z"] = 10, ["name"] = "default:steelblock"}, {["x"] = 14, ["meta"] = {["fields"] = {}, ["inventory"] = {}}, ["y"] = 12, ["param1"] = 81, ["z"] = 6, ["name"] = "default:steelblock"}, {["x"] = 14, ["meta"] = {["fields"] = {}, ["inventory"] = {}}, ["y"] = 12, ["param1"] = 81, ["z"] = 7, ["name"] = "default:steelblock"}, {["x"] = 14, ["meta"] = {["fields"] = {}, ["inventory"] = {}}, ["y"] = 12, ["param1"] = 81, ["z"] = 8, ["name"] = "default:steelblock"}, {["x"] = 14, ["meta"] = {["fields"] = {}, ["inventory"] = {}}, ["y"] = 12, ["param1"] = 81, ["z"] = 9, ["name"] = "default:steelblock"}, {["x"] = 14, ["meta"] = {["fields"] = {}, ["inventory"] = {}}, ["y"] = 13, ["param1"] = 81, ["z"] = 6, ["name"] = "default:steelblock"}, {["x"] = 14, ["meta"] = {["fields"] = {}, ["inventory"] = {}}, ["y"] = 13, ["param1"] = 81, ["z"] = 9, ["name"] = "default:steelblock"}, {["x"] = 14, ["meta"] = {["fields"] = {}, ["inventory"] = {}}, ["y"] = 14, ["param1"] = 81, ["z"] = 6, ["name"] = "default:steelblock"}, {["x"] = 14, ["meta"] = {["fields"] = {}, ["inventory"] = {}}, ["y"] = 14, ["param1"] = 81, ["z"] = 9, ["name"] = "default:steelblock"}, {["x"] = 14, ["meta"] = {["fields"] = {}, ["inventory"] = {}}, ["y"] = 15, ["param1"] = 81, ["z"] = 6, ["name"] = "default:steelblock"}, {["x"] = 14, ["meta"] = {["fields"] = {}, ["inventory"] = {}}, ["y"] = 15, ["param1"] = 81, ["z"] = 7, ["name"] = "default:steelblock"}, {["x"] = 14, ["meta"] = {["fields"] = {}, ["inventory"] = {}}, ["y"] = 15, ["param1"] = 81, ["z"] = 8, ["name"] = "default:steelblock"}, {["x"] = 14, ["meta"] = {["fields"] = {}, ["inventory"] = {}}, ["y"] = 15, ["param1"] = 81, ["z"] = 9, ["name"] = "default:steelblock"}, {["x"] = 15, ["meta"] = {["fields"] = {}, ["inventory"] = {}}, ["y"] = 0, ["param1"] = 84, ["z"] = 5, ["name"] = "wool:green"}, {["x"] = 15, ["meta"] = {["fields"] = {}, ["inventory"] = {}}, ["y"] = 0, ["param1"] = 84, ["z"] = 6, ["name"] = "wool:green"}, {["x"] = 15, ["meta"] = {["fields"] = {}, ["inventory"] = {}}, ["y"] = 0, ["param1"] = 84, ["z"] = 7, ["name"] = "wool:green"}, {["x"] = 15, ["meta"] = {["fields"] = {}, ["inventory"] = {}}, ["y"] = 0, ["param1"] = 84, ["z"] = 8, ["name"] = "wool:green"}, {["x"] = 15, ["meta"] = {["fields"] = {}, ["inventory"] = {}}, ["y"] = 0, ["param1"] = 84, ["z"] = 9, ["name"] = "wool:green"}, {["x"] = 15, ["meta"] = {["fields"] = {}, ["inventory"] = {}}, ["y"] = 0, ["param1"] = 84, ["z"] = 10, ["name"] = "wool:green"}, {["x"] = 15, ["meta"] = {["fields"] = {}, ["inventory"] = {}}, ["y"] = 3, ["param1"] = 81, ["z"] = 6, ["name"] = "default:steelblock"}, {["x"] = 15, ["meta"] = {["fields"] = {}, ["inventory"] = {}}, ["y"] = 3, ["param1"] = 81, ["z"] = 7, ["name"] = "default:steelblock"}, {["x"] = 15, ["meta"] = {["fields"] = {}, ["inventory"] = {}}, ["y"] = 3, ["param1"] = 81, ["z"] = 8, ["name"] = "default:steelblock"}, {["x"] = 15, ["meta"] = {["fields"] = {}, ["inventory"] = {}}, ["y"] = 3, ["param1"] = 81, ["z"] = 9, ["name"] = "default:steelblock"}, {["x"] = 15, ["meta"] = {["fields"] = {}, ["inventory"] = {}}, ["y"] = 4, ["param1"] = 81, ["z"] = 6, ["name"] = "default:steelblock"}, {["x"] = 15, ["meta"] = {["fields"] = {}, ["inventory"] = {}}, ["y"] = 4, ["param1"] = 81, ["z"] = 7, ["name"] = "default:steelblock"}, {["x"] = 15, ["meta"] = {["fields"] = {}, ["inventory"] = {}}, ["y"] = 4, ["param1"] = 81, ["z"] = 8, ["name"] = "default:steelblock"}, {["x"] = 15, ["meta"] = {["fields"] = {}, ["inventory"] = {}}, ["y"] = 4, ["param1"] = 81, ["z"] = 9, ["name"] = "default:steelblock"}, {["x"] = 15, ["meta"] = {["fields"] = {}, ["inventory"] = {}}, ["y"] = 5, ["param1"] = 81, ["z"] = 6, ["name"] = "default:steelblock"}, {["x"] = 15, ["meta"] = {["fields"] = {}, ["inventory"] = {}}, ["y"] = 5, ["param1"] = 81, ["z"] = 7, ["name"] = "default:steelblock"}, {["x"] = 15, ["meta"] = {["fields"] = {}, ["inventory"] = {}}, ["y"] = 5, ["param1"] = 81, ["z"] = 8, ["name"] = "default:steelblock"}, {["x"] = 15, ["meta"] = {["fields"] = {}, ["inventory"] = {}}, ["y"] = 5, ["param1"] = 81, ["z"] = 9, ["name"] = "default:steelblock"}, {["x"] = 15, ["meta"] = {["fields"] = {}, ["inventory"] = {}}, ["y"] = 6, ["param1"] = 81, ["z"] = 6, ["name"] = "default:steelblock"}, {["x"] = 15, ["meta"] = {["fields"] = {}, ["inventory"] = {}}, ["y"] = 6, ["param1"] = 81, ["z"] = 7, ["name"] = "default:steelblock"}, {["x"] = 15, ["meta"] = {["fields"] = {}, ["inventory"] = {}}, ["y"] = 6, ["param1"] = 81, ["z"] = 8, ["name"] = "default:steelblock"}, {["x"] = 15, ["meta"] = {["fields"] = {}, ["inventory"] = {}}, ["y"] = 6, ["param1"] = 81, ["z"] = 9, ["name"] = "default:steelblock"}, {["x"] = 15, ["meta"] = {["fields"] = {}, ["inventory"] = {}}, ["y"] = 7, ["param1"] = 81, ["z"] = 6, ["name"] = "default:steelblock"}, {["x"] = 15, ["meta"] = {["fields"] = {}, ["inventory"] = {}}, ["y"] = 7, ["param1"] = 81, ["z"] = 7, ["name"] = "default:steelblock"}, {["x"] = 15, ["meta"] = {["fields"] = {}, ["inventory"] = {}}, ["y"] = 7, ["param1"] = 81, ["z"] = 8, ["name"] = "default:steelblock"}, {["x"] = 15, ["meta"] = {["fields"] = {}, ["inventory"] = {}}, ["y"] = 7, ["param1"] = 81, ["z"] = 9, ["name"] = "default:steelblock"}, {["x"] = 15, ["meta"] = {["fields"] = {}, ["inventory"] = {}}, ["y"] = 8, ["param1"] = 81, ["z"] = 6, ["name"] = "default:steelblock"}, {["x"] = 15, ["meta"] = {["fields"] = {}, ["inventory"] = {}}, ["y"] = 8, ["param1"] = 81, ["z"] = 7, ["name"] = "default:steelblock"}, {["x"] = 15, ["meta"] = {["fields"] = {}, ["inventory"] = {}}, ["y"] = 8, ["param1"] = 81, ["z"] = 8, ["name"] = "default:steelblock"}, {["x"] = 15, ["meta"] = {["fields"] = {}, ["inventory"] = {}}, ["y"] = 8, ["param1"] = 81, ["z"] = 9, ["name"] = "default:steelblock"}, {["x"] = 15, ["meta"] = {["fields"] = {}, ["inventory"] = {}}, ["y"] = 9, ["param1"] = 81, ["z"] = 6, ["name"] = "default:steelblock"}, {["x"] = 15, ["meta"] = {["fields"] = {}, ["inventory"] = {}}, ["y"] = 9, ["param1"] = 81, ["z"] = 7, ["name"] = "default:steelblock"}, {["x"] = 15, ["meta"] = {["fields"] = {}, ["inventory"] = {}}, ["y"] = 9, ["param1"] = 81, ["z"] = 8, ["name"] = "default:steelblock"}, {["x"] = 15, ["meta"] = {["fields"] = {}, ["inventory"] = {}}, ["y"] = 9, ["param1"] = 81, ["z"] = 9, ["name"] = "default:steelblock"}, {["x"] = 15, ["meta"] = {["fields"] = {}, ["inventory"] = {}}, ["y"] = 10, ["param1"] = 81, ["z"] = 6, ["name"] = "default:steelblock"}, {["x"] = 15, ["meta"] = {["fields"] = {}, ["inventory"] = {}}, ["y"] = 10, ["param1"] = 81, ["z"] = 7, ["name"] = "default:steelblock"}, {["x"] = 15, ["meta"] = {["fields"] = {}, ["inventory"] = {}}, ["y"] = 10, ["param1"] = 81, ["z"] = 8, ["name"] = "default:steelblock"}, {["x"] = 15, ["meta"] = {["fields"] = {}, ["inventory"] = {}}, ["y"] = 10, ["param1"] = 81, ["z"] = 9, ["name"] = "default:steelblock"}, {["x"] = 15, ["meta"] = {["fields"] = {}, ["inventory"] = {}}, ["y"] = 11, ["param1"] = 81, ["z"] = 6, ["name"] = "default:steelblock"}, {["x"] = 15, ["meta"] = {["fields"] = {}, ["inventory"] = {}}, ["y"] = 11, ["param1"] = 81, ["z"] = 7, ["name"] = "default:steelblock"}, {["x"] = 15, ["meta"] = {["fields"] = {}, ["inventory"] = {}}, ["y"] = 11, ["param1"] = 81, ["z"] = 8, ["name"] = "default:steelblock"}, {["x"] = 15, ["meta"] = {["fields"] = {}, ["inventory"] = {}}, ["y"] = 11, ["param1"] = 81, ["z"] = 9, ["name"] = "default:steelblock"}}