5:return {{["x"] = 0, ["y"] = 7, ["z"] = 7, ["name"] = "wool:yellow"}, {["x"] = 0, ["y"] = 7, ["z"] = 8, ["name"] = "wool:yellow"}, {["x"] = 0, ["y"] = 8, ["z"] = 7, ["name"] = "wool:yellow"}, {["x"] = 0, ["y"] = 8, ["z"] = 8, ["name"] = "wool:yellow"}, {["x"] = 1, ["y"] = 7, ["z"] = 7, ["name"] = "wool:yellow"}, {["x"] = 1, ["y"] = 8, ["z"] = 7, ["name"] = "wool:red"}, {["x"] = 2, ["y"] = 0, ["param1"] = 88, ["z"] = 2, ["name"] = "wool:red"}, {["x"] = 2, ["y"] = 0, ["param1"] = 88, ["z"] = 3, ["name"] = "wool:red"}, {["x"] = 2, ["y"] = 0, ["param1"] = 88, ["z"] = 4, ["name"] = "wool:red"}, {["x"] = 2, ["y"] = 0, ["param1"] = 88, ["z"] = 5, ["name"] = "wool:red"}, {["x"] = 2, ["y"] = 0, ["param1"] = 88, ["z"] = 6, ["name"] = "wool:red"}, {["x"] = 2, ["y"] = 0, ["param1"] = 88, ["z"] = 7, ["name"] = "wool:red"}, {["x"] = 2, ["y"] = 0, ["param1"] = 88, ["z"] = 8, ["name"] = "wool:red"}, {["x"] = 2, ["y"] = 0, ["param1"] = 88, ["z"] = 9, ["name"] = "wool:red"}, {["x"] = 2, ["y"] = 0, ["param1"] = 88, ["z"] = 10, ["name"] = "wool:red"}, {["x"] = 2, ["y"] = 0, ["param1"] = 88, ["z"] = 11, ["name"] = "wool:red"}, {["x"] = 2, ["y"] = 0, ["param1"] = 88, ["z"] = 12, ["name"] = "wool:red"}, {["x"] = 2, ["y"] = 0, ["param1"] = 88, ["z"] = 13, ["name"] = "wool:red"}, {["x"] = 2, ["y"] = 1, ["param1"] = 88, ["z"] = 1, ["name"] = "wool:red"}, {["x"] = 2, ["y"] = 1, ["z"] = 4, ["name"] = "wool:red"}, {["x"] = 2, ["y"] = 1, ["z"] = 7, ["name"] = "wool:red"}, {["x"] = 2, ["y"] = 1, ["z"] = 9, ["name"] = "wool:red"}, {["x"] = 2, ["y"] = 1, ["param1"] = 88, ["z"] = 14, ["name"] = "wool:red"}, {["x"] = 2, ["y"] = 2, ["param1"] = 88, ["z"] = 1, ["name"] = "wool:red"}, {["x"] = 2, ["y"] = 2, ["param1"] = 88, ["z"] = 14, ["name"] = "wool:red"}, {["x"] = 2, ["y"] = 3, ["param1"] = 88, ["z"] = 1, ["name"] = "wool:red"}, {["x"] = 2, ["y"] = 3, ["param1"] = 88, ["z"] = 14, ["name"] = "wool:red"}, {["x"] = 2, ["y"] = 4, ["param1"] = 88, ["z"] = 1, ["name"] = "wool:red"}, {["x"] = 2, ["y"] = 4, ["z"] = 13, ["name"] = "wool:red"}, {["x"] = 2, ["y"] = 4, ["param1"] = 88, ["z"] = 14, ["name"] = "wool:red"}, {["x"] = 2, ["y"] = 5, ["param1"] = 88, ["z"] = 1, ["name"] = "wool:red"}, {["x"] = 2, ["y"] = 5, ["param1"] = 88, ["z"] = 14, ["name"] = "wool:red"}, {["x"] = 2, ["y"] = 6, ["param1"] = 88, ["z"] = 1, ["name"] = "wool:red"}, {["x"] = 2, ["y"] = 6, ["param1"] = 88, ["z"] = 14, ["name"] = "wool:red"}, {["x"] = 2, ["y"] = 7, ["param1"] = 88, ["z"] = 1, ["name"] = "wool:red"}, {["x"] = 2, ["y"] = 7, ["z"] = 7, ["name"] = "wool:yellow"}, {["x"] = 2, ["y"] = 7, ["param1"] = 88, ["z"] = 14, ["name"] = "wool:red"}, {["x"] = 2, ["y"] = 8, ["param1"] = 88, ["z"] = 1, ["name"] = "wool:red"}, {["x"] = 2, ["y"] = 8, ["z"] = 2, ["name"] = "wool:red"}, {["x"] = 2, ["y"] = 8, ["z"] = 3, ["name"] = "wool:red"}, {["x"] = 2, ["y"] = 8, ["z"] = 4, ["name"] = "wool:red"}, {["x"] = 2, ["y"] = 8, ["z"] = 5, ["name"] = "wool:red"}, {["x"] = 2, ["y"] = 8, ["z"] = 6, ["name"] = "wool:red"}, {["x"] = 2, ["y"] = 8, ["z"] = 7, ["name"] = "wool:red"}, {["x"] = 2, ["y"] = 8, ["z"] = 8, ["name"] = "wool:red"}, {["x"] = 2, ["y"] = 8, ["z"] = 9, ["name"] = "wool:red"}, {["x"] = 2, ["y"] = 8, ["z"] = 10, ["name"] = "wool:red"}, {["x"] = 2, ["y"] = 8, ["z"] = 11, ["name"] = "wool:red"}, {["x"] = 2, ["y"] = 8, ["z"] = 12, ["name"] = "wool:red"}, {["x"] = 2, ["y"] = 8, ["z"] = 13, ["name"] = "wool:red"}, {["x"] = 2, ["y"] = 8, ["param1"] = 88, ["z"] = 14, ["name"] = "wool:red"}, {["x"] = 2, ["y"] = 9, ["z"] = 1, ["name"] = "wool:red"}, {["x"] = 2, ["y"] = 9, ["z"] = 14, ["name"] = "wool:red"}, {["x"] = 3, ["y"] = 0, ["param1"] = 88, ["z"] = 1, ["name"] = "wool:red"}, {["x"] = 3, ["y"] = 0, ["param1"] = 88, ["z"] = 14, ["name"] = "wool:red"}, {["x"] = 3, ["y"] = 1, ["z"] = 4, ["name"] = "wool:red"}, {["x"] = 3, ["y"] = 1, ["z"] = 7, ["name"] = "wool:red"}, {["x"] = 3, ["y"] = 1, ["z"] = 9, ["name"] = "wool:red"}, {["x"] = 3, ["y"] = 4, ["z"] = 13, ["name"] = "wool:red"}, {["x"] = 3, ["y"] = 5, ["z"] = 7, ["name"] = "wool:yellow"}, {["x"] = 3, ["y"] = 6, ["z"] = 7, ["name"] = "wool:yellow"}, {["x"] = 3, ["y"] = 7, ["z"] = 7, ["name"] = "wool:yellow"}, {["x"] = 3, ["y"] = 8, ["z"] = 1, ["name"] = "wool:red"}, {["x"] = 3, ["y"] = 8, ["z"] = 2, ["name"] = "wool:red"}, {["x"] = 3, ["y"] = 8, ["z"] = 3, ["name"] = "wool:blue"}, {["x"] = 3, ["y"] = 8, ["z"] = 4, ["name"] = "wool:blue"}, {["x"] = 3, ["y"] = 8, ["z"] = 5, ["name"] = "wool:blue"}, {["x"] = 3, ["y"] = 8, ["z"] = 6, ["name"] = "wool:blue"}, {["x"] = 3, ["y"] = 8, ["z"] = 7, ["name"] = "wool:blue"}, {["x"] = 3, ["y"] = 8, ["z"] = 8, ["name"] = "wool:blue"}, {["x"] = 3, ["y"] = 8, ["z"] = 9, ["name"] = "wool:blue"}, {["x"] = 3, ["y"] = 8, ["z"] = 10, ["name"] = "wool:blue"}, {["x"] = 3, ["y"] = 8, ["z"] = 11, ["name"] = "wool:blue"}, {["x"] = 3, ["y"] = 8, ["z"] = 12, ["name"] = "wool:blue"}, {["x"] = 3, ["y"] = 8, ["z"] = 13, ["name"] = "wool:red"}, {["x"] = 3, ["y"] = 8, ["z"] = 14, ["name"] = "wool:red"}, {["x"] = 3, ["y"] = 9, ["z"] = 4, ["name"] = "wool:blue"}, {["x"] = 3, ["y"] = 9, ["z"] = 5, ["name"] = "wool:blue"}, {["x"] = 3, ["y"] = 9, ["z"] = 6, ["name"] = "wool:blue"}, {["x"] = 3, ["y"] = 9, ["z"] = 7, ["name"] = "wool:blue"}, {["x"] = 3, ["y"] = 9, ["z"] = 8, ["name"] = "wool:blue"}, {["x"] = 3, ["y"] = 9, ["z"] = 9, ["name"] = "wool:blue"}, {["x"] = 3, ["y"] = 9, ["z"] = 10, ["name"] = "wool:blue"}, {["x"] = 3, ["y"] = 9, ["z"] = 11, ["name"] = "wool:blue"}, {["x"] = 3, ["y"] = 10, ["z"] = 1, ["name"] = "wool:red"}, {["x"] = 3, ["y"] = 10, ["z"] = 14, ["name"] = "wool:red"}, {["x"] = 4, ["y"] = 0, ["param1"] = 88, ["z"] = 1, ["name"] = "wool:red"}, {["x"] = 4, ["y"] = 0, ["param1"] = 88, ["z"] = 14, ["name"] = "wool:red"}, {["x"] = 4, ["y"] = 1, ["z"] = 3, ["name"] = "wool:orange"}, {["x"] = 4, ["y"] = 1, ["z"] = 4, ["name"] = "default:steelblock"}, {["x"] = 4, ["y"] = 1, ["z"] = 5, ["name"] = "default:steelblock"}, {["x"] = 4, ["y"] = 1, ["z"] = 6, ["name"] = "default:steelblock"}, {["x"] = 4, ["y"] = 1, ["z"] = 7, ["name"] = "default:steelblock"}, {["x"] = 4, ["y"] = 1, ["z"] = 9, ["name"] = "wool:red"}, {["x"] = 4, ["y"] = 2, ["z"] = 3, ["name"] = "wool:orange"}, {["x"] = 4, ["y"] = 2, ["z"] = 4, ["name"] = "default:steelblock"}, {["x"] = 4, ["y"] = 2, ["z"] = 5, ["name"] = "default:steelblock"}, {["x"] = 4, ["y"] = 2, ["z"] = 6, ["name"] = "default:steelblock"}, {["x"] = 4, ["y"] = 2, ["z"] = 7, ["name"] = "default:steelblock"}, {["x"] = 4, ["y"] = 2, ["param1"] = 86, ["z"] = 8, ["name"] = "wool:brown"}, {["x"] = 4, ["y"] = 2, ["param1"] = 86, ["z"] = 9, ["name"] = "wool:brown"}, {["x"] = 4, ["y"] = 2, ["param1"] = 86, ["z"] = 10, ["name"] = "wool:brown"}, {["x"] = 4, ["y"] = 2, ["param1"] = 86, ["z"] = 11, ["name"] = "wool:brown"}, {["x"] = 4, ["y"] = 2, ["param1"] = 86, ["z"] = 12, ["name"] = "wool:brown"}, {["x"] = 4, ["y"] = 2, ["param1"] = 86, ["z"] = 13, ["name"] = "wool:brown"}, {["x"] = 4, ["y"] = 3, ["z"] = 3, ["name"] = "wool:orange"}, {["x"] = 4, ["y"] = 3, ["z"] = 4, ["name"] = "default:steelblock"}, {["x"] = 4, ["y"] = 3, ["z"] = 5, ["name"] = "default:steelblock"}, {["x"] = 4, ["y"] = 3, ["z"] = 6, ["name"] = "default:steelblock"}, {["x"] = 4, ["y"] = 3, ["z"] = 7, ["name"] = "default:steelblock"}, {["x"] = 4, ["y"] = 3, ["param1"] = 86, ["z"] = 8, ["name"] = "wool:brown"}, {["x"] = 4, ["y"] = 3, ["param1"] = 86, ["z"] = 9, ["name"] = "wool:brown"}, {["x"] = 4, ["y"] = 3, ["param1"] = 86, ["z"] = 10, ["name"] = "wool:brown"}, {["x"] = 4, ["y"] = 3, ["param1"] = 86, ["z"] = 11, ["name"] = "wool:brown"}, {["x"] = 4, ["y"] = 3, ["param1"] = 86, ["z"] = 12, ["name"] = "wool:brown"}, {["x"] = 4, ["y"] = 3, ["param1"] = 86, ["z"] = 13, ["name"] = "wool:brown"}, {["x"] = 4, ["y"] = 4, ["z"] = 3, ["name"] = "wool:orange"}, {["x"] = 4, ["y"] = 4, ["z"] = 4, ["name"] = "default:steelblock"}, {["x"] = 4, ["y"] = 4, ["z"] = 5, ["name"] = "default:steelblock"}, {["x"] = 4, ["y"] = 4, ["z"] = 6, ["name"] = "default:steelblock"}, {["x"] = 4, ["y"] = 4, ["z"] = 7, ["name"] = "default:steelblock"}, {["x"] = 4, ["y"] = 4, ["z"] = 13, ["name"] = "wool:red"}, {["x"] = 4, ["y"] = 5, ["z"] = 7, ["name"] = "wool:yellow"}, {["x"] = 4, ["y"] = 7, ["z"] = 3, ["name"] = "wool:blue"}, {["x"] = 4, ["y"] = 7, ["z"] = 4, ["name"] = "wool:blue"}, {["x"] = 4, ["y"] = 7, ["z"] = 5, ["name"] = "wool:blue"}, {["x"] = 4, ["y"] = 7, ["z"] = 6, ["name"] = "wool:blue"}, {["x"] = 4, ["y"] = 7, ["z"] = 7, ["name"] = "wool:blue"}, {["x"] = 4, ["y"] = 7, ["z"] = 8, ["name"] = "wool:blue"}, {["x"] = 4, ["y"] = 7, ["z"] = 9, ["name"] = "wool:blue"}, {["x"] = 4, ["y"] = 7, ["z"] = 10, ["name"] = "wool:blue"}, {["x"] = 4, ["y"] = 7, ["z"] = 11, ["name"] = "wool:blue"}, {["x"] = 4, ["y"] = 7, ["z"] = 12, ["name"] = "wool:blue"}, {["x"] = 4, ["y"] = 8, ["z"] = 1, ["name"] = "wool:red"}, {["x"] = 4, ["y"] = 8, ["z"] = 2, ["name"] = "wool:blue"}, {["x"] = 4, ["y"] = 8, ["z"] = 3, ["name"] = "wool:blue"}, {["x"] = 4, ["y"] = 8, ["z"] = 4, ["name"] = "wool:blue"}, {["x"] = 4, ["y"] = 8, ["z"] = 5, ["name"] = "wool:blue"}, {["x"] = 4, ["y"] = 8, ["z"] = 6, ["name"] = "wool:blue"}, {["x"] = 4, ["y"] = 8, ["z"] = 7, ["name"] = "wool:blue"}, {["x"] = 4, ["y"] = 8, ["z"] = 8, ["name"] = "wool:blue"}, {["x"] = 4, ["y"] = 8, ["z"] = 9, ["name"] = "wool:blue"}, {["x"] = 4, ["y"] = 8, ["z"] = 10, ["name"] = "wool:blue"}, {["x"] = 4, ["y"] = 8, ["z"] = 11, ["name"] = "wool:blue"}, {["x"] = 4, ["y"] = 8, ["z"] = 12, ["name"] = "wool:blue"}, {["x"] = 4, ["y"] = 8, ["z"] = 13, ["name"] = "wool:blue"}, {["x"] = 4, ["y"] = 8, ["z"] = 14, ["name"] = "wool:red"}, {["x"] = 4, ["y"] = 9, ["z"] = 3, ["name"] = "wool:blue"}, {["x"] = 4, ["y"] = 9, ["z"] = 4, ["name"] = "wool:blue"}, {["x"] = 4, ["y"] = 9, ["z"] = 5, ["name"] = "wool:blue"}, {["x"] = 4, ["y"] = 9, ["z"] = 6, ["name"] = "wool:blue"}, {["x"] = 4, ["y"] = 9, ["z"] = 7, ["name"] = "wool:blue"}, {["x"] = 4, ["y"] = 9, ["z"] = 8, ["name"] = "wool:blue"}, {["x"] = 4, ["y"] = 9, ["z"] = 9, ["name"] = "wool:blue"}, {["x"] = 4, ["y"] = 9, ["z"] = 10, ["name"] = "wool:blue"}, {["x"] = 4, ["y"] = 9, ["z"] = 11, ["name"] = "wool:blue"}, {["x"] = 4, ["y"] = 9, ["z"] = 12, ["name"] = "wool:blue"}, {["x"] = 4, ["y"] = 10, ["z"] = 1, ["name"] = "wool:red"}, {["x"] = 4, ["y"] = 10, ["z"] = 4, ["name"] = "wool:blue"}, {["x"] = 4, ["y"] = 10, ["z"] = 5, ["name"] = "wool:blue"}, {["x"] = 4, ["y"] = 10, ["z"] = 6, ["name"] = "wool:blue"}, {["x"] = 4, ["y"] = 10, ["z"] = 7, ["name"] = "wool:blue"}, {["x"] = 4, ["y"] = 10, ["z"] = 8, ["name"] = "wool:blue"}, {["x"] = 4, ["y"] = 10, ["z"] = 9, ["name"] = "wool:blue"}, {["x"] = 4, ["y"] = 10, ["z"] = 10, ["name"] = "wool:blue"}, {["x"] = 4, ["y"] = 10, ["z"] = 11, ["name"] = "wool:blue"}, {["x"] = 4, ["y"] = 10, ["z"] = 14, ["name"] = "wool:red"}, {["x"] = 5, ["y"] = 0, ["param1"] = 88, ["z"] = 1, ["name"] = "wool:red"}, {["x"] = 5, ["y"] = 0, ["z"] = 13, ["name"] = "wool:red"}, {["x"] = 5, ["y"] = 0, ["param1"] = 88, ["z"] = 14, ["name"] = "wool:red"}, {["x"] = 5, ["y"] = 1, ["z"] = 3, ["name"] = "wool:orange"}, {["x"] = 5, ["y"] = 1, ["z"] = 4, ["name"] = "default:steelblock"}, {["x"] = 5, ["y"] = 1, ["z"] = 5, ["name"] = "default:steelblock"}, {["x"] = 5, ["y"] = 1, ["z"] = 6, ["name"] = "default:steelblock"}, {["x"] = 5, ["y"] = 1, ["z"] = 7, ["name"] = "default:steelblock"}, {["x"] = 5, ["y"] = 1, ["param1"] = 86, ["z"] = 8, ["name"] = "wool:brown"}, {["x"] = 5, ["y"] = 1, ["param1"] = 86, ["z"] = 9, ["name"] = "wool:brown"}, {["x"] = 5, ["y"] = 1, ["param1"] = 86, ["z"] = 10, ["name"] = "wool:brown"}, {["x"] = 5, ["y"] = 1, ["param1"] = 86, ["z"] = 11, ["name"] = "wool:brown"}, {["x"] = 5, ["y"] = 1, ["param1"] = 86, ["z"] = 12, ["name"] = "wool:brown"}, {["x"] = 5, ["y"] = 1, ["param1"] = 86, ["z"] = 13, ["name"] = "wool:brown"}, {["x"] = 5, ["y"] = 2, ["z"] = 2, ["name"] = "wool:orange"}, {["x"] = 5, ["y"] = 2, ["z"] = 3, ["name"] = "wool:orange"}, {["x"] = 5, ["y"] = 2, ["z"] = 4, ["name"] = "default:steelblock"}, {["x"] = 5, ["y"] = 2, ["z"] = 5, ["name"] = "default:steelblock"}, {["x"] = 5, ["y"] = 2, ["z"] = 6, ["name"] = "default:steelblock"}, {["x"] = 5, ["y"] = 2, ["z"] = 7, ["name"] = "default:steelblock"}, {["x"] = 5, ["y"] = 2, ["z"] = 8, ["name"] = "wool:brown"}, {["x"] = 5, ["y"] = 2, ["z"] = 9, ["name"] = "wool:brown"}, {["x"] = 5, ["y"] = 2, ["z"] = 10, ["name"] = "wool:brown"}, {["x"] = 5, ["y"] = 2, ["z"] = 11, ["name"] = "wool:brown"}, {["x"] = 5, ["y"] = 2, ["z"] = 12, ["name"] = "wool:brown"}, {["x"] = 5, ["y"] = 2, ["z"] = 13, ["name"] = "wool:brown"}, {["x"] = 5, ["y"] = 2, ["param1"] = 86, ["z"] = 14, ["name"] = "wool:brown"}, {["x"] = 5, ["y"] = 3, ["z"] = 2, ["name"] = "wool:orange"}, {["x"] = 5, ["y"] = 3, ["z"] = 3, ["name"] = "wool:orange"}, {["x"] = 5, ["y"] = 3, ["z"] = 4, ["name"] = "default:steelblock"}, {["x"] = 5, ["y"] = 3, ["z"] = 5, ["name"] = "default:steelblock"}, {["x"] = 5, ["y"] = 3, ["z"] = 6, ["name"] = "default:steelblock"}, {["x"] = 5, ["y"] = 3, ["z"] = 7, ["name"] = "default:steelblock"}, {["x"] = 5, ["y"] = 3, ["z"] = 8, ["name"] = "wool:brown"}, {["x"] = 5, ["y"] = 3, ["z"] = 9, ["name"] = "wool:brown"}, {["x"] = 5, ["y"] = 3, ["z"] = 10, ["name"] = "wool:brown"}, {["x"] = 5, ["y"] = 3, ["z"] = 11, ["name"] = "wool:brown"}, {["x"] = 5, ["y"] = 3, ["z"] = 12, ["name"] = "wool:brown"}, {["x"] = 5, ["y"] = 3, ["z"] = 13, ["name"] = "wool:brown"}, {["x"] = 5, ["y"] = 3, ["param1"] = 86, ["z"] = 14, ["name"] = "wool:brown"}, {["x"] = 5, ["y"] = 4, ["z"] = 3, ["name"] = "wool:orange"}, {["x"] = 5, ["y"] = 4, ["z"] = 4, ["name"] = "default:steelblock"}, {["x"] = 5, ["y"] = 4, ["z"] = 5, ["name"] = "default:steelblock"}, {["x"] = 5, ["y"] = 4, ["z"] = 6, ["name"] = "default:steelblock"}, {["x"] = 5, ["y"] = 4, ["z"] = 7, ["name"] = "default:steelblock"}, {["x"] = 5, ["y"] = 4, ["param1"] = 86, ["z"] = 8, ["name"] = "wool:brown"}, {["x"] = 5, ["y"] = 4, ["param1"] = 86, ["z"] = 9, ["name"] = "wool:brown"}, {["x"] = 5, ["y"] = 4, ["param1"] = 86, ["z"] = 10, ["name"] = "wool:brown"}, {["x"] = 5, ["y"] = 4, ["param1"] = 86, ["z"] = 11, ["name"] = "wool:brown"}, {["x"] = 5, ["y"] = 4, ["param1"] = 86, ["z"] = 12, ["name"] = "wool:brown"}, {["x"] = 5, ["y"] = 4, ["param1"] = 86, ["z"] = 13, ["name"] = "wool:brown"}, {["x"] = 5, ["y"] = 5, ["z"] = 7, ["name"] = "wool:yellow"}, {["x"] = 5, ["y"] = 7, ["z"] = 3, ["name"] = "wool:blue"}, {["x"] = 5, ["y"] = 7, ["z"] = 4, ["name"] = "wool:blue"}, {["x"] = 5, ["y"] = 7, ["z"] = 5, ["name"] = "wool:blue"}, {["x"] = 5, ["y"] = 7, ["z"] = 6, ["name"] = "wool:blue"}, {["x"] = 5, ["y"] = 7, ["z"] = 7, ["name"] = "wool:blue"}, {["x"] = 5, ["y"] = 7, ["z"] = 8, ["name"] = "wool:blue"}, {["x"] = 5, ["y"] = 7, ["z"] = 9, ["name"] = "wool:blue"}, {["x"] = 5, ["y"] = 7, ["z"] = 10, ["name"] = "wool:blue"}, {["x"] = 5, ["y"] = 7, ["z"] = 11, ["name"] = "wool:blue"}, {["x"] = 5, ["y"] = 7, ["z"] = 12, ["name"] = "wool:blue"}, {["x"] = 5, ["y"] = 8, ["z"] = 1, ["name"] = "wool:red"}, {["x"] = 5, ["y"] = 8, ["z"] = 2, ["name"] = "wool:blue"}, {["x"] = 5, ["y"] = 8, ["z"] = 3, ["name"] = "wool:blue"}, {["x"] = 5, ["y"] = 8, ["z"] = 4, ["name"] = "wool:blue"}, {["x"] = 5, ["y"] = 8, ["z"] = 5, ["name"] = "wool:blue"}, {["x"] = 5, ["y"] = 8, ["z"] = 6, ["name"] = "wool:blue"}, {["x"] = 5, ["y"] = 8, ["z"] = 7, ["name"] = "wool:blue"}, {["x"] = 5, ["y"] = 8, ["z"] = 8, ["name"] = "wool:blue"}, {["x"] = 5, ["y"] = 8, ["z"] = 9, ["name"] = "wool:blue"}, {["x"] = 5, ["y"] = 8, ["z"] = 10, ["name"] = "wool:blue"}, {["x"] = 5, ["y"] = 8, ["z"] = 11, ["name"] = "wool:blue"}, {["x"] = 5, ["y"] = 8, ["z"] = 12, ["name"] = "wool:blue"}, {["x"] = 5, ["y"] = 8, ["z"] = 13, ["name"] = "wool:blue"}, {["x"] = 5, ["y"] = 8, ["z"] = 14, ["name"] = "wool:red"}, {["x"] = 5, ["y"] = 9, ["z"] = 3, ["name"] = "wool:blue"}, {["x"] = 5, ["y"] = 9, ["z"] = 4, ["name"] = "wool:blue"}, {["x"] = 5, ["y"] = 9, ["z"] = 5, ["name"] = "wool:blue"}, {["x"] = 5, ["y"] = 9, ["z"] = 6, ["name"] = "wool:blue"}, {["x"] = 5, ["y"] = 9, ["z"] = 7, ["name"] = "wool:blue"}, {["x"] = 5, ["y"] = 9, ["z"] = 8, ["name"] = "wool:blue"}, {["x"] = 5, ["y"] = 9, ["z"] = 9, ["name"] = "wool:blue"}, {["x"] = 5, ["y"] = 9, ["z"] = 10, ["name"] = "wool:blue"}, {["x"] = 5, ["y"] = 9, ["z"] = 11, ["name"] = "wool:blue"}, {["x"] = 5, ["y"] = 9, ["z"] = 12, ["name"] = "wool:blue"}, {["x"] = 5, ["y"] = 10, ["z"] = 1, ["name"] = "wool:red"}, {["x"] = 5, ["y"] = 10, ["z"] = 4, ["name"] = "wool:blue"}, {["x"] = 5, ["y"] = 10, ["z"] = 5, ["name"] = "wool:blue"}, {["x"] = 5, ["y"] = 10, ["z"] = 6, ["name"] = "wool:blue"}, {["x"] = 5, ["y"] = 10, ["z"] = 7, ["name"] = "wool:blue"}, {["x"] = 5, ["y"] = 10, ["z"] = 8, ["name"] = "wool:blue"}, {["x"] = 5, ["y"] = 10, ["z"] = 9, ["name"] = "wool:blue"}, {["x"] = 5, ["y"] = 10, ["z"] = 10, ["name"] = "wool:blue"}, {["x"] = 5, ["y"] = 10, ["z"] = 11, ["name"] = "wool:blue"}, {["x"] = 5, ["y"] = 10, ["z"] = 14, ["name"] = "wool:red"}, {["x"] = 6, ["y"] = 0, ["param1"] = 88, ["z"] = 1, ["name"] = "wool:red"}, {["x"] = 6, ["y"] = 0, ["z"] = 13, ["name"] = "wool:red"}, {["x"] = 6, ["y"] = 0, ["param1"] = 88, ["z"] = 14, ["name"] = "wool:red"}, {["x"] = 6, ["y"] = 1, ["z"] = 3, ["name"] = "wool:orange"}, {["x"] = 6, ["y"] = 1, ["z"] = 4, ["name"] = "default:steelblock"}, {["x"] = 6, ["y"] = 1, ["z"] = 5, ["name"] = "default:steelblock"}, {["x"] = 6, ["y"] = 1, ["z"] = 6, ["name"] = "default:steelblock"}, {["x"] = 6, ["y"] = 1, ["z"] = 7, ["name"] = "default:steelblock"}, {["x"] = 6, ["y"] = 1, ["param1"] = 86, ["z"] = 8, ["name"] = "wool:brown"}, {["x"] = 6, ["y"] = 1, ["param1"] = 86, ["z"] = 9, ["name"] = "wool:brown"}, {["x"] = 6, ["y"] = 1, ["param1"] = 86, ["z"] = 10, ["name"] = "wool:brown"}, {["x"] = 6, ["y"] = 1, ["param1"] = 86, ["z"] = 11, ["name"] = "wool:brown"}, {["x"] = 6, ["y"] = 1, ["param1"] = 86, ["z"] = 12, ["name"] = "wool:brown"}, {["x"] = 6, ["y"] = 1, ["param1"] = 86, ["z"] = 13, ["name"] = "wool:brown"}, {["x"] = 6, ["y"] = 2, ["z"] = 2, ["name"] = "wool:orange"}, {["x"] = 6, ["y"] = 2, ["z"] = 3, ["name"] = "wool:orange"}, {["x"] = 6, ["y"] = 2, ["z"] = 4, ["name"] = "default:steelblock"}, {["x"] = 6, ["y"] = 2, ["z"] = 5, ["name"] = "default:steelblock"}, {["x"] = 6, ["y"] = 2, ["z"] = 6, ["name"] = "default:steelblock"}, {["x"] = 6, ["y"] = 2, ["z"] = 7, ["name"] = "default:steelblock"}, {["x"] = 6, ["y"] = 2, ["z"] = 8, ["name"] = "wool:brown"}, {["x"] = 6, ["y"] = 2, ["z"] = 9, ["name"] = "wool:brown"}, {["x"] = 6, ["y"] = 2, ["z"] = 10, ["name"] = "wool:brown"}, {["x"] = 6, ["y"] = 2, ["z"] = 11, ["name"] = "wool:brown"}, {["x"] = 6, ["y"] = 2, ["z"] = 12, ["name"] = "wool:brown"}, {["x"] = 6, ["y"] = 2, ["z"] = 13, ["name"] = "wool:brown"}, {["x"] = 6, ["y"] = 2, ["z"] = 14, ["name"] = "wool:brown"}, {["x"] = 6, ["y"] = 3, ["z"] = 2, ["name"] = "wool:orange"}, {["x"] = 6, ["y"] = 3, ["z"] = 3, ["name"] = "wool:orange"}, {["x"] = 6, ["y"] = 3, ["z"] = 4, ["name"] = "default:steelblock"}, {["x"] = 6, ["y"] = 3, ["z"] = 5, ["name"] = "default:steelblock"}, {["x"] = 6, ["y"] = 3, ["z"] = 6, ["name"] = "default:steelblock"}, {["x"] = 6, ["y"] = 3, ["z"] = 7, ["name"] = "default:steelblock"}, {["x"] = 6, ["y"] = 3, ["z"] = 8, ["name"] = "wool:brown"}, {["x"] = 6, ["y"] = 3, ["z"] = 9, ["name"] = "wool:brown"}, {["x"] = 6, ["y"] = 3, ["z"] = 10, ["name"] = "wool:brown"}, {["x"] = 6, ["y"] = 3, ["z"] = 11, ["name"] = "wool:brown"}, {["x"] = 6, ["y"] = 3, ["z"] = 12, ["name"] = "wool:brown"}, {["x"] = 6, ["y"] = 3, ["z"] = 13, ["name"] = "wool:brown"}, {["x"] = 6, ["y"] = 3, ["z"] = 14, ["name"] = "wool:brown"}, {["x"] = 6, ["y"] = 4, ["z"] = 3, ["name"] = "wool:orange"}, {["x"] = 6, ["y"] = 4, ["z"] = 4, ["name"] = "default:steelblock"}, {["x"] = 6, ["y"] = 4, ["z"] = 5, ["name"] = "default:steelblock"}, {["x"] = 6, ["y"] = 4, ["z"] = 6, ["name"] = "default:steelblock"}, {["x"] = 6, ["y"] = 4, ["z"] = 7, ["name"] = "default:steelblock"}, {["x"] = 6, ["y"] = 4, ["param1"] = 86, ["z"] = 8, ["name"] = "wool:brown"}, {["x"] = 6, ["y"] = 4, ["param1"] = 86, ["z"] = 9, ["name"] = "wool:brown"}, {["x"] = 6, ["y"] = 4, ["param1"] = 86, ["z"] = 10, ["name"] = "wool:brown"}, {["x"] = 6, ["y"] = 4, ["param1"] = 86, ["z"] = 11, ["name"] = "wool:brown"}, {["x"] = 6, ["y"] = 4, ["param1"] = 86, ["z"] = 12, ["name"] = "wool:brown"}, {["x"] = 6, ["y"] = 4, ["param1"] = 86, ["z"] = 13, ["name"] = "wool:brown"}, {["x"] = 6, ["y"] = 5, ["z"] = 5, ["name"] = "wool:black"}, {["x"] = 6, ["y"] = 5, ["z"] = 7, ["name"] = "wool:yellow"}, {["x"] = 6, ["y"] = 6, ["z"] = 5, ["name"] = "wool:black"}, {["x"] = 6, ["y"] = 7, ["z"] = 3, ["name"] = "wool:blue"}, {["x"] = 6, ["y"] = 7, ["z"] = 4, ["name"] = "wool:blue"}, {["x"] = 6, ["y"] = 7, ["z"] = 5, ["name"] = "wool:blue"}, {["x"] = 6, ["y"] = 7, ["z"] = 6, ["name"] = "wool:blue"}, {["x"] = 6, ["y"] = 7, ["z"] = 7, ["name"] = "wool:blue"}, {["x"] = 6, ["y"] = 7, ["z"] = 8, ["name"] = "wool:blue"}, {["x"] = 6, ["y"] = 7, ["z"] = 9, ["name"] = "wool:blue"}, {["x"] = 6, ["y"] = 7, ["z"] = 10, ["name"] = "wool:blue"}, {["x"] = 6, ["y"] = 7, ["z"] = 11, ["name"] = "wool:blue"}, {["x"] = 6, ["y"] = 7, ["z"] = 12, ["name"] = "wool:blue"}, {["x"] = 6, ["y"] = 8, ["z"] = 1, ["name"] = "wool:red"}, {["x"] = 6, ["y"] = 8, ["z"] = 2, ["name"] = "wool:blue"}, {["x"] = 6, ["y"] = 8, ["z"] = 3, ["name"] = "wool:blue"}, {["x"] = 6, ["y"] = 8, ["z"] = 4, ["name"] = "wool:blue"}, {["x"] = 6, ["y"] = 8, ["z"] = 5, ["name"] = "wool:blue"}, {["x"] = 6, ["y"] = 8, ["z"] = 6, ["name"] = "wool:blue"}, {["x"] = 6, ["y"] = 8, ["z"] = 7, ["name"] = "wool:blue"}, {["x"] = 6, ["y"] = 8, ["z"] = 8, ["name"] = "wool:blue"}, {["x"] = 6, ["y"] = 8, ["z"] = 9, ["name"] = "wool:blue"}, {["x"] = 6, ["y"] = 8, ["z"] = 10, ["name"] = "wool:blue"}, {["x"] = 6, ["y"] = 8, ["z"] = 11, ["name"] = "wool:blue"}, {["x"] = 6, ["y"] = 8, ["z"] = 12, ["name"] = "wool:blue"}, {["x"] = 6, ["y"] = 8, ["z"] = 13, ["name"] = "wool:blue"}, {["x"] = 6, ["y"] = 8, ["z"] = 14, ["name"] = "wool:red"}, {["x"] = 6, ["y"] = 9, ["z"] = 3, ["name"] = "wool:blue"}, {["x"] = 6, ["y"] = 9, ["z"] = 4, ["name"] = "wool:blue"}, {["x"] = 6, ["y"] = 9, ["z"] = 5, ["name"] = "wool:blue"}, {["x"] = 6, ["y"] = 9, ["z"] = 6, ["name"] = "wool:blue"}, {["x"] = 6, ["y"] = 9, ["z"] = 7, ["name"] = "wool:blue"}, {["x"] = 6, ["y"] = 9, ["z"] = 8, ["name"] = "wool:blue"}, {["x"] = 6, ["y"] = 9, ["z"] = 9, ["name"] = "wool:blue"}, {["x"] = 6, ["y"] = 9, ["z"] = 10, ["name"] = "wool:blue"}, {["x"] = 6, ["y"] = 9, ["z"] = 11, ["name"] = "wool:blue"}, {["x"] = 6, ["y"] = 9, ["z"] = 12, ["name"] = "wool:blue"}, {["x"] = 6, ["y"] = 10, ["z"] = 1, ["name"] = "wool:red"}, {["x"] = 6, ["y"] = 10, ["z"] = 4, ["name"] = "wool:blue"}, {["x"] = 6, ["y"] = 10, ["z"] = 5, ["name"] = "wool:blue"}, {["x"] = 6, ["y"] = 10, ["z"] = 6, ["name"] = "wool:blue"}, {["x"] = 6, ["y"] = 10, ["z"] = 7, ["name"] = "wool:blue"}, {["x"] = 6, ["y"] = 10, ["z"] = 8, ["name"] = "wool:blue"}, {["x"] = 6, ["y"] = 10, ["z"] = 9, ["name"] = "wool:blue"}, {["x"] = 6, ["y"] = 10, ["z"] = 10, ["name"] = "wool:blue"}, {["x"] = 6, ["y"] = 10, ["z"] = 11, ["name"] = "wool:blue"}, {["x"] = 6, ["y"] = 10, ["z"] = 14, ["name"] = "wool:red"}, {["x"] = 7, ["y"] = 0, ["param1"] = 88, ["z"] = 1, ["name"] = "wool:red"}, {["x"] = 7, ["y"] = 0, ["param1"] = 88, ["z"] = 14, ["name"] = "wool:red"}, {["x"] = 7, ["y"] = 1, ["z"] = 3, ["name"] = "wool:orange"}, {["x"] = 7, ["y"] = 1, ["z"] = 4, ["name"] = "default:steelblock"}, {["x"] = 7, ["y"] = 1, ["z"] = 5, ["name"] = "default:steelblock"}, {["x"] = 7, ["y"] = 1, ["z"] = 6, ["name"] = "default:steelblock"}, {["x"] = 7, ["y"] = 1, ["z"] = 7, ["name"] = "default:steelblock"}, {["x"] = 7, ["y"] = 2, ["z"] = 3, ["name"] = "wool:orange"}, {["x"] = 7, ["y"] = 2, ["z"] = 4, ["name"] = "default:steelblock"}, {["x"] = 7, ["y"] = 2, ["z"] = 5, ["name"] = "default:steelblock"}, {["x"] = 7, ["y"] = 2, ["z"] = 6, ["name"] = "default:steelblock"}, {["x"] = 7, ["y"] = 2, ["z"] = 7, ["name"] = "default:steelblock"}, {["x"] = 7, ["y"] = 2, ["param1"] = 86, ["z"] = 8, ["name"] = "wool:brown"}, {["x"] = 7, ["y"] = 2, ["param1"] = 86, ["z"] = 9, ["name"] = "wool:brown"}, {["x"] = 7, ["y"] = 2, ["param1"] = 86, ["z"] = 10, ["name"] = "wool:brown"}, {["x"] = 7, ["y"] = 2, ["param1"] = 86, ["z"] = 11, ["name"] = "wool:brown"}, {["x"] = 7, ["y"] = 2, ["param1"] = 86, ["z"] = 12, ["name"] = "wool:brown"}, {["x"] = 7, ["y"] = 2, ["param1"] = 86, ["z"] = 13, ["name"] = "wool:brown"}, {["x"] = 7, ["y"] = 3, ["z"] = 3, ["name"] = "wool:orange"}, {["x"] = 7, ["y"] = 3, ["z"] = 4, ["name"] = "default:steelblock"}, {["x"] = 7, ["y"] = 3, ["z"] = 5, ["name"] = "default:steelblock"}, {["x"] = 7, ["y"] = 3, ["z"] = 6, ["name"] = "default:steelblock"}, {["x"] = 7, ["y"] = 3, ["z"] = 7, ["name"] = "default:steelblock"}, {["x"] = 7, ["y"] = 3, ["param1"] = 86, ["z"] = 8, ["name"] = "wool:brown"}, {["x"] = 7, ["y"] = 3, ["param1"] = 86, ["z"] = 9, ["name"] = "wool:brown"}, {["x"] = 7, ["y"] = 3, ["param1"] = 86, ["z"] = 10, ["name"] = "wool:brown"}, {["x"] = 7, ["y"] = 3, ["param1"] = 86, ["z"] = 11, ["name"] = "wool:brown"}, {["x"] = 7, ["y"] = 3, ["param1"] = 86, ["z"] = 12, ["name"] = "wool:brown"}, {["x"] = 7, ["y"] = 3, ["param1"] = 86, ["z"] = 13, ["name"] = "wool:brown"}, {["x"] = 7, ["y"] = 4, ["z"] = 3, ["name"] = "wool:orange"}, {["x"] = 7, ["y"] = 4, ["z"] = 4, ["name"] = "default:steelblock"}, {["x"] = 7, ["y"] = 4, ["z"] = 5, ["name"] = "default:steelblock"}, {["x"] = 7, ["y"] = 4, ["z"] = 6, ["name"] = "default:steelblock"}, {["x"] = 7, ["y"] = 4, ["z"] = 7, ["name"] = "default:steelblock"}, {["x"] = 7, ["y"] = 5, ["z"] = 3, ["name"] = "wool:yellow"}, {["x"] = 7, ["y"] = 5, ["z"] = 4, ["name"] = "wool:yellow"}, {["x"] = 7, ["y"] = 5, ["z"] = 5, ["name"] = "wool:yellow"}, {["x"] = 7, ["y"] = 5, ["z"] = 6, ["name"] = "wool:yellow"}, {["x"] = 7, ["y"] = 5, ["z"] = 7, ["name"] = "wool:yellow"}, {["x"] = 7, ["y"] = 6, ["z"] = 3, ["name"] = "wool:yellow"}, {["x"] = 7, ["y"] = 7, ["z"] = 0, ["name"] = "wool:yellow"}, {["x"] = 7, ["y"] = 7, ["z"] = 3, ["name"] = "wool:blue"}, {["x"] = 7, ["y"] = 7, ["z"] = 4, ["name"] = "wool:blue"}, {["x"] = 7, ["y"] = 7, ["z"] = 5, ["name"] = "wool:blue"}, {["x"] = 7, ["y"] = 7, ["z"] = 6, ["name"] = "wool:blue"}, {["x"] = 7, ["y"] = 7, ["z"] = 7, ["name"] = "wool:blue"}, {["x"] = 7, ["y"] = 7, ["z"] = 8, ["name"] = "wool:blue"}, {["x"] = 7, ["y"] = 7, ["z"] = 9, ["name"] = "wool:blue"}, {["x"] = 7, ["y"] = 7, ["z"] = 10, ["name"] = "wool:blue"}, {["x"] = 7, ["y"] = 7, ["z"] = 11, ["name"] = "wool:blue"}, {["x"] = 7, ["y"] = 7, ["z"] = 12, ["name"] = "wool:blue"}, {["x"] = 7, ["y"] = 7, ["z"] = 15, ["name"] = "wool:yellow"}, {["x"] = 7, ["y"] = 8, ["z"] = 0, ["name"] = "wool:yellow"}, {["x"] = 7, ["y"] = 8, ["z"] = 1, ["name"] = "wool:red"}, {["x"] = 7, ["y"] = 8, ["z"] = 2, ["name"] = "wool:blue"}, {["x"] = 7, ["y"] = 8, ["z"] = 3, ["name"] = "wool:blue"}, {["x"] = 7, ["y"] = 8, ["z"] = 4, ["name"] = "wool:blue"}, {["x"] = 7, ["y"] = 8, ["z"] = 5, ["name"] = "wool:blue"}, {["x"] = 7, ["y"] = 8, ["z"] = 6, ["name"] = "wool:blue"}, {["x"] = 7, ["y"] = 8, ["z"] = 7, ["name"] = "wool:blue"}, {["x"] = 7, ["y"] = 8, ["z"] = 8, ["name"] = "wool:blue"}, {["x"] = 7, ["y"] = 8, ["z"] = 9, ["name"] = "wool:blue"}, {["x"] = 7, ["y"] = 8, ["z"] = 10, ["name"] = "wool:blue"}, {["x"] = 7, ["y"] = 8, ["z"] = 11, ["name"] = "wool:blue"}, {["x"] = 7, ["y"] = 8, ["z"] = 12, ["name"] = "wool:blue"}, {["x"] = 7, ["y"] = 8, ["z"] = 13, ["name"] = "wool:blue"}, {["x"] = 7, ["y"] = 8, ["z"] = 14, ["name"] = "wool:red"}, {["x"] = 7, ["y"] = 8, ["z"] = 15, ["name"] = "wool:yellow"}, {["x"] = 7, ["y"] = 9, ["z"] = 3, ["name"] = "wool:blue"}, {["x"] = 7, ["y"] = 9, ["z"] = 4, ["name"] = "wool:blue"}, {["x"] = 7, ["y"] = 9, ["z"] = 5, ["name"] = "wool:blue"}, {["x"] = 7, ["y"] = 9, ["z"] = 6, ["name"] = "wool:blue"}, {["x"] = 7, ["y"] = 9, ["z"] = 7, ["name"] = "wool:blue"}, {["x"] = 7, ["y"] = 9, ["z"] = 8, ["name"] = "wool:blue"}, {["x"] = 7, ["y"] = 9, ["z"] = 9, ["name"] = "wool:blue"}, {["x"] = 7, ["y"] = 9, ["z"] = 10, ["name"] = "wool:blue"}, {["x"] = 7, ["y"] = 9, ["z"] = 11, ["name"] = "wool:blue"}, {["x"] = 7, ["y"] = 9, ["z"] = 12, ["name"] = "wool:blue"}, {["x"] = 7, ["y"] = 10, ["z"] = 1, ["name"] = "wool:red"}, {["x"] = 7, ["y"] = 10, ["z"] = 4, ["name"] = "wool:blue"}, {["x"] = 7, ["y"] = 10, ["z"] = 5, ["name"] = "wool:blue"}, {["x"] = 7, ["y"] = 10, ["z"] = 6, ["name"] = "wool:blue"}, {["x"] = 7, ["y"] = 10, ["z"] = 7, ["name"] = "wool:blue"}, {["x"] = 7, ["y"] = 10, ["z"] = 8, ["name"] = "wool:blue"}, {["x"] = 7, ["y"] = 10, ["z"] = 9, ["name"] = "wool:blue"}, {["x"] = 7, ["y"] = 10, ["z"] = 10, ["name"] = "wool:blue"}, {["x"] = 7, ["y"] = 10, ["z"] = 11, ["name"] = "wool:blue"}, {["x"] = 7, ["y"] = 10, ["z"] = 14, ["name"] = "wool:red"}, {["x"] = 7, ["y"] = 11, ["z"] = 5, ["name"] = "wool:black"}, {["x"] = 7, ["y"] = 11, ["z"] = 6, ["name"] = "wool:black"}, {["x"] = 8, ["y"] = 0, ["param1"] = 88, ["z"] = 1, ["name"] = "wool:red"}, {["x"] = 8, ["y"] = 0, ["param1"] = 88, ["z"] = 14, ["name"] = "wool:red"}, {["x"] = 8, ["y"] = 1, ["z"] = 6, ["name"] = "wool:white"}, {["x"] = 8, ["y"] = 2, ["z"] = 5, ["name"] = "default:steelblock"}, {["x"] = 8, ["y"] = 2, ["z"] = 6, ["name"] = "default:steelblock"}, {["x"] = 8, ["y"] = 2, ["z"] = 7, ["name"] = "default:steelblock"}, {["x"] = 8, ["y"] = 3, ["z"] = 6, ["name"] = "wool:white"}, {["x"] = 8, ["y"] = 4, ["z"] = 13, ["name"] = "wool:yellow"}, {["x"] = 8, ["y"] = 5, ["z"] = 7, ["name"] = "wool:yellow"}, {["x"] = 8, ["y"] = 5, ["z"] = 13, ["name"] = "wool:yellow"}, {["x"] = 8, ["y"] = 6, ["z"] = 2, ["name"] = "wool:yellow"}, {["x"] = 8, ["y"] = 6, ["z"] = 3, ["name"] = "wool:yellow"}, {["x"] = 8, ["y"] = 6, ["z"] = 13, ["name"] = "wool:yellow"}, {["x"] = 8, ["y"] = 7, ["z"] = 0, ["name"] = "wool:yellow"}, {["x"] = 8, ["y"] = 7, ["z"] = 1, ["name"] = "wool:yellow"}, {["x"] = 8, ["y"] = 7, ["z"] = 2, ["name"] = "wool:yellow"}, {["x"] = 8, ["y"] = 7, ["z"] = 3, ["name"] = "wool:blue"}, {["x"] = 8, ["y"] = 7, ["z"] = 4, ["name"] = "wool:blue"}, {["x"] = 8, ["y"] = 7, ["z"] = 5, ["name"] = "wool:blue"}, {["x"] = 8, ["y"] = 7, ["z"] = 6, ["name"] = "wool:blue"}, {["x"] = 8, ["y"] = 7, ["z"] = 7, ["name"] = "wool:blue"}, {["x"] = 8, ["y"] = 7, ["z"] = 8, ["name"] = "wool:blue"}, {["x"] = 8, ["y"] = 7, ["z"] = 9, ["name"] = "wool:blue"}, {["x"] = 8, ["y"] = 7, ["z"] = 10, ["name"] = "wool:blue"}, {["x"] = 8, ["y"] = 7, ["z"] = 11, ["name"] = "wool:blue"}, {["x"] = 8, ["y"] = 7, ["z"] = 12, ["name"] = "wool:blue"}, {["x"] = 8, ["y"] = 7, ["z"] = 13, ["name"] = "wool:yellow"}, {["x"] = 8, ["y"] = 7, ["z"] = 14, ["name"] = "wool:yellow"}, {["x"] = 8, ["y"] = 7, ["z"] = 15, ["name"] = "wool:yellow"}, {["x"] = 8, ["y"] = 8, ["z"] = 0, ["name"] = "wool:yellow"}, {["x"] = 8, ["y"] = 8, ["z"] = 1, ["name"] = "wool:red"}, {["x"] = 8, ["y"] = 8, ["z"] = 2, ["name"] = "wool:blue"}, {["x"] = 8, ["y"] = 8, ["z"] = 3, ["name"] = "wool:blue"}, {["x"] = 8, ["y"] = 8, ["z"] = 4, ["name"] = "wool:blue"}, {["x"] = 8, ["y"] = 8, ["z"] = 5, ["name"] = "wool:blue"}, {["x"] = 8, ["y"] = 8, ["z"] = 6, ["name"] = "wool:blue"}, {["x"] = 8, ["y"] = 8, ["z"] = 7, ["name"] = "wool:blue"}, {["x"] = 8, ["y"] = 8, ["z"] = 8, ["name"] = "wool:blue"}, {["x"] = 8, ["y"] = 8, ["z"] = 9, ["name"] = "wool:blue"}, {["x"] = 8, ["y"] = 8, ["z"] = 10, ["name"] = "wool:blue"}, {["x"] = 8, ["y"] = 8, ["z"] = 11, ["name"] = "wool:blue"}, {["x"] = 8, ["y"] = 8, ["z"] = 12, ["name"] = "wool:blue"}, {["x"] = 8, ["y"] = 8, ["z"] = 13, ["name"] = "wool:blue"}, {["x"] = 8, ["y"] = 8, ["z"] = 14, ["name"] = "wool:red"}, {["x"] = 8, ["y"] = 8, ["z"] = 15, ["name"] = "wool:yellow"}, {["x"] = 8, ["y"] = 9, ["z"] = 3, ["name"] = "wool:blue"}, {["x"] = 8, ["y"] = 9, ["z"] = 4, ["name"] = "wool:blue"}, {["x"] = 8, ["y"] = 9, ["z"] = 5, ["name"] = "wool:blue"}, {["x"] = 8, ["y"] = 9, ["z"] = 6, ["name"] = "wool:blue"}, {["x"] = 8, ["y"] = 9, ["z"] = 7, ["name"] = "wool:blue"}, {["x"] = 8, ["y"] = 9, ["z"] = 8, ["name"] = "wool:blue"}, {["x"] = 8, ["y"] = 9, ["z"] = 9, ["name"] = "wool:blue"}, {["x"] = 8, ["y"] = 9, ["z"] = 10, ["name"] = "wool:blue"}, {["x"] = 8, ["y"] = 9, ["z"] = 11, ["name"] = "wool:blue"}, {["x"] = 8, ["y"] = 9, ["z"] = 12, ["name"] = "wool:blue"}, {["x"] = 8, ["y"] = 10, ["z"] = 1, ["name"] = "wool:red"}, {["x"] = 8, ["y"] = 10, ["z"] = 4, ["name"] = "wool:blue"}, {["x"] = 8, ["y"] = 10, ["z"] = 5, ["name"] = "wool:blue"}, {["x"] = 8, ["y"] = 10, ["z"] = 6, ["name"] = "wool:blue"}, {["x"] = 8, ["y"] = 10, ["z"] = 7, ["name"] = "wool:blue"}, {["x"] = 8, ["y"] = 10, ["z"] = 8, ["name"] = "wool:blue"}, {["x"] = 8, ["y"] = 10, ["z"] = 9, ["name"] = "wool:blue"}, {["x"] = 8, ["y"] = 10, ["z"] = 10, ["name"] = "wool:blue"}, {["x"] = 8, ["y"] = 10, ["z"] = 11, ["name"] = "wool:blue"}, {["x"] = 8, ["y"] = 10, ["z"] = 14, ["name"] = "wool:red"}, {["x"] = 8, ["y"] = 11, ["z"] = 5, ["name"] = "wool:black"}, {["x"] = 8, ["y"] = 11, ["z"] = 6, ["name"] = "wool:black"}, {["x"] = 9, ["y"] = 0, ["z"] = 1, ["name"] = "wool:red"}, {["x"] = 9, ["y"] = 0, ["z"] = 14, ["name"] = "wool:red"}, {["x"] = 9, ["y"] = 1, ["z"] = 2, ["name"] = "default:junglewood"}, {["x"] = 9, ["y"] = 1, ["z"] = 3, ["name"] = "default:junglewood"}, {["x"] = 9, ["y"] = 1, ["z"] = 5, ["name"] = "default:steelblock"}, {["x"] = 9, ["y"] = 1, ["z"] = 6, ["name"] = "default:steelblock"}, {["x"] = 9, ["y"] = 1, ["z"] = 7, ["name"] = "default:steelblock"}, {["x"] = 9, ["y"] = 2, ["z"] = 2, ["name"] = "default:junglewood"}, {["x"] = 9, ["y"] = 2, ["z"] = 3, ["name"] = "default:junglewood"}, {["x"] = 9, ["y"] = 2, ["z"] = 5, ["name"] = "default:steelblock"}, {["x"] = 9, ["y"] = 2, ["z"] = 6, ["name"] = "default:steelblock"}, {["x"] = 9, ["y"] = 2, ["z"] = 7, ["name"] = "default:steelblock"}, {["x"] = 9, ["y"] = 2, ["z"] = 9, ["name"] = "wool:brown"}, {["x"] = 9, ["y"] = 2, ["z"] = 10, ["name"] = "wool:brown"}, {["x"] = 9, ["y"] = 2, ["z"] = 11, ["name"] = "wool:brown"}, {["x"] = 9, ["y"] = 2, ["z"] = 12, ["name"] = "wool:brown"}, {["x"] = 9, ["y"] = 2, ["z"] = 13, ["name"] = "wool:brown"}, {["x"] = 9, ["y"] = 3, ["z"] = 2, ["name"] = "default:junglewood"}, {["x"] = 9, ["y"] = 3, ["z"] = 3, ["name"] = "default:junglewood"}, {["x"] = 9, ["y"] = 3, ["z"] = 5, ["name"] = "default:steelblock"}, {["x"] = 9, ["y"] = 3, ["z"] = 6, ["name"] = "default:steelblock"}, {["x"] = 9, ["y"] = 3, ["z"] = 7, ["name"] = "default:steelblock"}, {["x"] = 9, ["y"] = 3, ["z"] = 9, ["name"] = "wool:brown"}, {["x"] = 9, ["y"] = 3, ["z"] = 10, ["name"] = "wool:brown"}, {["x"] = 9, ["y"] = 3, ["z"] = 11, ["name"] = "wool:brown"}, {["x"] = 9, ["y"] = 3, ["z"] = 12, ["name"] = "wool:brown"}, {["x"] = 9, ["y"] = 3, ["z"] = 13, ["name"] = "wool:brown"}, {["x"] = 9, ["y"] = 4, ["z"] = 2, ["name"] = "default:junglewood"}, {["x"] = 9, ["y"] = 4, ["z"] = 3, ["name"] = "default:junglewood"}, {["x"] = 9, ["y"] = 4, ["z"] = 7, ["name"] = "wool:yellow"}, {["x"] = 9, ["y"] = 4, ["z"] = 8, ["name"] = "wool:yellow"}, {["x"] = 9, ["y"] = 4, ["z"] = 9, ["name"] = "wool:yellow"}, {["x"] = 9, ["y"] = 4, ["z"] = 10, ["name"] = "wool:yellow"}, {["x"] = 9, ["y"] = 4, ["z"] = 11, ["name"] = "wool:yellow"}, {["x"] = 9, ["y"] = 4, ["z"] = 12, ["name"] = "wool:yellow"}, {["x"] = 9, ["y"] = 4, ["z"] = 13, ["name"] = "wool:yellow"}, {["x"] = 9, ["y"] = 5, ["z"] = 2, ["name"] = "default:junglewood"}, {["x"] = 9, ["y"] = 5, ["z"] = 7, ["name"] = "wool:yellow"}, {["x"] = 9, ["y"] = 7, ["z"] = 3, ["name"] = "wool:blue"}, {["x"] = 9, ["y"] = 7, ["z"] = 4, ["name"] = "wool:blue"}, {["x"] = 9, ["y"] = 7, ["z"] = 5, ["name"] = "wool:blue"}, {["x"] = 9, ["y"] = 7, ["z"] = 6, ["name"] = "wool:blue"}, {["x"] = 9, ["y"] = 7, ["z"] = 7, ["name"] = "wool:blue"}, {["x"] = 9, ["y"] = 7, ["z"] = 8, ["name"] = "wool:blue"}, {["x"] = 9, ["y"] = 7, ["z"] = 9, ["name"] = "wool:blue"}, {["x"] = 9, ["y"] = 7, ["z"] = 10, ["name"] = "wool:blue"}, {["x"] = 9, ["y"] = 7, ["z"] = 11, ["name"] = "wool:blue"}, {["x"] = 9, ["y"] = 7, ["z"] = 12, ["name"] = "wool:blue"}, {["x"] = 9, ["y"] = 8, ["z"] = 1, ["name"] = "wool:red"}, {["x"] = 9, ["y"] = 8, ["z"] = 2, ["name"] = "wool:blue"}, {["x"] = 9, ["y"] = 8, ["z"] = 3, ["name"] = "wool:blue"}, {["x"] = 9, ["y"] = 8, ["z"] = 4, ["name"] = "wool:blue"}, {["x"] = 9, ["y"] = 8, ["z"] = 5, ["name"] = "wool:blue"}, {["x"] = 9, ["y"] = 8, ["z"] = 6, ["name"] = "wool:blue"}, {["x"] = 9, ["y"] = 8, ["z"] = 7, ["name"] = "wool:blue"}, {["x"] = 9, ["y"] = 8, ["z"] = 8, ["name"] = "wool:blue"}, {["x"] = 9, ["y"] = 8, ["z"] = 9, ["name"] = "wool:blue"}, {["x"] = 9, ["y"] = 8, ["z"] = 10, ["name"] = "wool:blue"}, {["x"] = 9, ["y"] = 8, ["z"] = 11, ["name"] = "wool:blue"}, {["x"] = 9, ["y"] = 8, ["z"] = 12, ["name"] = "wool:blue"}, {["x"] = 9, ["y"] = 8, ["z"] = 13, ["name"] = "wool:blue"}, {["x"] = 9, ["y"] = 8, ["z"] = 14, ["name"] = "wool:red"}, {["x"] = 9, ["y"] = 9, ["z"] = 3, ["name"] = "wool:blue"}, {["x"] = 9, ["y"] = 9, ["z"] = 4, ["name"] = "wool:blue"}, {["x"] = 9, ["y"] = 9, ["z"] = 5, ["name"] = "wool:blue"}, {["x"] = 9, ["y"] = 9, ["z"] = 6, ["name"] = "wool:blue"}, {["x"] = 9, ["y"] = 9, ["z"] = 7, ["name"] = "wool:blue"}, {["x"] = 9, ["y"] = 9, ["z"] = 8, ["name"] = "wool:blue"}, {["x"] = 9, ["y"] = 9, ["z"] = 9, ["name"] = "wool:blue"}, {["x"] = 9, ["y"] = 9, ["z"] = 10, ["name"] = "wool:blue"}, {["x"] = 9, ["y"] = 9, ["z"] = 11, ["name"] = "wool:blue"}, {["x"] = 9, ["y"] = 9, ["z"] = 12, ["name"] = "wool:blue"}, {["x"] = 9, ["y"] = 10, ["z"] = 1, ["name"] = "wool:red"}, {["x"] = 9, ["y"] = 10, ["z"] = 4, ["name"] = "wool:blue"}, {["x"] = 9, ["y"] = 10, ["z"] = 5, ["name"] = "wool:blue"}, {["x"] = 9, ["y"] = 10, ["z"] = 6, ["name"] = "wool:blue"}, {["x"] = 9, ["y"] = 10, ["z"] = 7, ["name"] = "wool:blue"}, {["x"] = 9, ["y"] = 10, ["z"] = 8, ["name"] = "wool:blue"}, {["x"] = 9, ["y"] = 10, ["z"] = 9, ["name"] = "wool:blue"}, {["x"] = 9, ["y"] = 10, ["z"] = 10, ["name"] = "wool:blue"}, {["x"] = 9, ["y"] = 10, ["z"] = 11, ["name"] = "wool:blue"}, {["x"] = 9, ["y"] = 10, ["z"] = 14, ["name"] = "wool:red"}, {["x"] = 10, ["y"] = 0, ["z"] = 1, ["name"] = "wool:red"}, {["x"] = 10, ["y"] = 0, ["z"] = 13, ["name"] = "wool:red"}, {["x"] = 10, ["y"] = 0, ["z"] = 14, ["name"] = "wool:red"}, {["x"] = 10, ["y"] = 1, ["z"] = 2, ["name"] = "default:junglewood"}, {["x"] = 10, ["y"] = 1, ["z"] = 3, ["name"] = "default:junglewood"}, {["x"] = 10, ["y"] = 1, ["z"] = 5, ["name"] = "default:steelblock"}, {["x"] = 10, ["y"] = 1, ["z"] = 6, ["name"] = "default:steelblock"}, {["x"] = 10, ["y"] = 1, ["z"] = 7, ["name"] = "default:steelblock"}, {["x"] = 10, ["y"] = 1, ["z"] = 9, ["name"] = "wool:brown"}, {["x"] = 10, ["y"] = 1, ["z"] = 10, ["name"] = "wool:brown"}, {["x"] = 10, ["y"] = 1, ["z"] = 11, ["name"] = "wool:brown"}, {["x"] = 10, ["y"] = 1, ["z"] = 12, ["name"] = "wool:brown"}, {["x"] = 10, ["y"] = 1, ["z"] = 13, ["name"] = "wool:brown"}, {["x"] = 10, ["y"] = 2, ["z"] = 2, ["name"] = "default:junglewood"}, {["x"] = 10, ["y"] = 2, ["z"] = 3, ["name"] = "default:junglewood"}, {["x"] = 10, ["y"] = 2, ["z"] = 5, ["name"] = "default:steelblock"}, {["x"] = 10, ["y"] = 2, ["z"] = 6, ["name"] = "default:steelblock"}, {["x"] = 10, ["y"] = 2, ["z"] = 7, ["name"] = "default:steelblock"}, {["x"] = 10, ["y"] = 2, ["z"] = 9, ["name"] = "wool:brown"}, {["x"] = 10, ["y"] = 2, ["z"] = 10, ["name"] = "wool:brown"}, {["x"] = 10, ["y"] = 2, ["z"] = 11, ["name"] = "wool:brown"}, {["x"] = 10, ["y"] = 2, ["z"] = 12, ["name"] = "wool:brown"}, {["x"] = 10, ["y"] = 2, ["z"] = 13, ["name"] = "wool:brown"}, {["x"] = 10, ["y"] = 3, ["z"] = 2, ["name"] = "default:junglewood"}, {["x"] = 10, ["y"] = 3, ["z"] = 3, ["name"] = "default:junglewood"}, {["x"] = 10, ["y"] = 3, ["z"] = 5, ["name"] = "default:steelblock"}, {["x"] = 10, ["y"] = 3, ["z"] = 6, ["name"] = "default:steelblock"}, {["x"] = 10, ["y"] = 3, ["z"] = 7, ["name"] = "default:steelblock"}, {["x"] = 10, ["y"] = 3, ["z"] = 8, ["name"] = "wool:white"}, {["x"] = 10, ["y"] = 3, ["z"] = 9, ["name"] = "wool:brown"}, {["x"] = 10, ["y"] = 3, ["z"] = 10, ["name"] = "wool:brown"}, {["x"] = 10, ["y"] = 3, ["z"] = 11, ["name"] = "wool:brown"}, {["x"] = 10, ["y"] = 3, ["z"] = 12, ["name"] = "wool:brown"}, {["x"] = 10, ["y"] = 3, ["z"] = 13, ["name"] = "wool:brown"}, {["x"] = 10, ["y"] = 4, ["z"] = 2, ["name"] = "default:junglewood"}, {["x"] = 10, ["y"] = 4, ["z"] = 3, ["name"] = "default:junglewood"}, {["x"] = 10, ["y"] = 4, ["z"] = 5, ["name"] = "default:steelblock"}, {["x"] = 10, ["y"] = 4, ["z"] = 6, ["name"] = "default:steelblock"}, {["x"] = 10, ["y"] = 4, ["z"] = 7, ["name"] = "default:steelblock"}, {["x"] = 10, ["y"] = 4, ["z"] = 9, ["name"] = "wool:brown"}, {["x"] = 10, ["y"] = 4, ["z"] = 10, ["name"] = "wool:brown"}, {["x"] = 10, ["y"] = 4, ["z"] = 11, ["name"] = "wool:brown"}, {["x"] = 10, ["y"] = 4, ["z"] = 12, ["name"] = "wool:brown"}, {["x"] = 10, ["y"] = 4, ["z"] = 13, ["name"] = "wool:brown"}, {["x"] = 10, ["y"] = 5, ["z"] = 2, ["name"] = "default:junglewood"}, {["x"] = 10, ["y"] = 5, ["z"] = 7, ["name"] = "wool:yellow"}, {["x"] = 10, ["y"] = 7, ["z"] = 3, ["name"] = "wool:blue"}, {["x"] = 10, ["y"] = 7, ["z"] = 4, ["name"] = "wool:blue"}, {["x"] = 10, ["y"] = 7, ["z"] = 5, ["name"] = "wool:blue"}, {["x"] = 10, ["y"] = 7, ["z"] = 6, ["name"] = "wool:blue"}, {["x"] = 10, ["y"] = 7, ["z"] = 7, ["name"] = "wool:blue"}, {["x"] = 10, ["y"] = 7, ["z"] = 8, ["name"] = "wool:blue"}, {["x"] = 10, ["y"] = 7, ["z"] = 9, ["name"] = "wool:blue"}, {["x"] = 10, ["y"] = 7, ["z"] = 10, ["name"] = "wool:blue"}, {["x"] = 10, ["y"] = 7, ["z"] = 11, ["name"] = "wool:blue"}, {["x"] = 10, ["y"] = 7, ["z"] = 12, ["name"] = "wool:blue"}, {["x"] = 10, ["y"] = 8, ["z"] = 1, ["name"] = "wool:red"}, {["x"] = 10, ["y"] = 8, ["z"] = 2, ["name"] = "wool:blue"}, {["x"] = 10, ["y"] = 8, ["z"] = 3, ["name"] = "wool:blue"}, {["x"] = 10, ["y"] = 8, ["z"] = 4, ["name"] = "wool:blue"}, {["x"] = 10, ["y"] = 8, ["z"] = 5, ["name"] = "wool:blue"}, {["x"] = 10, ["y"] = 8, ["z"] = 6, ["name"] = "wool:blue"}, {["x"] = 10, ["y"] = 8, ["z"] = 7, ["name"] = "wool:blue"}, {["x"] = 10, ["y"] = 8, ["z"] = 8, ["name"] = "wool:blue"}, {["x"] = 10, ["y"] = 8, ["z"] = 9, ["name"] = "wool:blue"}, {["x"] = 10, ["y"] = 8, ["z"] = 10, ["name"] = "wool:blue"}, {["x"] = 10, ["y"] = 8, ["z"] = 11, ["name"] = "wool:blue"}, {["x"] = 10, ["y"] = 8, ["z"] = 12, ["name"] = "wool:blue"}, {["x"] = 10, ["y"] = 8, ["z"] = 13, ["name"] = "wool:blue"}, {["x"] = 10, ["y"] = 8, ["z"] = 14, ["name"] = "wool:red"}, {["x"] = 10, ["y"] = 9, ["z"] = 3, ["name"] = "wool:blue"}, {["x"] = 10, ["y"] = 9, ["z"] = 4, ["name"] = "wool:blue"}, {["x"] = 10, ["y"] = 9, ["z"] = 5, ["name"] = "wool:blue"}, {["x"] = 10, ["y"] = 9, ["z"] = 6, ["name"] = "wool:blue"}, {["x"] = 10, ["y"] = 9, ["z"] = 7, ["name"] = "wool:blue"}, {["x"] = 10, ["y"] = 9, ["z"] = 8, ["name"] = "wool:blue"}, {["x"] = 10, ["y"] = 9, ["z"] = 9, ["name"] = "wool:blue"}, {["x"] = 10, ["y"] = 9, ["z"] = 10, ["name"] = "wool:blue"}, {["x"] = 10, ["y"] = 9, ["z"] = 11, ["name"] = "wool:blue"}, {["x"] = 10, ["y"] = 9, ["z"] = 12, ["name"] = "wool:blue"}, {["x"] = 10, ["y"] = 10, ["z"] = 1, ["name"] = "wool:red"}, {["x"] = 10, ["y"] = 10, ["z"] = 4, ["name"] = "wool:blue"}, {["x"] = 10, ["y"] = 10, ["z"] = 5, ["name"] = "wool:blue"}, {["x"] = 10, ["y"] = 10, ["z"] = 6, ["name"] = "wool:blue"}, {["x"] = 10, ["y"] = 10, ["z"] = 7, ["name"] = "wool:blue"}, {["x"] = 10, ["y"] = 10, ["z"] = 8, ["name"] = "wool:blue"}, {["x"] = 10, ["y"] = 10, ["z"] = 9, ["name"] = "wool:blue"}, {["x"] = 10, ["y"] = 10, ["z"] = 10, ["name"] = "wool:blue"}, {["x"] = 10, ["y"] = 10, ["z"] = 11, ["name"] = "wool:blue"}, {["x"] = 10, ["y"] = 10, ["z"] = 14, ["name"] = "wool:red"}, {["x"] = 11, ["y"] = 0, ["z"] = 1, ["name"] = "wool:red"}, {["x"] = 11, ["y"] = 0, ["z"] = 14, ["name"] = "wool:red"}, {["x"] = 11, ["y"] = 1, ["z"] = 2, ["name"] = "default:junglewood"}, {["x"] = 11, ["y"] = 1, ["z"] = 3, ["name"] = "default:junglewood"}, {["x"] = 11, ["y"] = 1, ["z"] = 5, ["name"] = "wool:red"}, {["x"] = 11, ["y"] = 1, ["z"] = 7, ["name"] = "wool:red"}, {["x"] = 11, ["y"] = 1, ["z"] = 9, ["name"] = "wool:red"}, {["x"] = 11, ["y"] = 2, ["z"] = 2, ["name"] = "default:junglewood"}, {["x"] = 11, ["y"] = 2, ["z"] = 3, ["name"] = "default:junglewood"}, {["x"] = 11, ["y"] = 2, ["z"] = 9, ["name"] = "wool:brown"}, {["x"] = 11, ["y"] = 2, ["z"] = 10, ["name"] = "wool:brown"}, {["x"] = 11, ["y"] = 2, ["z"] = 11, ["name"] = "wool:brown"}, {["x"] = 11, ["y"] = 2, ["z"] = 12, ["name"] = "wool:brown"}, {["x"] = 11, ["y"] = 2, ["z"] = 13, ["name"] = "wool:brown"}, {["x"] = 11, ["y"] = 3, ["z"] = 2, ["name"] = "default:junglewood"}, {["x"] = 11, ["y"] = 3, ["z"] = 3, ["name"] = "default:junglewood"}, {["x"] = 11, ["y"] = 3, ["z"] = 5, ["name"] = "default:steelblock"}, {["x"] = 11, ["y"] = 3, ["z"] = 6, ["name"] = "default:steelblock"}, {["x"] = 11, ["y"] = 3, ["z"] = 7, ["name"] = "default:steelblock"}, {["x"] = 11, ["y"] = 3, ["z"] = 9, ["name"] = "wool:brown"}, {["x"] = 11, ["y"] = 3, ["z"] = 10, ["name"] = "wool:brown"}, {["x"] = 11, ["y"] = 3, ["z"] = 11, ["name"] = "wool:brown"}, {["x"] = 11, ["y"] = 3, ["z"] = 12, ["name"] = "wool:brown"}, {["x"] = 11, ["y"] = 3, ["z"] = 13, ["name"] = "wool:brown"}, {["x"] = 11, ["y"] = 4, ["z"] = 2, ["name"] = "default:junglewood"}, {["x"] = 11, ["y"] = 4, ["z"] = 3, ["name"] = "default:junglewood"}, {["x"] = 11, ["y"] = 4, ["z"] = 13, ["name"] = "wool:red"}, {["x"] = 11, ["y"] = 5, ["z"] = 2, ["name"] = "default:junglewood"}, {["x"] = 11, ["y"] = 5, ["z"] = 7, ["name"] = "wool:yellow"}, {["x"] = 11, ["y"] = 7, ["z"] = 3, ["name"] = "wool:blue"}, {["x"] = 11, ["y"] = 7, ["z"] = 4, ["name"] = "wool:blue"}, {["x"] = 11, ["y"] = 7, ["z"] = 5, ["name"] = "wool:blue"}, {["x"] = 11, ["y"] = 7, ["z"] = 6, ["name"] = "wool:blue"}, {["x"] = 11, ["y"] = 7, ["z"] = 7, ["name"] = "wool:blue"}, {["x"] = 11, ["y"] = 7, ["z"] = 8, ["name"] = "wool:blue"}, {["x"] = 11, ["y"] = 7, ["z"] = 9, ["name"] = "wool:blue"}, {["x"] = 11, ["y"] = 7, ["z"] = 10, ["name"] = "wool:blue"}, {["x"] = 11, ["y"] = 7, ["z"] = 11, ["name"] = "wool:blue"}, {["x"] = 11, ["y"] = 7, ["z"] = 12, ["name"] = "wool:blue"}, {["x"] = 11, ["y"] = 8, ["z"] = 1, ["name"] = "wool:red"}, {["x"] = 11, ["y"] = 8, ["z"] = 2, ["name"] = "wool:blue"}, {["x"] = 11, ["y"] = 8, ["z"] = 3, ["name"] = "wool:blue"}, {["x"] = 11, ["y"] = 8, ["z"] = 4, ["name"] = "wool:blue"}, {["x"] = 11, ["y"] = 8, ["z"] = 5, ["name"] = "wool:blue"}, {["x"] = 11, ["y"] = 8, ["z"] = 6, ["name"] = "wool:blue"}, {["x"] = 11, ["y"] = 8, ["z"] = 7, ["name"] = "wool:blue"}, {["x"] = 11, ["y"] = 8, ["z"] = 8, ["name"] = "wool:blue"}, {["x"] = 11, ["y"] = 8, ["z"] = 9, ["name"] = "wool:blue"}, {["x"] = 11, ["y"] = 8, ["z"] = 10, ["name"] = "wool:blue"}, {["x"] = 11, ["y"] = 8, ["z"] = 11, ["name"] = "wool:blue"}, {["x"] = 11, ["y"] = 8, ["z"] = 12, ["name"] = "wool:blue"}, {["x"] = 11, ["y"] = 8, ["z"] = 13, ["name"] = "wool:blue"}, {["x"] = 11, ["y"] = 8, ["z"] = 14, ["name"] = "wool:red"}, {["x"] = 11, ["y"] = 9, ["z"] = 3, ["name"] = "wool:blue"}, {["x"] = 11, ["y"] = 9, ["z"] = 4, ["name"] = "wool:blue"}, {["x"] = 11, ["y"] = 9, ["z"] = 5, ["name"] = "wool:blue"}, {["x"] = 11, ["y"] = 9, ["z"] = 6, ["name"] = "wool:blue"}, {["x"] = 11, ["y"] = 9, ["z"] = 7, ["name"] = "wool:blue"}, {["x"] = 11, ["y"] = 9, ["z"] = 8, ["name"] = "wool:blue"}, {["x"] = 11, ["y"] = 9, ["z"] = 9, ["name"] = "wool:blue"}, {["x"] = 11, ["y"] = 9, ["z"] = 10, ["name"] = "wool:blue"}, {["x"] = 11, ["y"] = 9, ["z"] = 11, ["name"] = "wool:blue"}, {["x"] = 11, ["y"] = 9, ["z"] = 12, ["name"] = "wool:blue"}, {["x"] = 11, ["y"] = 10, ["z"] = 1, ["name"] = "wool:red"}, {["x"] = 11, ["y"] = 10, ["z"] = 4, ["name"] = "wool:blue"}, {["x"] = 11, ["y"] = 10, ["z"] = 5, ["name"] = "wool:blue"}, {["x"] = 11, ["y"] = 10, ["z"] = 6, ["name"] = "wool:blue"}, {["x"] = 11, ["y"] = 10, ["z"] = 7, ["name"] = "wool:blue"}, {["x"] = 11, ["y"] = 10, ["z"] = 8, ["name"] = "wool:blue"}, {["x"] = 11, ["y"] = 10, ["z"] = 9, ["name"] = "wool:blue"}, {["x"] = 11, ["y"] = 10, ["z"] = 10, ["name"] = "wool:blue"}, {["x"] = 11, ["y"] = 10, ["z"] = 11, ["name"] = "wool:blue"}, {["x"] = 11, ["y"] = 10, ["z"] = 14, ["name"] = "wool:red"}, {["x"] = 12, ["y"] = 0, ["z"] = 1, ["name"] = "wool:red"}, {["x"] = 12, ["y"] = 0, ["z"] = 14, ["name"] = "wool:red"}, {["x"] = 12, ["y"] = 1, ["z"] = 5, ["name"] = "wool:red"}, {["x"] = 12, ["y"] = 1, ["z"] = 7, ["name"] = "wool:red"}, {["x"] = 12, ["y"] = 1, ["z"] = 9, ["name"] = "wool:red"}, {["x"] = 12, ["y"] = 4, ["z"] = 13, ["name"] = "wool:red"}, {["x"] = 12, ["y"] = 5, ["z"] = 2, ["name"] = "wool:red"}, {["x"] = 12, ["y"] = 5, ["z"] = 7, ["name"] = "wool:yellow"}, {["x"] = 12, ["y"] = 6, ["z"] = 7, ["name"] = "wool:yellow"}, {["x"] = 12, ["y"] = 7, ["z"] = 7, ["name"] = "wool:yellow"}, {["x"] = 12, ["y"] = 8, ["z"] = 1, ["name"] = "wool:red"}, {["x"] = 12, ["y"] = 8, ["z"] = 2, ["name"] = "wool:red"}, {["x"] = 12, ["y"] = 8, ["z"] = 3, ["name"] = "wool:blue"}, {["x"] = 12, ["y"] = 8, ["z"] = 4, ["name"] = "wool:blue"}, {["x"] = 12, ["y"] = 8, ["z"] = 5, ["name"] = "wool:blue"}, {["x"] = 12, ["y"] = 8, ["z"] = 6, ["name"] = "wool:blue"}, {["x"] = 12, ["y"] = 8, ["z"] = 7, ["name"] = "wool:blue"}, {["x"] = 12, ["y"] = 8, ["z"] = 8, ["name"] = "wool:blue"}, {["x"] = 12, ["y"] = 8, ["z"] = 9, ["name"] = "wool:blue"}, {["x"] = 12, ["y"] = 8, ["z"] = 10, ["name"] = "wool:blue"}, {["x"] = 12, ["y"] = 8, ["z"] = 11, ["name"] = "wool:blue"}, {["x"] = 12, ["y"] = 8, ["z"] = 12, ["name"] = "wool:blue"}, {["x"] = 12, ["y"] = 8, ["z"] = 13, ["name"] = "wool:red"}, {["x"] = 12, ["y"] = 8, ["z"] = 14, ["name"] = "wool:red"}, {["x"] = 12, ["y"] = 9, ["z"] = 4, ["name"] = "wool:blue"}, {["x"] = 12, ["y"] = 9, ["z"] = 5, ["name"] = "wool:blue"}, {["x"] = 12, ["y"] = 9, ["z"] = 6, ["name"] = "wool:blue"}, {["x"] = 12, ["y"] = 9, ["z"] = 7, ["name"] = "wool:blue"}, {["x"] = 12, ["y"] = 9, ["z"] = 8, ["name"] = "wool:blue"}, {["x"] = 12, ["y"] = 9, ["z"] = 9, ["name"] = "wool:blue"}, {["x"] = 12, ["y"] = 9, ["z"] = 10, ["name"] = "wool:blue"}, {["x"] = 12, ["y"] = 9, ["z"] = 11, ["name"] = "wool:blue"}, {["x"] = 12, ["y"] = 10, ["z"] = 1, ["name"] = "wool:red"}, {["x"] = 12, ["y"] = 10, ["z"] = 14, ["name"] = "wool:red"}, {["x"] = 13, ["y"] = 0, ["z"] = 2, ["name"] = "wool:red"}, {["x"] = 13, ["y"] = 0, ["z"] = 3, ["name"] = "wool:red"}, {["x"] = 13, ["y"] = 0, ["z"] = 4, ["name"] = "wool:red"}, {["x"] = 13, ["y"] = 0, ["z"] = 5, ["name"] = "wool:red"}, {["x"] = 13, ["y"] = 0, ["z"] = 6, ["name"] = "wool:red"}, {["x"] = 13, ["y"] = 0, ["z"] = 7, ["name"] = "wool:red"}, {["x"] = 13, ["y"] = 0, ["z"] = 8, ["name"] = "wool:red"}, {["x"] = 13, ["y"] = 0, ["z"] = 9, ["name"] = "wool:red"}, {["x"] = 13, ["y"] = 0, ["z"] = 10, ["name"] = "wool:red"}, {["x"] = 13, ["y"] = 0, ["z"] = 11, ["name"] = "wool:red"}, {["x"] = 13, ["y"] = 0, ["z"] = 12, ["name"] = "wool:red"}, {["x"] = 13, ["y"] = 0, ["z"] = 13, ["name"] = "wool:red"}, {["x"] = 13, ["y"] = 1, ["z"] = 1, ["name"] = "wool:red"}, {["x"] = 13, ["y"] = 1, ["z"] = 5, ["name"] = "wool:red"}, {["x"] = 13, ["y"] = 1, ["z"] = 7, ["name"] = "wool:red"}, {["x"] = 13, ["y"] = 1, ["z"] = 9, ["name"] = "wool:red"}, {["x"] = 13, ["y"] = 1, ["z"] = 14, ["name"] = "wool:red"}, {["x"] = 13, ["y"] = 2, ["z"] = 1, ["name"] = "wool:red"}, {["x"] = 13, ["y"] = 2, ["z"] = 14, ["name"] = "wool:red"}, {["x"] = 13, ["y"] = 3, ["z"] = 1, ["name"] = "wool:red"}, {["x"] = 13, ["y"] = 3, ["z"] = 14, ["name"] = "wool:red"}, {["x"] = 13, ["y"] = 4, ["z"] = 1, ["name"] = "wool:red"}, {["x"] = 13, ["y"] = 4, ["z"] = 13, ["name"] = "wool:red"}, {["x"] = 13, ["y"] = 4, ["z"] = 14, ["name"] = "wool:red"}, {["x"] = 13, ["y"] = 5, ["z"] = 1, ["name"] = "wool:red"}, {["x"] = 13, ["y"] = 5, ["z"] = 2, ["name"] = "wool:red"}, {["x"] = 13, ["y"] = 5, ["z"] = 14, ["name"] = "wool:red"}, {["x"] = 13, ["y"] = 6, ["z"] = 1, ["name"] = "wool:red"}, {["x"] = 13, ["y"] = 6, ["z"] = 14, ["name"] = "wool:red"}, {["x"] = 13, ["y"] = 7, ["z"] = 1, ["name"] = "wool:red"}, {["x"] = 13, ["y"] = 7, ["z"] = 7, ["name"] = "wool:yellow"}, {["x"] = 13, ["y"] = 7, ["z"] = 14, ["name"] = "wool:red"}, {["x"] = 13, ["y"] = 8, ["z"] = 1, ["name"] = "wool:red"}, {["x"] = 13, ["y"] = 8, ["z"] = 2, ["name"] = "wool:red"}, {["x"] = 13, ["y"] = 8, ["z"] = 3, ["name"] = "wool:red"}, {["x"] = 13, ["y"] = 8, ["z"] = 4, ["name"] = "wool:red"}, {["x"] = 13, ["y"] = 8, ["z"] = 5, ["name"] = "wool:red"}, {["x"] = 13, ["y"] = 8, ["z"] = 6, ["name"] = "wool:red"}, {["x"] = 13, ["y"] = 8, ["z"] = 7, ["name"] = "wool:red"}, {["x"] = 13, ["y"] = 8, ["z"] = 8, ["name"] = "wool:red"}, {["x"] = 13, ["y"] = 8, ["z"] = 9, ["name"] = "wool:red"}, {["x"] = 13, ["y"] = 8, ["z"] = 10, ["name"] = "wool:red"}, {["x"] = 13, ["y"] = 8, ["z"] = 11, ["name"] = "wool:red"}, {["x"] = 13, ["y"] = 8, ["z"] = 12, ["name"] = "wool:red"}, {["x"] = 13, ["y"] = 8, ["z"] = 13, ["name"] = "wool:red"}, {["x"] = 13, ["y"] = 8, ["z"] = 14, ["name"] = "wool:red"}, {["x"] = 13, ["y"] = 9, ["z"] = 1, ["name"] = "wool:red"}, {["x"] = 13, ["y"] = 9, ["z"] = 14, ["name"] = "wool:red"}, {["x"] = 14, ["y"] = 7, ["z"] = 7, ["name"] = "wool:yellow"}, {["x"] = 14, ["y"] = 8, ["z"] = 7, ["name"] = "wool:red"}, {["x"] = 15, ["y"] = 7, ["z"] = 7, ["name"] = "wool:yellow"}, {["x"] = 15, ["y"] = 7, ["z"] = 8, ["name"] = "wool:yellow"}, {["x"] = 15, ["y"] = 8, ["z"] = 7, ["name"] = "wool:yellow"}, {["x"] = 15, ["y"] = 8, ["z"] = 8, ["name"] = "wool:yellow"}}