5:return {{["x"] = 2, ["y"] = 0, ["z"] = 6, ["name"] = "wool:blue"}, {["x"] = 2, ["y"] = 0, ["z"] = 7, ["name"] = "wool:blue"}, {["x"] = 2, ["y"] = 0, ["z"] = 8, ["name"] = "wool:blue"}, {["x"] = 2, ["y"] = 0, ["z"] = 9, ["name"] = "wool:blue"}, {["x"] = 3, ["y"] = 0, ["z"] = 5, ["name"] = "wool:blue"}, {["x"] = 3, ["y"] = 0, ["z"] = 6, ["name"] = "wool:blue"}, {["x"] = 3, ["y"] = 0, ["z"] = 7, ["name"] = "wool:blue"}, {["x"] = 3, ["y"] = 0, ["z"] = 8, ["name"] = "wool:blue"}, {["x"] = 3, ["y"] = 0, ["z"] = 9, ["name"] = "wool:blue"}, {["x"] = 3, ["y"] = 0, ["z"] = 10, ["name"] = "wool:blue"}, {["x"] = 3, ["y"] = 1, ["z"] = 7, ["name"] = "wool:red"}, {["x"] = 3, ["y"] = 1, ["z"] = 8, ["name"] = "wool:red"}, {["x"] = 3, ["y"] = 2, ["z"] = 7, ["name"] = "wool:red"}, {["x"] = 3, ["y"] = 2, ["z"] = 8, ["name"] = "wool:red"}, {["x"] = 3, ["y"] = 3, ["z"] = 7, ["name"] = "wool:red"}, {["x"] = 3, ["y"] = 3, ["z"] = 8, ["name"] = "wool:red"}, {["x"] = 3, ["y"] = 4, ["z"] = 7, ["name"] = "wool:red"}, {["x"] = 3, ["y"] = 4, ["z"] = 8, ["name"] = "wool:red"}, {["x"] = 3, ["y"] = 5, ["z"] = 7, ["name"] = "wool:red"}, {["x"] = 3, ["y"] = 5, ["z"] = 8, ["name"] = "wool:red"}, {["x"] = 3, ["y"] = 6, ["z"] = 7, ["name"] = "wool:red"}, {["x"] = 3, ["y"] = 6, ["z"] = 8, ["name"] = "wool:red"}, {["x"] = 3, ["y"] = 7, ["z"] = 7, ["name"] = "wool:red"}, {["x"] = 3, ["y"] = 7, ["z"] = 8, ["name"] = "wool:red"}, {["x"] = 4, ["y"] = 0, ["z"] = 5, ["name"] = "wool:blue"}, {["x"] = 4, ["y"] = 0, ["z"] = 6, ["name"] = "wool:blue"}, {["x"] = 4, ["y"] = 0, ["z"] = 7, ["name"] = "wool:blue"}, {["x"] = 4, ["y"] = 0, ["z"] = 8, ["name"] = "wool:blue"}, {["x"] = 4, ["y"] = 0, ["z"] = 9, ["name"] = "wool:blue"}, {["x"] = 4, ["y"] = 0, ["z"] = 10, ["name"] = "wool:blue"}, {["x"] = 4, ["y"] = 1, ["z"] = 6, ["name"] = "wool:red"}, {["x"] = 4, ["y"] = 1, ["z"] = 9, ["name"] = "wool:red"}, {["x"] = 4, ["y"] = 2, ["z"] = 6, ["name"] = "wool:red"}, {["x"] = 4, ["y"] = 2, ["z"] = 9, ["name"] = "wool:red"}, {["x"] = 4, ["y"] = 3, ["z"] = 6, ["name"] = "wool:red"}, {["x"] = 4, ["y"] = 3, ["z"] = 9, ["name"] = "wool:red"}, {["x"] = 4, ["y"] = 4, ["z"] = 6, ["name"] = "wool:red"}, {["x"] = 4, ["y"] = 4, ["z"] = 9, ["name"] = "wool:red"}, {["x"] = 4, ["y"] = 5, ["z"] = 6, ["name"] = "wool:red"}, {["x"] = 4, ["y"] = 5, ["z"] = 9, ["name"] = "wool:red"}, {["x"] = 4, ["y"] = 6, ["z"] = 6, ["name"] = "wool:red"}, {["x"] = 4, ["y"] = 6, ["z"] = 9, ["name"] = "wool:red"}, {["x"] = 4, ["y"] = 7, ["z"] = 6, ["name"] = "wool:red"}, {["x"] = 4, ["y"] = 7, ["z"] = 9, ["name"] = "wool:red"}, {["x"] = 5, ["y"] = 0, ["z"] = 5, ["name"] = "wool:blue"}, {["x"] = 5, ["y"] = 0, ["z"] = 6, ["name"] = "wool:blue"}, {["x"] = 5, ["y"] = 0, ["z"] = 7, ["name"] = "wool:blue"}, {["x"] = 5, ["y"] = 0, ["z"] = 8, ["name"] = "wool:blue"}, {["x"] = 5, ["y"] = 0, ["z"] = 9, ["name"] = "wool:blue"}, {["x"] = 5, ["y"] = 0, ["z"] = 10, ["name"] = "wool:blue"}, {["x"] = 5, ["y"] = 1, ["z"] = 6, ["name"] = "wool:red"}, {["x"] = 5, ["y"] = 1, ["z"] = 9, ["name"] = "wool:red"}, {["x"] = 5, ["y"] = 2, ["z"] = 6, ["name"] = "wool:red"}, {["x"] = 5, ["y"] = 2, ["z"] = 9, ["name"] = "wool:red"}, {["x"] = 5, ["y"] = 3, ["z"] = 6, ["name"] = "wool:red"}, {["x"] = 5, ["y"] = 3, ["z"] = 9, ["name"] = "wool:red"}, {["x"] = 5, ["y"] = 4, ["z"] = 6, ["name"] = "wool:red"}, {["x"] = 5, ["y"] = 4, ["z"] = 9, ["name"] = "wool:red"}, {["x"] = 5, ["y"] = 5, ["z"] = 6, ["name"] = "wool:red"}, {["x"] = 5, ["y"] = 5, ["z"] = 9, ["name"] = "wool:red"}, {["x"] = 5, ["y"] = 6, ["z"] = 6, ["name"] = "wool:red"}, {["x"] = 5, ["y"] = 6, ["z"] = 9, ["name"] = "wool:red"}, {["x"] = 5, ["y"] = 7, ["z"] = 6, ["name"] = "wool:red"}, {["x"] = 5, ["y"] = 7, ["z"] = 9, ["name"] = "wool:red"}, {["x"] = 6, ["y"] = 0, ["z"] = 5, ["name"] = "wool:blue"}, {["x"] = 6, ["y"] = 0, ["z"] = 6, ["name"] = "wool:blue"}, {["x"] = 6, ["y"] = 0, ["z"] = 7, ["name"] = "wool:blue"}, {["x"] = 6, ["y"] = 0, ["z"] = 8, ["name"] = "wool:blue"}, {["x"] = 6, ["y"] = 0, ["z"] = 9, ["name"] = "wool:blue"}, {["x"] = 6, ["y"] = 0, ["z"] = 10, ["name"] = "wool:blue"}, {["x"] = 6, ["y"] = 1, ["z"] = 7, ["name"] = "wool:red"}, {["x"] = 6, ["y"] = 1, ["z"] = 8, ["name"] = "wool:red"}, {["x"] = 6, ["y"] = 2, ["z"] = 7, ["name"] = "wool:red"}, {["x"] = 6, ["y"] = 2, ["z"] = 8, ["name"] = "wool:red"}, {["x"] = 6, ["y"] = 3, ["z"] = 7, ["name"] = "wool:red"}, {["x"] = 6, ["y"] = 3, ["z"] = 8, ["name"] = "wool:red"}, {["x"] = 6, ["y"] = 4, ["z"] = 7, ["name"] = "wool:red"}, {["x"] = 6, ["y"] = 4, ["z"] = 8, ["name"] = "wool:red"}, {["x"] = 6, ["y"] = 5, ["z"] = 7, ["name"] = "wool:red"}, {["x"] = 6, ["y"] = 5, ["z"] = 8, ["name"] = "wool:red"}, {["x"] = 6, ["y"] = 6, ["z"] = 7, ["name"] = "wool:red"}, {["x"] = 6, ["y"] = 6, ["z"] = 8, ["name"] = "wool:red"}, {["x"] = 6, ["y"] = 7, ["z"] = 7, ["name"] = "wool:red"}, {["x"] = 6, ["y"] = 7, ["z"] = 8, ["name"] = "wool:red"}, {["x"] = 7, ["y"] = 0, ["z"] = 6, ["name"] = "wool:blue"}, {["x"] = 7, ["y"] = 0, ["z"] = 7, ["name"] = "wool:blue"}, {["x"] = 7, ["y"] = 0, ["z"] = 8, ["name"] = "wool:blue"}, {["x"] = 7, ["y"] = 0, ["z"] = 9, ["name"] = "wool:blue"}, {["x"] = 7, ["y"] = 1, ["z"] = 7, ["name"] = "wool:yellow"}, {["x"] = 8, ["y"] = 2, ["z"] = 7, ["name"] = "wool:yellow"}, {["x"] = 8, ["y"] = 3, ["z"] = 7, ["name"] = "wool:yellow"}, {["x"] = 8, ["y"] = 4, ["z"] = 7, ["name"] = "wool:yellow"}, {["x"] = 8, ["y"] = 5, ["z"] = 7, ["name"] = "wool:yellow"}, {["x"] = 8, ["y"] = 6, ["z"] = 7, ["name"] = "wool:yellow"}, {["x"] = 8, ["y"] = 7, ["z"] = 7, ["name"] = "wool:yellow"}, {["x"] = 9, ["y"] = 8, ["z"] = 7, ["name"] = "wool:yellow"}, {["x"] = 9, ["y"] = 9, ["z"] = 7, ["name"] = "wool:yellow"}, {["x"] = 9, ["y"] = 10, ["z"] = 7, ["name"] = "wool:yellow"}, {["x"] = 9, ["y"] = 11, ["z"] = 7, ["name"] = "wool:yellow"}, {["x"] = 9, ["y"] = 12, ["z"] = 7, ["name"] = "wool:yellow"}, {["x"] = 10, ["y"] = 0, ["z"] = 5, ["name"] = "wool:green"}, {["x"] = 10, ["y"] = 0, ["z"] = 6, ["name"] = "wool:green"}, {["x"] = 10, ["y"] = 0, ["z"] = 7, ["name"] = "wool:green"}, {["x"] = 10, ["y"] = 0, ["z"] = 8, ["name"] = "wool:green"}, {["x"] = 10, ["y"] = 0, ["z"] = 9, ["name"] = "wool:green"}, {["x"] = 10, ["y"] = 0, ["z"] = 10, ["name"] = "wool:green"}, {["x"] = 10, ["y"] = 3, ["z"] = 6, ["name"] = "default:steelblock"}, {["x"] = 10, ["y"] = 3, ["z"] = 7, ["name"] = "default:steelblock"}, {["x"] = 10, ["y"] = 3, ["z"] = 8, ["name"] = "default:steelblock"}, {["x"] = 10, ["y"] = 3, ["z"] = 9, ["name"] = "default:steelblock"}, {["x"] = 10, ["y"] = 4, ["z"] = 6, ["name"] = "default:steelblock"}, {["x"] = 10, ["y"] = 4, ["z"] = 7, ["name"] = "default:steelblock"}, {["x"] = 10, ["y"] = 4, ["z"] = 8, ["name"] = "default:steelblock"}, {["x"] = 10, ["y"] = 4, ["z"] = 9, ["name"] = "default:steelblock"}, {["x"] = 10, ["y"] = 5, ["z"] = 6, ["name"] = "default:steelblock"}, {["x"] = 10, ["y"] = 5, ["z"] = 7, ["name"] = "default:steelblock"}, {["x"] = 10, ["y"] = 5, ["z"] = 8, ["name"] = "default:steelblock"}, {["x"] = 10, ["y"] = 5, ["z"] = 9, ["name"] = "default:steelblock"}, {["x"] = 10, ["y"] = 6, ["z"] = 6, ["name"] = "default:steelblock"}, {["x"] = 10, ["y"] = 6, ["z"] = 7, ["name"] = "default:steelblock"}, {["x"] = 10, ["y"] = 6, ["z"] = 8, ["name"] = "default:steelblock"}, {["x"] = 10, ["y"] = 6, ["z"] = 9, ["name"] = "default:steelblock"}, {["x"] = 10, ["y"] = 7, ["z"] = 6, ["name"] = "default:steelblock"}, {["x"] = 10, ["y"] = 7, ["z"] = 7, ["name"] = "default:steelblock"}, {["x"] = 10, ["y"] = 7, ["z"] = 8, ["name"] = "default:steelblock"}, {["x"] = 10, ["y"] = 7, ["z"] = 9, ["name"] = "default:steelblock"}, {["x"] = 10, ["y"] = 8, ["z"] = 6, ["name"] = "default:steelblock"}, {["x"] = 10, ["y"] = 8, ["z"] = 7, ["name"] = "default:steelblock"}, {["x"] = 10, ["y"] = 8, ["z"] = 8, ["name"] = "default:steelblock"}, {["x"] = 10, ["y"] = 8, ["z"] = 9, ["name"] = "default:steelblock"}, {["x"] = 10, ["y"] = 9, ["z"] = 6, ["name"] = "default:steelblock"}, {["x"] = 10, ["y"] = 9, ["z"] = 7, ["name"] = "default:steelblock"}, {["x"] = 10, ["y"] = 9, ["z"] = 8, ["name"] = "default:steelblock"}, {["x"] = 10, ["y"] = 9, ["z"] = 9, ["name"] = "default:steelblock"}, {["x"] = 10, ["y"] = 10, ["z"] = 6, ["name"] = "default:steelblock"}, {["x"] = 10, ["y"] = 10, ["z"] = 7, ["name"] = "default:steelblock"}, {["x"] = 10, ["y"] = 10, ["z"] = 8, ["name"] = "default:steelblock"}, {["x"] = 10, ["y"] = 10, ["z"] = 9, ["name"] = "default:steelblock"}, {["x"] = 10, ["y"] = 11, ["z"] = 6, ["name"] = "default:steelblock"}, {["x"] = 10, ["y"] = 11, ["z"] = 7, ["name"] = "default:steelblock"}, {["x"] = 10, ["y"] = 11, ["z"] = 8, ["name"] = "default:steelblock"}, {["x"] = 10, ["y"] = 11, ["z"] = 9, ["name"] = "default:steelblock"}, {["x"] = 10, ["y"] = 13, ["z"] = 7, ["name"] = "wool:yellow"}, {["x"] = 11, ["y"] = 0, ["z"] = 5, ["name"] = "wool:green"}, {["x"] = 11, ["y"] = 0, ["z"] = 6, ["name"] = "wool:green"}, {["x"] = 11, ["y"] = 0, ["z"] = 7, ["name"] = "wool:green"}, {["x"] = 11, ["y"] = 0, ["z"] = 8, ["name"] = "wool:green"}, {["x"] = 11, ["y"] = 0, ["z"] = 9, ["name"] = "wool:green"}, {["x"] = 11, ["y"] = 0, ["z"] = 10, ["name"] = "wool:green"}, {["x"] = 11, ["y"] = 1, ["z"] = 6, ["name"] = "default:steelblock"}, {["x"] = 11, ["y"] = 1, ["z"] = 7, ["name"] = "default:steelblock"}, {["x"] = 11, ["y"] = 1, ["z"] = 8, ["name"] = "default:steelblock"}, {["x"] = 11, ["y"] = 1, ["z"] = 9, ["name"] = "default:steelblock"}, {["x"] = 11, ["y"] = 2, ["z"] = 6, ["name"] = "default:steelblock"}, {["x"] = 11, ["y"] = 2, ["z"] = 7, ["name"] = "default:steelblock"}, {["x"] = 11, ["y"] = 2, ["z"] = 8, ["name"] = "default:steelblock"}, {["x"] = 11, ["y"] = 2, ["z"] = 9, ["name"] = "default:steelblock"}, {["x"] = 11, ["y"] = 3, ["z"] = 5, ["name"] = "default:steelblock"}, {["x"] = 11, ["y"] = 3, ["z"] = 6, ["name"] = "default:steelblock"}, {["x"] = 11, ["y"] = 3, ["z"] = 7, ["name"] = "default:steelblock"}, {["x"] = 11, ["y"] = 3, ["z"] = 8, ["name"] = "default:steelblock"}, {["x"] = 11, ["y"] = 3, ["z"] = 9, ["name"] = "default:steelblock"}, {["x"] = 11, ["y"] = 3, ["z"] = 10, ["name"] = "default:steelblock"}, {["x"] = 11, ["y"] = 4, ["z"] = 5, ["name"] = "default:steelblock"}, {["x"] = 11, ["y"] = 4, ["z"] = 10, ["name"] = "default:steelblock"}, {["x"] = 11, ["y"] = 5, ["z"] = 5, ["name"] = "default:steelblock"}, {["x"] = 11, ["y"] = 5, ["z"] = 10, ["name"] = "default:steelblock"}, {["x"] = 11, ["y"] = 6, ["z"] = 5, ["name"] = "default:steelblock"}, {["x"] = 11, ["y"] = 6, ["z"] = 10, ["name"] = "default:steelblock"}, {["x"] = 11, ["y"] = 7, ["z"] = 5, ["name"] = "default:steelblock"}, {["x"] = 11, ["y"] = 7, ["z"] = 10, ["name"] = "default:steelblock"}, {["x"] = 11, ["y"] = 8, ["z"] = 5, ["name"] = "default:steelblock"}, {["x"] = 11, ["y"] = 8, ["z"] = 10, ["name"] = "default:steelblock"}, {["x"] = 11, ["y"] = 9, ["z"] = 5, ["name"] = "default:steelblock"}, {["x"] = 11, ["y"] = 9, ["z"] = 10, ["name"] = "default:steelblock"}, {["x"] = 11, ["y"] = 10, ["z"] = 5, ["name"] = "default:steelblock"}, {["x"] = 11, ["y"] = 10, ["z"] = 10, ["name"] = "default:steelblock"}, {["x"] = 11, ["y"] = 11, ["z"] = 5, ["name"] = "default:steelblock"}, {["x"] = 11, ["y"] = 11, ["z"] = 10, ["name"] = "default:steelblock"}, {["x"] = 11, ["y"] = 12, ["z"] = 6, ["name"] = "default:steelblock"}, {["x"] = 11, ["y"] = 12, ["z"] = 7, ["name"] = "default:steelblock"}, {["x"] = 11, ["y"] = 12, ["z"] = 8, ["name"] = "default:steelblock"}, {["x"] = 11, ["y"] = 12, ["z"] = 9, ["name"] = "default:steelblock"}, {["x"] = 11, ["y"] = 13, ["z"] = 6, ["name"] = "default:steelblock"}, {["x"] = 11, ["y"] = 13, ["z"] = 7, ["name"] = "wool:yellow"}, {["x"] = 11, ["y"] = 13, ["z"] = 9, ["name"] = "default:steelblock"}, {["x"] = 11, ["y"] = 14, ["z"] = 6, ["name"] = "default:steelblock"}, {["x"] = 11, ["y"] = 14, ["z"] = 9, ["name"] = "default:steelblock"}, {["x"] = 11, ["y"] = 15, ["z"] = 6, ["name"] = "default:steelblock"}, {["x"] = 11, ["y"] = 15, ["z"] = 7, ["name"] = "default:steelblock"}, {["x"] = 11, ["y"] = 15, ["z"] = 8, ["name"] = "default:steelblock"}, {["x"] = 11, ["y"] = 15, ["z"] = 9, ["name"] = "default:steelblock"}, {["x"] = 12, ["y"] = 0, ["z"] = 5, ["name"] = "wool:green"}, {["x"] = 12, ["y"] = 0, ["z"] = 6, ["name"] = "wool:green"}, {["x"] = 12, ["y"] = 0, ["z"] = 7, ["name"] = "wool:green"}, {["x"] = 12, ["y"] = 0, ["z"] = 8, ["name"] = "wool:green"}, {["x"] = 12, ["y"] = 0, ["z"] = 9, ["name"] = "wool:green"}, {["x"] = 12, ["y"] = 0, ["z"] = 10, ["name"] = "wool:green"}, {["x"] = 12, ["y"] = 1, ["z"] = 6, ["name"] = "default:steelblock"}, {["x"] = 12, ["y"] = 1, ["z"] = 9, ["name"] = "default:steelblock"}, {["x"] = 12, ["y"] = 2, ["z"] = 6, ["name"] = "default:steelblock"}, {["x"] = 12, ["y"] = 2, ["z"] = 9, ["name"] = "default:steelblock"}, {["x"] = 12, ["y"] = 3, ["z"] = 5, ["name"] = "default:steelblock"}, {["x"] = 12, ["y"] = 3, ["z"] = 6, ["name"] = "default:steelblock"}, {["x"] = 12, ["y"] = 3, ["z"] = 7, ["name"] = "default:steelblock"}, {["x"] = 12, ["y"] = 3, ["z"] = 8, ["name"] = "default:steelblock"}, {["x"] = 12, ["y"] = 3, ["z"] = 9, ["name"] = "default:steelblock"}, {["x"] = 12, ["y"] = 3, ["z"] = 10, ["name"] = "default:steelblock"}, {["x"] = 12, ["y"] = 4, ["z"] = 5, ["name"] = "default:steelblock"}, {["x"] = 12, ["y"] = 4, ["z"] = 10, ["name"] = "default:steelblock"}, {["x"] = 12, ["y"] = 5, ["z"] = 5, ["name"] = "default:steelblock"}, {["x"] = 12, ["y"] = 5, ["z"] = 10, ["name"] = "default:steelblock"}, {["x"] = 12, ["y"] = 6, ["z"] = 5, ["name"] = "default:steelblock"}, {["x"] = 12, ["y"] = 6, ["z"] = 10, ["name"] = "default:steelblock"}, {["x"] = 12, ["y"] = 7, ["z"] = 5, ["name"] = "default:steelblock"}, {["x"] = 12, ["y"] = 7, ["z"] = 10, ["name"] = "default:steelblock"}, {["x"] = 12, ["y"] = 8, ["z"] = 5, ["name"] = "default:steelblock"}, {["x"] = 12, ["y"] = 8, ["z"] = 10, ["name"] = "default:steelblock"}, {["x"] = 12, ["y"] = 9, ["z"] = 5, ["name"] = "default:steelblock"}, {["x"] = 12, ["y"] = 9, ["z"] = 10, ["name"] = "default:steelblock"}, {["x"] = 12, ["y"] = 10, ["z"] = 5, ["name"] = "default:steelblock"}, {["x"] = 12, ["y"] = 10, ["z"] = 10, ["name"] = "default:steelblock"}, {["x"] = 12, ["y"] = 11, ["z"] = 5, ["name"] = "default:steelblock"}, {["x"] = 12, ["y"] = 11, ["z"] = 10, ["name"] = "default:steelblock"}, {["x"] = 12, ["y"] = 12, ["z"] = 6, ["name"] = "default:steelblock"}, {["x"] = 12, ["y"] = 12, ["z"] = 7, ["name"] = "default:steelblock"}, {["x"] = 12, ["y"] = 12, ["z"] = 8, ["name"] = "default:steelblock"}, {["x"] = 12, ["y"] = 12, ["z"] = 9, ["name"] = "default:steelblock"}, {["x"] = 12, ["y"] = 13, ["z"] = 7, ["name"] = "wool:yellow"}, {["x"] = 12, ["y"] = 15, ["z"] = 6, ["name"] = "default:steelblock"}, {["x"] = 12, ["y"] = 15, ["z"] = 9, ["name"] = "default:steelblock"}, {["x"] = 13, ["y"] = 0, ["z"] = 5, ["name"] = "wool:green"}, {["x"] = 13, ["y"] = 0, ["z"] = 6, ["name"] = "wool:green"}, {["x"] = 13, ["y"] = 0, ["z"] = 7, ["name"] = "wool:green"}, {["x"] = 13, ["y"] = 0, ["z"] = 8, ["name"] = "wool:green"}, {["x"] = 13, ["y"] = 0, ["z"] = 9, ["name"] = "wool:green"}, {["x"] = 13, ["y"] = 0, ["z"] = 10, ["name"] = "wool:green"}, {["x"] = 13, ["y"] = 1, ["z"] = 6, ["name"] = "default:steelblock"}, {["x"] = 13, ["y"] = 1, ["z"] = 9, ["name"] = "default:steelblock"}, {["x"] = 13, ["y"] = 2, ["z"] = 6, ["name"] = "default:steelblock"}, {["x"] = 13, ["y"] = 2, ["z"] = 9, ["name"] = "default:steelblock"}, {["x"] = 13, ["y"] = 3, ["z"] = 5, ["name"] = "default:steelblock"}, {["x"] = 13, ["y"] = 3, ["z"] = 6, ["name"] = "default:steelblock"}, {["x"] = 13, ["y"] = 3, ["z"] = 7, ["name"] = "default:steelblock"}, {["x"] = 13, ["y"] = 3, ["z"] = 8, ["name"] = "default:steelblock"}, {["x"] = 13, ["y"] = 3, ["z"] = 9, ["name"] = "default:steelblock"}, {["x"] = 13, ["y"] = 3, ["z"] = 10, ["name"] = "default:steelblock"}, {["x"] = 13, ["y"] = 4, ["z"] = 5, ["name"] = "default:steelblock"}, {["x"] = 13, ["y"] = 4, ["z"] = 10, ["name"] = "default:steelblock"}, {["x"] = 13, ["y"] = 5, ["z"] = 5, ["name"] = "default:steelblock"}, {["x"] = 13, ["y"] = 5, ["z"] = 10, ["name"] = "default:steelblock"}, {["x"] = 13, ["y"] = 6, ["z"] = 5, ["name"] = "default:steelblock"}, {["x"] = 13, ["y"] = 6, ["z"] = 10, ["name"] = "default:steelblock"}, {["x"] = 13, ["y"] = 7, ["z"] = 5, ["name"] = "default:steelblock"}, {["x"] = 13, ["y"] = 7, ["z"] = 10, ["name"] = "default:steelblock"}, {["x"] = 13, ["y"] = 8, ["z"] = 5, ["name"] = "default:steelblock"}, {["x"] = 13, ["y"] = 8, ["z"] = 10, ["name"] = "default:steelblock"}, {["x"] = 13, ["y"] = 9, ["z"] = 5, ["name"] = "default:steelblock"}, {["x"] = 13, ["y"] = 9, ["z"] = 10, ["name"] = "default:steelblock"}, {["x"] = 13, ["y"] = 10, ["z"] = 5, ["name"] = "default:steelblock"}, {["x"] = 13, ["y"] = 10, ["z"] = 10, ["name"] = "default:steelblock"}, {["x"] = 13, ["y"] = 11, ["z"] = 5, ["name"] = "default:steelblock"}, {["x"] = 13, ["y"] = 11, ["z"] = 10, ["name"] = "default:steelblock"}, {["x"] = 13, ["y"] = 12, ["z"] = 6, ["name"] = "default:steelblock"}, {["x"] = 13, ["y"] = 12, ["z"] = 7, ["name"] = "default:steelblock"}, {["x"] = 13, ["y"] = 12, ["z"] = 8, ["name"] = "default:steelblock"}, {["x"] = 13, ["y"] = 12, ["z"] = 9, ["name"] = "default:steelblock"}, {["x"] = 13, ["y"] = 15, ["z"] = 6, ["name"] = "default:steelblock"}, {["x"] = 13, ["y"] = 15, ["z"] = 9, ["name"] = "default:steelblock"}, {["x"] = 14, ["y"] = 0, ["z"] = 5, ["name"] = "wool:green"}, {["x"] = 14, ["y"] = 0, ["z"] = 6, ["name"] = "wool:green"}, {["x"] = 14, ["y"] = 0, ["z"] = 7, ["name"] = "wool:green"}, {["x"] = 14, ["y"] = 0, ["z"] = 8, ["name"] = "wool:green"}, {["x"] = 14, ["y"] = 0, ["z"] = 9, ["name"] = "wool:green"}, {["x"] = 14, ["y"] = 0, ["z"] = 10, ["name"] = "wool:green"}, {["x"] = 14, ["y"] = 1, ["z"] = 6, ["name"] = "default:steelblock"}, {["x"] = 14, ["y"] = 1, ["z"] = 7, ["name"] = "default:steelblock"}, {["x"] = 14, ["y"] = 1, ["z"] = 8, ["name"] = "default:steelblock"}, {["x"] = 14, ["y"] = 1, ["z"] = 9, ["name"] = "default:steelblock"}, {["x"] = 14, ["y"] = 2, ["z"] = 6, ["name"] = "default:steelblock"}, {["x"] = 14, ["y"] = 2, ["z"] = 7, ["name"] = "default:steelblock"}, {["x"] = 14, ["y"] = 2, ["z"] = 8, ["name"] = "default:steelblock"}, {["x"] = 14, ["y"] = 2, ["z"] = 9, ["name"] = "default:steelblock"}, {["x"] = 14, ["y"] = 3, ["z"] = 5, ["name"] = "default:steelblock"}, {["x"] = 14, ["y"] = 3, ["z"] = 6, ["name"] = "default:steelblock"}, {["x"] = 14, ["y"] = 3, ["z"] = 7, ["name"] = "default:steelblock"}, {["x"] = 14, ["y"] = 3, ["z"] = 8, ["name"] = "default:steelblock"}, {["x"] = 14, ["y"] = 3, ["z"] = 9, ["name"] = "default:steelblock"}, {["x"] = 14, ["y"] = 3, ["z"] = 10, ["name"] = "default:steelblock"}, {["x"] = 14, ["y"] = 4, ["z"] = 5, ["name"] = "default:steelblock"}, {["x"] = 14, ["y"] = 4, ["z"] = 10, ["name"] = "default:steelblock"}, {["x"] = 14, ["y"] = 5, ["z"] = 5, ["name"] = "default:steelblock"}, {["x"] = 14, ["y"] = 5, ["z"] = 10, ["name"] = "default:steelblock"}, {["x"] = 14, ["y"] = 6, ["z"] = 5, ["name"] = "default:steelblock"}, {["x"] = 14, ["y"] = 6, ["z"] = 10, ["name"] = "default:steelblock"}, {["x"] = 14, ["y"] = 7, ["z"] = 5, ["name"] = "default:steelblock"}, {["x"] = 14, ["y"] = 7, ["z"] = 10, ["name"] = "default:steelblock"}, {["x"] = 14, ["y"] = 8, ["z"] = 5, ["name"] = "default:steelblock"}, {["x"] = 14, ["y"] = 8, ["z"] = 10, ["name"] = "default:steelblock"}, {["x"] = 14, ["y"] = 9, ["z"] = 5, ["name"] = "default:steelblock"}, {["x"] = 14, ["y"] = 9, ["z"] = 10, ["name"] = "default:steelblock"}, {["x"] = 14, ["y"] = 10, ["z"] = 5, ["name"] = "default:steelblock"}, {["x"] = 14, ["y"] = 10, ["z"] = 10, ["name"] = "default:steelblock"}, {["x"] = 14, ["y"] = 11, ["z"] = 5, ["name"] = "default:steelblock"}, {["x"] = 14, ["y"] = 11, ["z"] = 10, ["name"] = "default:steelblock"}, {["x"] = 14, ["y"] = 12, ["z"] = 6, ["name"] = "default:steelblock"}, {["x"] = 14, ["y"] = 12, ["z"] = 7, ["name"] = "default:steelblock"}, {["x"] = 14, ["y"] = 12, ["z"] = 8, ["name"] = "default:steelblock"}, {["x"] = 14, ["y"] = 12, ["z"] = 9, ["name"] = "default:steelblock"}, {["x"] = 14, ["y"] = 13, ["z"] = 6, ["name"] = "default:steelblock"}, {["x"] = 14, ["y"] = 13, ["z"] = 9, ["name"] = "default:steelblock"}, {["x"] = 14, ["y"] = 14, ["z"] = 6, ["name"] = "default:steelblock"}, {["x"] = 14, ["y"] = 14, ["z"] = 9, ["name"] = "default:steelblock"}, {["x"] = 14, ["y"] = 15, ["z"] = 6, ["name"] = "default:steelblock"}, {["x"] = 14, ["y"] = 15, ["z"] = 7, ["name"] = "default:steelblock"}, {["x"] = 14, ["y"] = 15, ["z"] = 8, ["name"] = "default:steelblock"}, {["x"] = 14, ["y"] = 15, ["z"] = 9, ["name"] = "default:steelblock"}, {["x"] = 15, ["y"] = 0, ["z"] = 5, ["name"] = "wool:green"}, {["x"] = 15, ["y"] = 0, ["z"] = 6, ["name"] = "wool:green"}, {["x"] = 15, ["y"] = 0, ["z"] = 7, ["name"] = "wool:green"}, {["x"] = 15, ["y"] = 0, ["z"] = 8, ["name"] = "wool:green"}, {["x"] = 15, ["y"] = 0, ["z"] = 9, ["name"] = "wool:green"}, {["x"] = 15, ["y"] = 0, ["z"] = 10, ["name"] = "wool:green"}, {["x"] = 15, ["y"] = 3, ["z"] = 6, ["name"] = "default:steelblock"}, {["x"] = 15, ["y"] = 3, ["z"] = 7, ["name"] = "default:steelblock"}, {["x"] = 15, ["y"] = 3, ["z"] = 8, ["name"] = "default:steelblock"}, {["x"] = 15, ["y"] = 3, ["z"] = 9, ["name"] = "default:steelblock"}, {["x"] = 15, ["y"] = 4, ["z"] = 6, ["name"] = "default:steelblock"}, {["x"] = 15, ["y"] = 4, ["z"] = 7, ["name"] = "default:steelblock"}, {["x"] = 15, ["y"] = 4, ["z"] = 8, ["name"] = "default:steelblock"}, {["x"] = 15, ["y"] = 4, ["z"] = 9, ["name"] = "default:steelblock"}, {["x"] = 15, ["y"] = 5, ["z"] = 6, ["name"] = "default:steelblock"}, {["x"] = 15, ["y"] = 5, ["z"] = 7, ["name"] = "default:steelblock"}, {["x"] = 15, ["y"] = 5, ["z"] = 8, ["name"] = "default:steelblock"}, {["x"] = 15, ["y"] = 5, ["z"] = 9, ["name"] = "default:steelblock"}, {["x"] = 15, ["y"] = 6, ["z"] = 6, ["name"] = "default:steelblock"}, {["x"] = 15, ["y"] = 6, ["z"] = 7, ["name"] = "default:steelblock"}, {["x"] = 15, ["y"] = 6, ["z"] = 8, ["name"] = "default:steelblock"}, {["x"] = 15, ["y"] = 6, ["z"] = 9, ["name"] = "default:steelblock"}, {["x"] = 15, ["y"] = 7, ["z"] = 6, ["name"] = "default:steelblock"}, {["x"] = 15, ["y"] = 7, ["z"] = 7, ["name"] = "default:steelblock"}, {["x"] = 15, ["y"] = 7, ["z"] = 8, ["name"] = "default:steelblock"}, {["x"] = 15, ["y"] = 7, ["z"] = 9, ["name"] = "default:steelblock"}, {["x"] = 15, ["y"] = 8, ["z"] = 6, ["name"] = "default:steelblock"}, {["x"] = 15, ["y"] = 8, ["z"] = 7, ["name"] = "default:steelblock"}, {["x"] = 15, ["y"] = 8, ["z"] = 8, ["name"] = "default:steelblock"}, {["x"] = 15, ["y"] = 8, ["z"] = 9, ["name"] = "default:steelblock"}, {["x"] = 15, ["y"] = 9, ["z"] = 6, ["name"] = "default:steelblock"}, {["x"] = 15, ["y"] = 9, ["z"] = 7, ["name"] = "default:steelblock"}, {["x"] = 15, ["y"] = 9, ["z"] = 8, ["name"] = "default:steelblock"}, {["x"] = 15, ["y"] = 9, ["z"] = 9, ["name"] = "default:steelblock"}, {["x"] = 15, ["y"] = 10, ["z"] = 6, ["name"] = "default:steelblock"}, {["x"] = 15, ["y"] = 10, ["z"] = 7, ["name"] = "default:steelblock"}, {["x"] = 15, ["y"] = 10, ["z"] = 8, ["name"] = "default:steelblock"}, {["x"] = 15, ["y"] = 10, ["z"] = 9, ["name"] = "default:steelblock"}, {["x"] = 15, ["y"] = 11, ["z"] = 6, ["name"] = "default:steelblock"}, {["x"] = 15, ["y"] = 11, ["z"] = 7, ["name"] = "default:steelblock"}, {["x"] = 15, ["y"] = 11, ["z"] = 8, ["name"] = "default:steelblock"}, {["x"] = 15, ["y"] = 11, ["z"] = 9, ["name"] = "default:steelblock"}}